Workbook
Name MonthStart: RATES!$H$6
Name MonthEnd: RATES!$I$6
Name OffCodes: 'OFF ROAD RETURN'!$A$5:$A$170
Name OffTaxable: 'OFF ROAD RETURN'!$G$5:$G$170
Name OnCodes: 'ON ROAD RETURN'!$A$5:$A$336
Name OnFuelType: 'ON ROAD RETURN'!$M$5:$M$336
Name OnGallons: 'ON ROAD RETURN'!$E$5:$E$336
Name OnExempt: 'ON ROAD RETURN'!$F$5:$F$336
Name OnTaxableSales: 'ON ROAD RETURN'!$H$5:$H$336
Name OnGoesOn: 'ON ROAD RETURN'!$N$5:$N$336
Name ReturnMonth: RECAP!$C$3
Name OffAccount: RECAP!$C$15
Name OnAccount: RECAP!$D$15
Name OffLines: RECAP!$C$19:$C$31
Name OnLines: RECAP!$D$19:$D$31

Sheet READ ME
B2: Georgia sales tax workbook
B4: One rule: yellow cells are the only cells you type in. Everything else calculates itself.
B6: EVERY MONTH:
B7: 1. Run the AR sales tax report for Georgia for the month. Copy the whole thing, headers and all,
B8: and paste it into the AR SALES tab starting at cell A1, replacing what's there.
B9: 2. Run the TERSE for Georgia for the same month. Paste it into the TERSE tab the same way, at A1.
B10: 3. On RECAP, type the month (the first of it, like 9/1/2026) and the collected general ledger amount.
B11: 4. Press Get rates on RECAP and pick the state's ST-3 import template for the month's quarter,
B12: downloaded from dor.georgia.gov/sales-use-tax-import. Every county's rate comes from it.
B13: The rates stay until the next quarter, so this is once a quarter.
B14: 5. Look at the light at the top of RECAP. Green means all clear. Red means open the REVIEW tab,
B15: where anything that needs you is marked LOOK, turns pink, and says what to do.
... B59: - No macros? GASalesTax.bas is the same macro as text; the steps at its top put it in this workbook.

Sheet RECAP
B2: GA sales tax recap | F2: =IF(REVIEW!$E$2=0,"All clear"&IF(REVIEW!$E$26>0,". Pipeline orders left off the return: "&REVIEW!$E$26,""),"CHECK THE REVIEW TAB: "&REVIEW!$E$2&IF(REVIEW!$E$2=1," thing needs"," things need")&" a look")
B3: Month: | D3: type the first of the month, like 9/1/2026
B4: Rates: | C4: =IF(RATES!$H$1="","none yet, press Get rates",RATES!$H$1&", for "&TEXT(RATES!$H$2,"m/d/yyyy")&" to "&TEXT(RATES!$I$2,"m/d/yyyy"))
B5: Does the month balance? We don't make money on taxes.
B6: Collected, A/R general ledger | D6: 0 | F6: type this from the GL
B7: Paid to suppliers, A/P general ledger | D7: 0 | F7: exempt with suppliers, stays 0 for Georgia
B8: Void/rebill crossing months (V/R) | D8: 0 | F8: tax on invoices voided or rebilled in another month; type it with its sign, usually 0
B9: Paid to the state, off-road | D9: =C31 | F9: line 13 below
B10: Paid to the state, on-road | D10: =D31 | F10: line 13 below
B11: Vendor's compensation kept, off-road | D11: =C28 | F11: line 10 below
B12: Vendor's compensation kept, on-road | D12: =D28 | F12: line 10 below
B14: Leftover (should be about zero) | D14: =D6-D7+D8-D9-D10-D11-D12
B15: Account number, on the state's files | F15: type each once and save; Make the state's files puts them on the template's Main tab
B17: Return lines: Make the state's files, or key these into the state site
C18: Off-road | D18: On-road
B19: 1. Total sales | C19: ='OFF ROAD RETURN'!E4 | D19: =SUMIF('ON ROAD RETURN'!$C$5:$C$336,"Diesel",'ON ROAD RETURN'!$E$5:$E$336)*'ON ROAD RETURN'!$C$2+SUMIF('ON ROAD RETURN'!$C$5:$C$336,"Gas",'ON ROAD RETURN'!$E$5:$E$336)*'ON ROAD RETURN'!$F$2 | F19: on-road: every gallon times the state-set price
B20: 2. Total exempt sales | C20: ='OFF ROAD RETURN'!F4 | D20: =D19 | F20: on-road: all of it, road fuel is exempt from state sales tax
B21: 3. Taxable state sales | C21: =C19-C20 | D21: =D19-D20
B22: 4. Total sales tax | C22: =ROUND('OFF ROAD RETURN'!I4,2) | D22: =ROUND(SUMIF('ON ROAD RETURN'!$N$5:$N$336,"line 4",'ON ROAD RETURN'!$I$5:$I$336),2) | F22: on-road: College Park only
B23: 5. Total use tax | C23: 0 | D23: 0 | F23: only if there's use tax to report, normally 0
B24: 6. Prepaid local sales/use | C24: 0 | D24: =ROUND('ON ROAD RETURN'!I4,2)-D22 | F24: on-road: all on-road tax except College Park
B25: 7. Total tax collected | C25: =ROUND('OFF ROAD RETURN'!H4,2) | D25: =ROUND('ON ROAD RETURN'!J4,2) | F25: from the return tabs
B26: 8. Total sales/use tax | C26: =C22+C23+C24 | D26: =D22+D23+D24 | F26: lines 4 + 5 + 6
B27: 9. Excess tax | C27: =MAX(0,ROUND(C25-C26,2)) | D27: =MAX(0,ROUND(D25-D26,2)) | F27: collected minus line 8, never below zero
B28: 10. Total vendor's compensation | C28: =ROUND(0.03*MIN(C22+C23+C27,3000)+0.005*MAX(C22+C23+C27-3000,0),2) | D28: =ROUND(0.03*D24,2)+ROUND(0.03*MIN(D22+D23+D27,3000)+0.005*MAX(D22+D23+D27-3000,0),2) | F28: only if filed and paid on time; check against the state site
B29: 11. Previous prepaid estimated tax | C29: 0 | D29: 0 | F29: from the prepaid estimated tax letter, if any, normally 0
B30: 12. Current prepaid estimated tax | C30: 0 | D30: 0 | F30: from the prepaid estimated tax letter, if any, normally 0
B31: 13. Total amount due | C31: =C26+C27-C28-C29+C30 | D31: =D26+D27-D28-D29+D30 | F31: lines 8 + 9 - 10 - 11 + 12

Sheet OFF ROAD RETURN
A1: Georgia off-road sales tax return
A2: One row per state code, from the AR SALES tab. Rates come from RATES for RECAP's month. Grey rows had no sales.
A3: State code | B3: Rate area | C3: Rate | D3: Local part of rate | E3: Total sales | F3: Exempt sales | G3: Taxable sales | H3: Tax collected | I3: Tax calculated | J3: Variance | K3: Local part of tax | L3: Rate rows found (helper)
A4: TOTAL | E4: =SUM(E5:E170) | F4: =SUM(F5:F170) | G4: =SUM(G5:G170) | H4: =SUM(H5:H170) | I4: =SUM(I5:I170) | J4: =SUM(J5:J170) | K4: =SUM(K5:K170)
A5: 001TE - Appling (TSPLOST Exempt) | B5: APPLING | C5: =IF($L5=1,SUMIFS(RATES!$F:$F,RATES!$A:$A,$A5,RATES!$B:$B,"<="&MonthStart,RATES!$C:$C,">="&MonthEnd),0) | D5: =IF($L5=1,SUMIFS(RATES!$E:$E,RATES!$A:$A,$A5,RATES!$B:$B,"<="&MonthStart,RATES!$C:$C,">="&MonthEnd),0) | E5: =SUMIFS('AR SALES'!$Y$2:$Y$2501,'AR SALES'!$AI$2:$AI$2501,$A5,'AR SALES'!$AD$2:$AD$2501,"OFF") | F5: =SUMIFS('AR SALES'!$Y$2:$Y$2501,'AR SALES'!$AI$2:$AI$2501,$A5,'AR SALES'!$AD$2:$AD$2501,"OFF",'AR SALES'!$J$2:$J$2501,"<>") | G5: =E5-F5 | H5: =SUMIFS('AR SALES'!$AA$2:$AA$2501,'AR SALES'!$AI$2:$AI$2501,$A5,'AR SALES'!$AD$2:$AD$2501,"OFF") | I5: =G5*C5 | J5: =H5-I5 | K5: =G5*D5 | L5: =COUNTIFS(RATES!$A:$A,$A5,RATES!$B:$B,"<="&MonthStart,RATES!$C:$C,">="&MonthEnd)
A6: 002TE - Atkinson (TSPLOST Exempt) | B6: ATKINSON | C6: =IF($L6=1,SUMIFS(RATES!$F:$F,RATES!$A:$A,$A6,RATES!$B:$B,"<="&MonthStart,RATES!$C:$C,">="&MonthEnd),0) | D6: =IF($L6=1,SUMIFS(RATES!$E:$E,RATES!$A:$A,$A6,RATES!$B:$B,"<="&MonthStart,RATES!$C:$C,">="&MonthEnd),0) | E6: =SUMIFS('AR SALES'!$Y$2:$Y$2501,'AR SALES'!$AI$2:$AI$2501,$A6,'AR SALES'!$AD$2:$AD$2501,"OFF") | F6: =SUMIFS('AR SALES'!$Y$2:$Y$2501,'AR SALES'!$AI$2:$AI$2501,$A6,'AR SALES'!$AD$2:$AD$2501,"OFF",'AR SALES'!$J$2:$J$2501,"<>") | G6: =E6-F6 | H6: =SUMIFS('AR SALES'!$AA$2:$AA$2501,'AR SALES'!$AI$2:$AI$2501,$A6,'AR SALES'!$AD$2:$AD$2501,"OFF") | I6: =G6*C6 | J6: =H6-I6 | K6: =G6*D6 | L6: =COUNTIFS(RATES!$A:$A,$A6,RATES!$B:$B,"<="&MonthStart,RATES!$C:$C,">="&MonthEnd)
A7: 003TE - Bacon (TSPLOST Exempt) | B7: BACON | C7: =IF($L7=1,SUMIFS(RATES!$F:$F,RATES!$A:$A,$A7,RATES!$B:$B,"<="&MonthStart,RATES!$C:$C,">="&MonthEnd),0) | D7: =IF($L7=1,SUMIFS(RATES!$E:$E,RATES!$A:$A,$A7,RATES!$B:$B,"<="&MonthStart,RATES!$C:$C,">="&MonthEnd),0) | E7: =SUMIFS('AR SALES'!$Y$2:$Y$2501,'AR SALES'!$AI$2:$AI$2501,$A7,'AR SALES'!$AD$2:$AD$2501,"OFF") | F7: =SUMIFS('AR SALES'!$Y$2:$Y$2501,'AR SALES'!$AI$2:$AI$2501,$A7,'AR SALES'!$AD$2:$AD$2501,"OFF",'AR SALES'!$J$2:$J$2501,"<>") | G7: =E7-F7 | H7: =SUMIFS('AR SALES'!$AA$2:$AA$2501,'AR SALES'!$AI$2:$AI$2501,$A7,'AR SALES'!$AD$2:$AD$2501,"OFF") | I7: =G7*C7 | J7: =H7-I7 | K7: =G7*D7 | L7: =COUNTIFS(RATES!$A:$A,$A7,RATES!$B:$B,"<="&MonthStart,RATES!$C:$C,">="&MonthEnd)
A8: 004TE - Baker (TSPLOST Exempt) | B8: BAKER | C8: =IF($L8=1,SUMIFS(RATES!$F:$F,RATES!$A:$A,$A8,RATES!$B:$B,"<="&MonthStart,RATES!$C:$C,">="&MonthEnd),0) | D8: =IF($L8=1,SUMIFS(RATES!$E:$E,RATES!$A:$A,$A8,RATES!$B:$B,"<="&MonthStart,RATES!$C:$C,">="&MonthEnd),0) | E8: =SUMIFS('AR SALES'!$Y$2:$Y$2501,'AR SALES'!$AI$2:$AI$2501,$A8,'AR SALES'!$AD$2:$AD$2501,"OFF") | F8: =SUMIFS('AR SALES'!$Y$2:$Y$2501,'AR SALES'!$AI$2:$AI$2501,$A8,'AR SALES'!$AD$2:$AD$2501,"OFF",'AR SALES'!$J$2:$J$2501,"<>") | G8: =E8-F8 | H8: =SUMIFS('AR SALES'!$AA$2:$AA$2501,'AR SALES'!$AI$2:$AI$2501,$A8,'AR SALES'!$AD$2:$AD$2501,"OFF") | I8: =G8*C8 | J8: =H8-I8 | K8: =G8*D8 | L8: =COUNTIFS(RATES!$A:$A,$A8,RATES!$B:$B,"<="&MonthStart,RATES!$C:$C,">="&MonthEnd)
A9: 005TE - Baldwin (TSPLOST Exempt) | B9: BALDWIN | C9: =IF($L9=1,SUMIFS(RATES!$F:$F,RATES!$A:$A,$A9,RATES!$B:$B,"<="&MonthStart,RATES!$C:$C,">="&MonthEnd),0) | D9: =IF($L9=1,SUMIFS(RATES!$E:$E,RATES!$A:$A,$A9,RATES!$B:$B,"<="&MonthStart,RATES!$C:$C,">="&MonthEnd),0) | E9: =SUMIFS('AR SALES'!$Y$2:$Y$2501,'AR SALES'!$AI$2:$AI$2501,$A9,'AR SALES'!$AD$2:$AD$2501,"OFF") | F9: =SUMIFS('AR SALES'!$Y$2:$Y$2501,'AR SALES'!$AI$2:$AI$2501,$A9,'AR SALES'!$AD$2:$AD$2501,"OFF",'AR SALES'!$J$2:$J$2501,"<>") | G9: =E9-F9 | H9: =SUMIFS('AR SALES'!$AA$2:$AA$2501,'AR SALES'!$AI$2:$AI$2501,$A9,'AR SALES'!$AD$2:$AD$2501,"OFF") | I9: =G9*C9 | J9: =H9-I9 | K9: =G9*D9 | L9: =COUNTIFS(RATES!$A:$A,$A9,RATES!$B:$B,"<="&MonthStart,RATES!$C:$C,">="&MonthEnd)
A10: 006TE - Banks (TSPLOST Exempt) | B10: BANKS | C10: =IF($L10=1,SUMIFS(RATES!$F:$F,RATES!$A:$A,$A10,RATES!$B:$B,"<="&MonthStart,RATES!$C:$C,">="&MonthEnd),0) | D10: =IF($L10=1,SUMIFS(RATES!$E:$E,RATES!$A:$A,$A10,RATES!$B:$B,"<="&MonthStart,RATES!$C:$C,">="&MonthEnd),0) | E10: =SUMIFS('AR SALES'!$Y$2:$Y$2501,'AR SALES'!$AI$2:$AI$2501,$A10,'AR SALES'!$AD$2:$AD$2501,"OFF") | F10: =SUMIFS('AR SALES'!$Y$2:$Y$2501,'AR SALES'!$AI$2:$AI$2501,$A10,'AR SALES'!$AD$2:$AD$2501,"OFF",'AR SALES'!$J$2:$J$2501,"<>") | G10: =E10-F10 | H10: =SUMIFS('AR SALES'!$AA$2:$AA$2501,'AR SALES'!$AI$2:$AI$2501,$A10,'AR SALES'!$AD$2:$AD$2501,"OFF") | I10: =G10*C10 | J10: =H10-I10 | K10: =G10*D10 | L10: =COUNTIFS(RATES!$A:$A,$A10,RATES!$B:$B,"<="&MonthStart,RATES!$C:$C,">="&MonthEnd)
A11: 007TE - Barrow (TSPLOST Exempt) | B11: BARROW | C11: =IF($L11=1,SUMIFS(RATES!$F:$F,RATES!$A:$A,$A11,RATES!$B:$B,"<="&MonthStart,RATES!$C:$C,">="&MonthEnd),0) | D11: =IF($L11=1,SUMIFS(RATES!$E:$E,RATES!$A:$A,$A11,RATES!$B:$B,"<="&MonthStart,RATES!$C:$C,">="&MonthEnd),0) | E11: =SUMIFS('AR SALES'!$Y$2:$Y$2501,'AR SALES'!$AI$2:$AI$2501,$A11,'AR SALES'!$AD$2:$AD$2501,"OFF") | F11: =SUMIFS('AR SALES'!$Y$2:$Y$2501,'AR SALES'!$AI$2:$AI$2501,$A11,'AR SALES'!$AD$2:$AD$2501,"OFF",'AR SALES'!$J$2:$J$2501,"<>") | G11: =E11-F11 | H11: =SUMIFS('AR SALES'!$AA$2:$AA$2501,'AR SALES'!$AI$2:$AI$2501,$A11,'AR SALES'!$AD$2:$AD$2501,"OFF") | I11: =G11*C11 | J11: =H11-I11 | K11: =G11*D11 | L11: =COUNTIFS(RATES!$A:$A,$A11,RATES!$B:$B,"<="&MonthStart,RATES!$C:$C,">="&MonthEnd)
A12: 008 - Bartow | B12: BARTOW | C12: =IF($L12=1,SUMIFS(RATES!$F:$F,RATES!$A:$A,$A12,RATES!$B:$B,"<="&MonthStart,RATES!$C:$C,">="&MonthEnd),0) | D12: =IF($L12=1,SUMIFS(RATES!$E:$E,RATES!$A:$A,$A12,RATES!$B:$B,"<="&MonthStart,RATES!$C:$C,">="&MonthEnd),0) | E12: =SUMIFS('AR SALES'!$Y$2:$Y$2501,'AR SALES'!$AI$2:$AI$2501,$A12,'AR SALES'!$AD$2:$AD$2501,"OFF") | F12: =SUMIFS('AR SALES'!$Y$2:$Y$2501,'AR SALES'!$AI$2:$AI$2501,$A12,'AR SALES'!$AD$2:$AD$2501,"OFF",'AR SALES'!$J$2:$J$2501,"<>") | G12: =E12-F12 | H12: =SUMIFS('AR SALES'!$AA$2:$AA$2501,'AR SALES'!$AI$2:$AI$2501,$A12,'AR SALES'!$AD$2:$AD$2501,"OFF") | I12: =G12*C12 | J12: =H12-I12 | K12: =G12*D12 | L12: =COUNTIFS(RATES!$A:$A,$A12,RATES!$B:$B,"<="&MonthStart,RATES!$C:$C,">="&MonthEnd)
A13: 009TE - Ben Hill (TSPLOST Exempt) | B13: BEN HILL | C13: =IF($L13=1,SUMIFS(RATES!$F:$F,RATES!$A:$A,$A13,RATES!$B:$B,"<="&MonthStart,RATES!$C:$C,">="&MonthEnd),0) | D13: =IF($L13=1,SUMIFS(RATES!$E:$E,RATES!$A:$A,$A13,RATES!$B:$B,"<="&MonthStart,RATES!$C:$C,">="&MonthEnd),0) | E13: =SUMIFS('AR SALES'!$Y$2:$Y$2501,'AR SALES'!$AI$2:$AI$2501,$A13,'AR SALES'!$AD$2:$AD$2501,"OFF") | F13: =SUMIFS('AR SALES'!$Y$2:$Y$2501,'AR SALES'!$AI$2:$AI$2501,$A13,'AR SALES'!$AD$2:$AD$2501,"OFF",'AR SALES'!$J$2:$J$2501,"<>") | G13: =E13-F13 | H13: =SUMIFS('AR SALES'!$AA$2:$AA$2501,'AR SALES'!$AI$2:$AI$2501,$A13,'AR SALES'!$AD$2:$AD$2501,"OFF") | I13: =G13*C13 | J13: =H13-I13 | K13: =G13*D13 | L13: =COUNTIFS(RATES!$A:$A,$A13,RATES!$B:$B,"<="&MonthStart,RATES!$C:$C,">="&MonthEnd)
A14: 010TE - Berrien (TSPLOST Exempt) | B14: BERRIEN | C14: =IF($L14=1,SUMIFS(RATES!$F:$F,RATES!$A:$A,$A14,RATES!$B:$B,"<="&MonthStart,RATES!$C:$C,">="&MonthEnd),0) | D14: =IF($L14=1,SUMIFS(RATES!$E:$E,RATES!$A:$A,$A14,RATES!$B:$B,"<="&MonthStart,RATES!$C:$C,">="&MonthEnd),0) | E14: =SUMIFS('AR SALES'!$Y$2:$Y$2501,'AR SALES'!$AI$2:$AI$2501,$A14,'AR SALES'!$AD$2:$AD$2501,"OFF") | F14: =SUMIFS('AR SALES'!$Y$2:$Y$2501,'AR SALES'!$AI$2:$AI$2501,$A14,'AR SALES'!$AD$2:$AD$2501,"OFF",'AR SALES'!$J$2:$J$2501,"<>") | G14: =E14-F14 | H14: =SUMIFS('AR SALES'!$AA$2:$AA$2501,'AR SALES'!$AI$2:$AI$2501,$A14,'AR SALES'!$AD$2:$AD$2501,"OFF") | I14: =G14*C14 | J14: =H14-I14 | K14: =G14*D14 | L14: =COUNTIFS(RATES!$A:$A,$A14,RATES!$B:$B,"<="&MonthStart,RATES!$C:$C,">="&MonthEnd)
A15: 011 - Bibb | B15: BIBB | C15: =IF($L15=1,SUMIFS(RATES!$F:$F,RATES!$A:$A,$A15,RATES!$B:$B,"<="&MonthStart,RATES!$C:$C,">="&MonthEnd),0) | D15: =IF($L15=1,SUMIFS(RATES!$E:$E,RATES!$A:$A,$A15,RATES!$B:$B,"<="&MonthStart,RATES!$C:$C,">="&MonthEnd),0) | E15: =SUMIFS('AR SALES'!$Y$2:$Y$2501,'AR SALES'!$AI$2:$AI$2501,$A15,'AR SALES'!$AD$2:$AD$2501,"OFF") | F15: =SUMIFS('AR SALES'!$Y$2:$Y$2501,'AR SALES'!$AI$2:$AI$2501,$A15,'AR SALES'!$AD$2:$AD$2501,"OFF",'AR SALES'!$J$2:$J$2501,"<>") | G15: =E15-F15 | H15: =SUMIFS('AR SALES'!$AA$2:$AA$2501,'AR SALES'!$AI$2:$AI$2501,$A15,'AR SALES'!$AD$2:$AD$2501,"OFF") | I15: =G15*C15 | J15: =H15-I15 | K15: =G15*D15 | L15: =COUNTIFS(RATES!$A:$A,$A15,RATES!$B:$B,"<="&MonthStart,RATES!$C:$C,">="&MonthEnd)
A16: 012TE -Bleckley (TSPLOST Exempt) | B16: BLECKLEY | C16: =IF($L16=1,SUMIFS(RATES!$F:$F,RATES!$A:$A,$A16,RATES!$B:$B,"<="&MonthStart,RATES!$C:$C,">="&MonthEnd),0) | D16: =IF($L16=1,SUMIFS(RATES!$E:$E,RATES!$A:$A,$A16,RATES!$B:$B,"<="&MonthStart,RATES!$C:$C,">="&MonthEnd),0) | E16: =SUMIFS('AR SALES'!$Y$2:$Y$2501,'AR SALES'!$AI$2:$AI$2501,$A16,'AR SALES'!$AD$2:$AD$2501,"OFF") | F16: =SUMIFS('AR SALES'!$Y$2:$Y$2501,'AR SALES'!$AI$2:$AI$2501,$A16,'AR SALES'!$AD$2:$AD$2501,"OFF",'AR SALES'!$J$2:$J$2501,"<>") | G16: =E16-F16 | H16: =SUMIFS('AR SALES'!$AA$2:$AA$2501,'AR SALES'!$AI$2:$AI$2501,$A16,'AR SALES'!$AD$2:$AD$2501,"OFF") | I16: =G16*C16 | J16: =H16-I16 | K16: =G16*D16 | L16: =COUNTIFS(RATES!$A:$A,$A16,RATES!$B:$B,"<="&MonthStart,RATES!$C:$C,">="&MonthEnd)
... A170: 804 - Clayton - City of College Park | B170: CLAYTON (COLLEGE PARK) | C170: =IF($L170=1,SUMIFS(RATES!$F:$F,RATES!$A:$A,$A170,RATES!$B:$B,"<="&MonthStart,RATES!$C:$C,">="&MonthEnd),0) | D170: =IF($L170=1,SUMIFS(RATES!$E:$E,RATES!$A:$A,$A170,RATES!$B:$B,"<="&MonthStart,RATES!$C:$C,">="&MonthEnd),0) | E170: =SUMIFS('AR SALES'!$Y$2:$Y$2501,'AR SALES'!$AI$2:$AI$2501,$A170,'AR SALES'!$AD$2:$AD$2501,"OFF") | F170: =SUMIFS('AR SALES'!$Y$2:$Y$2501,'AR SALES'!$AI$2:$AI$2501,$A170,'AR SALES'!$AD$2:$AD$2501,"OFF",'AR SALES'!$J$2:$J$2501,"<>") | G170: =E170-F170 | H170: =SUMIFS('AR SALES'!$AA$2:$AA$2501,'AR SALES'!$AI$2:$AI$2501,$A170,'AR SALES'!$AD$2:$AD$2501,"OFF") | I170: =G170*C170 | J170: =H170-I170 | K170: =G170*D170 | L170: =COUNTIFS(RATES!$A:$A,$A170,RATES!$B:$B,"<="&MonthStart,RATES!$C:$C,">="&MonthEnd)
A173: Cross-check against the TERSE (dyed diesel, product cost plus fees) | E173: TERSE says | F173: return says | G173: difference
A174: TERSE dyed, taxed lines | E174: =SUMIFS(TERSE!$AE$2:$AE$4001,TERSE!$F$2:$F$4001,"4",TERSE!$AB$2:$AB$4001,"<>0",TERSE!$AY$2:$AY$4001,"") | F174: =G4 | G174: =E174-F174 | H174: difference means an order's tax went stale; filter TERSE column BA for STALE to name it
A175: TERSE dyed, exempt lines | E175: =SUMIFS(TERSE!$AE$2:$AE$4001,TERSE!$F$2:$F$4001,"4",TERSE!$AB$2:$AB$4001,0,TERSE!$AY$2:$AY$4001,"") | F175: =F4 | G175: =E175-F175
A176: TERSE dyed, sales tax on the lines | E176: =SUMIFS(TERSE!$AB$2:$AB$4001,TERSE!$F$2:$F$4001,"4") | F176: =H4 | G176: =E176-F176

Sheet ON ROAD RETURN
A1: Georgia on-road sales tax return (gallons by state code by fuel)
A2: State-set price, Diesel: | C2: 3 | D2: Gas & Gasohol: | F2: 3 | G2: the state sets these every January and July, never above $3.00 by law; change them here
A3: State code | B3: Rate area | C3: Fuel | D3: Rate (local part) | E3: Gallons | F3: Exempt gallons | G3: Taxable gallons | H3: Taxable sales | I3: Tax calculated | J3: Tax collected | K3: Variance | L3: Gallons, exact (before rounding) | M3: Fuel type (for the state) | N3: Goes on | O3: Rate rows found (helper)
A4: TOTAL | E4: =SUM(E5:E336) | F4: =SUM(F5:F336) | G4: =SUM(G5:G336) | H4: =SUM(H5:H336) | I4: =SUM(I5:I336) | J4: =SUM(J5:J336) | K4: =SUM(K5:K336) | L4: =SUM(L5:L336)
A5: 001TE - Appling (TSPLOST Exempt) | B5: APPLING | C5: Diesel | D5: =IF($O5=1,SUMIFS(RATES!$E:$E,RATES!$A:$A,$A5,RATES!$B:$B,"<="&MonthStart,RATES!$C:$C,">="&MonthEnd),0) | E5: =ROUND(L5,0) | F5: =ROUND(SUMIFS(TERSE!$AX$2:$AX$4001,TERSE!$AZ$2:$AZ$4001,$A5,TERSE!$AV$2:$AV$4001,$C5,TERSE!$AY$2:$AY$4001,""),0) | G5: =E5-F5 | H5: =G5*IF($C5="Diesel",$C$2,$F$2) | I5: =H5*D5 | J5: =SUMIFS(TERSE!$AB$2:$AB$4001,TERSE!$AZ$2:$AZ$4001,$A5,TERSE!$AV$2:$AV$4001,$C5,TERSE!$AY$2:$AY$4001,"") | K5: =J5-I5 | L5: =SUMIFS(TERSE!$AW$2:$AW$4001,TERSE!$AZ$2:$AZ$4001,$A5,TERSE!$AV$2:$AV$4001,$C5,TERSE!$AY$2:$AY$4001,"") | M5: 2 - Diesel - Clear | N5: line 6 | O5: =COUNTIFS(RATES!$A:$A,$A5,RATES!$B:$B,"<="&MonthStart,RATES!$C:$C,">="&MonthEnd)
A6: 001TE - Appling (TSPLOST Exempt) | B6: APPLING | C6: Gas | D6: =IF($O6=1,SUMIFS(RATES!$E:$E,RATES!$A:$A,$A6,RATES!$B:$B,"<="&MonthStart,RATES!$C:$C,">="&MonthEnd),0) | E6: =ROUND(L6,0) | F6: =ROUND(SUMIFS(TERSE!$AX$2:$AX$4001,TERSE!$AZ$2:$AZ$4001,$A6,TERSE!$AV$2:$AV$4001,$C6,TERSE!$AY$2:$AY$4001,""),0) | G6: =E6-F6 | H6: =G6*IF($C6="Diesel",$C$2,$F$2) | I6: =H6*D6 | J6: =SUMIFS(TERSE!$AB$2:$AB$4001,TERSE!$AZ$2:$AZ$4001,$A6,TERSE!$AV$2:$AV$4001,$C6,TERSE!$AY$2:$AY$4001,"") | K6: =J6-I6 | L6: =SUMIFS(TERSE!$AW$2:$AW$4001,TERSE!$AZ$2:$AZ$4001,$A6,TERSE!$AV$2:$AV$4001,$C6,TERSE!$AY$2:$AY$4001,"") | M6: 1 - Gasoline | N6: line 6 | O6: =COUNTIFS(RATES!$A:$A,$A6,RATES!$B:$B,"<="&MonthStart,RATES!$C:$C,">="&MonthEnd)
A7: 002TE - Atkinson (TSPLOST Exempt) | B7: ATKINSON | C7: Diesel | D7: =IF($O7=1,SUMIFS(RATES!$E:$E,RATES!$A:$A,$A7,RATES!$B:$B,"<="&MonthStart,RATES!$C:$C,">="&MonthEnd),0) | E7: =ROUND(L7,0) | F7: =ROUND(SUMIFS(TERSE!$AX$2:$AX$4001,TERSE!$AZ$2:$AZ$4001,$A7,TERSE!$AV$2:$AV$4001,$C7,TERSE!$AY$2:$AY$4001,""),0) | G7: =E7-F7 | H7: =G7*IF($C7="Diesel",$C$2,$F$2) | I7: =H7*D7 | J7: =SUMIFS(TERSE!$AB$2:$AB$4001,TERSE!$AZ$2:$AZ$4001,$A7,TERSE!$AV$2:$AV$4001,$C7,TERSE!$AY$2:$AY$4001,"") | K7: =J7-I7 | L7: =SUMIFS(TERSE!$AW$2:$AW$4001,TERSE!$AZ$2:$AZ$4001,$A7,TERSE!$AV$2:$AV$4001,$C7,TERSE!$AY$2:$AY$4001,"") | M7: 2 - Diesel - Clear | N7: line 6 | O7: =COUNTIFS(RATES!$A:$A,$A7,RATES!$B:$B,"<="&MonthStart,RATES!$C:$C,">="&MonthEnd)
A8: 002TE - Atkinson (TSPLOST Exempt) | B8: ATKINSON | C8: Gas | D8: =IF($O8=1,SUMIFS(RATES!$E:$E,RATES!$A:$A,$A8,RATES!$B:$B,"<="&MonthStart,RATES!$C:$C,">="&MonthEnd),0) | E8: =ROUND(L8,0) | F8: =ROUND(SUMIFS(TERSE!$AX$2:$AX$4001,TERSE!$AZ$2:$AZ$4001,$A8,TERSE!$AV$2:$AV$4001,$C8,TERSE!$AY$2:$AY$4001,""),0) | G8: =E8-F8 | H8: =G8*IF($C8="Diesel",$C$2,$F$2) | I8: =H8*D8 | J8: =SUMIFS(TERSE!$AB$2:$AB$4001,TERSE!$AZ$2:$AZ$4001,$A8,TERSE!$AV$2:$AV$4001,$C8,TERSE!$AY$2:$AY$4001,"") | K8: =J8-I8 | L8: =SUMIFS(TERSE!$AW$2:$AW$4001,TERSE!$AZ$2:$AZ$4001,$A8,TERSE!$AV$2:$AV$4001,$C8,TERSE!$AY$2:$AY$4001,"") | M8: 1 - Gasoline | N8: line 6 | O8: =COUNTIFS(RATES!$A:$A,$A8,RATES!$B:$B,"<="&MonthStart,RATES!$C:$C,">="&MonthEnd)
A9: 003TE - Bacon (TSPLOST Exempt) | B9: BACON | C9: Diesel | D9: =IF($O9=1,SUMIFS(RATES!$E:$E,RATES!$A:$A,$A9,RATES!$B:$B,"<="&MonthStart,RATES!$C:$C,">="&MonthEnd),0) | E9: =ROUND(L9,0) | F9: =ROUND(SUMIFS(TERSE!$AX$2:$AX$4001,TERSE!$AZ$2:$AZ$4001,$A9,TERSE!$AV$2:$AV$4001,$C9,TERSE!$AY$2:$AY$4001,""),0) | G9: =E9-F9 | H9: =G9*IF($C9="Diesel",$C$2,$F$2) | I9: =H9*D9 | J9: =SUMIFS(TERSE!$AB$2:$AB$4001,TERSE!$AZ$2:$AZ$4001,$A9,TERSE!$AV$2:$AV$4001,$C9,TERSE!$AY$2:$AY$4001,"") | K9: =J9-I9 | L9: =SUMIFS(TERSE!$AW$2:$AW$4001,TERSE!$AZ$2:$AZ$4001,$A9,TERSE!$AV$2:$AV$4001,$C9,TERSE!$AY$2:$AY$4001,"") | M9: 2 - Diesel - Clear | N9: line 6 | O9: =COUNTIFS(RATES!$A:$A,$A9,RATES!$B:$B,"<="&MonthStart,RATES!$C:$C,">="&MonthEnd)
A10: 003TE - Bacon (TSPLOST Exempt) | B10: BACON | C10: Gas | D10: =IF($O10=1,SUMIFS(RATES!$E:$E,RATES!$A:$A,$A10,RATES!$B:$B,"<="&MonthStart,RATES!$C:$C,">="&MonthEnd),0) | E10: =ROUND(L10,0) | F10: =ROUND(SUMIFS(TERSE!$AX$2:$AX$4001,TERSE!$AZ$2:$AZ$4001,$A10,TERSE!$AV$2:$AV$4001,$C10,TERSE!$AY$2:$AY$4001,""),0) | G10: =E10-F10 | H10: =G10*IF($C10="Diesel",$C$2,$F$2) | I10: =H10*D10 | J10: =SUMIFS(TERSE!$AB$2:$AB$4001,TERSE!$AZ$2:$AZ$4001,$A10,TERSE!$AV$2:$AV$4001,$C10,TERSE!$AY$2:$AY$4001,"") | K10: =J10-I10 | L10: =SUMIFS(TERSE!$AW$2:$AW$4001,TERSE!$AZ$2:$AZ$4001,$A10,TERSE!$AV$2:$AV$4001,$C10,TERSE!$AY$2:$AY$4001,"") | M10: 1 - Gasoline | N10: line 6 | O10: =COUNTIFS(RATES!$A:$A,$A10,RATES!$B:$B,"<="&MonthStart,RATES!$C:$C,">="&MonthEnd)
A11: 004TE - Baker (TSPLOST Exempt) | B11: BAKER | C11: Diesel | D11: =IF($O11=1,SUMIFS(RATES!$E:$E,RATES!$A:$A,$A11,RATES!$B:$B,"<="&MonthStart,RATES!$C:$C,">="&MonthEnd),0) | E11: =ROUND(L11,0) | F11: =ROUND(SUMIFS(TERSE!$AX$2:$AX$4001,TERSE!$AZ$2:$AZ$4001,$A11,TERSE!$AV$2:$AV$4001,$C11,TERSE!$AY$2:$AY$4001,""),0) | G11: =E11-F11 | H11: =G11*IF($C11="Diesel",$C$2,$F$2) | I11: =H11*D11 | J11: =SUMIFS(TERSE!$AB$2:$AB$4001,TERSE!$AZ$2:$AZ$4001,$A11,TERSE!$AV$2:$AV$4001,$C11,TERSE!$AY$2:$AY$4001,"") | K11: =J11-I11 | L11: =SUMIFS(TERSE!$AW$2:$AW$4001,TERSE!$AZ$2:$AZ$4001,$A11,TERSE!$AV$2:$AV$4001,$C11,TERSE!$AY$2:$AY$4001,"") | M11: 2 - Diesel - Clear | N11: line 6 | O11: =COUNTIFS(RATES!$A:$A,$A11,RATES!$B:$B,"<="&MonthStart,RATES!$C:$C,">="&MonthEnd)
A12: 004TE - Baker (TSPLOST Exempt) | B12: BAKER | C12: Gas | D12: =IF($O12=1,SUMIFS(RATES!$E:$E,RATES!$A:$A,$A12,RATES!$B:$B,"<="&MonthStart,RATES!$C:$C,">="&MonthEnd),0) | E12: =ROUND(L12,0) | F12: =ROUND(SUMIFS(TERSE!$AX$2:$AX$4001,TERSE!$AZ$2:$AZ$4001,$A12,TERSE!$AV$2:$AV$4001,$C12,TERSE!$AY$2:$AY$4001,""),0) | G12: =E12-F12 | H12: =G12*IF($C12="Diesel",$C$2,$F$2) | I12: =H12*D12 | J12: =SUMIFS(TERSE!$AB$2:$AB$4001,TERSE!$AZ$2:$AZ$4001,$A12,TERSE!$AV$2:$AV$4001,$C12,TERSE!$AY$2:$AY$4001,"") | K12: =J12-I12 | L12: =SUMIFS(TERSE!$AW$2:$AW$4001,TERSE!$AZ$2:$AZ$4001,$A12,TERSE!$AV$2:$AV$4001,$C12,TERSE!$AY$2:$AY$4001,"") | M12: 1 - Gasoline | N12: line 6 | O12: =COUNTIFS(RATES!$A:$A,$A12,RATES!$B:$B,"<="&MonthStart,RATES!$C:$C,">="&MonthEnd)
A13: 005TE - Baldwin (TSPLOST Exempt) | B13: BALDWIN | C13: Diesel | D13: =IF($O13=1,SUMIFS(RATES!$E:$E,RATES!$A:$A,$A13,RATES!$B:$B,"<="&MonthStart,RATES!$C:$C,">="&MonthEnd),0) | E13: =ROUND(L13,0) | F13: =ROUND(SUMIFS(TERSE!$AX$2:$AX$4001,TERSE!$AZ$2:$AZ$4001,$A13,TERSE!$AV$2:$AV$4001,$C13,TERSE!$AY$2:$AY$4001,""),0) | G13: =E13-F13 | H13: =G13*IF($C13="Diesel",$C$2,$F$2) | I13: =H13*D13 | J13: =SUMIFS(TERSE!$AB$2:$AB$4001,TERSE!$AZ$2:$AZ$4001,$A13,TERSE!$AV$2:$AV$4001,$C13,TERSE!$AY$2:$AY$4001,"") | K13: =J13-I13 | L13: =SUMIFS(TERSE!$AW$2:$AW$4001,TERSE!$AZ$2:$AZ$4001,$A13,TERSE!$AV$2:$AV$4001,$C13,TERSE!$AY$2:$AY$4001,"") | M13: 2 - Diesel - Clear | N13: line 6 | O13: =COUNTIFS(RATES!$A:$A,$A13,RATES!$B:$B,"<="&MonthStart,RATES!$C:$C,">="&MonthEnd)
A14: 005TE - Baldwin (TSPLOST Exempt) | B14: BALDWIN | C14: Gas | D14: =IF($O14=1,SUMIFS(RATES!$E:$E,RATES!$A:$A,$A14,RATES!$B:$B,"<="&MonthStart,RATES!$C:$C,">="&MonthEnd),0) | E14: =ROUND(L14,0) | F14: =ROUND(SUMIFS(TERSE!$AX$2:$AX$4001,TERSE!$AZ$2:$AZ$4001,$A14,TERSE!$AV$2:$AV$4001,$C14,TERSE!$AY$2:$AY$4001,""),0) | G14: =E14-F14 | H14: =G14*IF($C14="Diesel",$C$2,$F$2) | I14: =H14*D14 | J14: =SUMIFS(TERSE!$AB$2:$AB$4001,TERSE!$AZ$2:$AZ$4001,$A14,TERSE!$AV$2:$AV$4001,$C14,TERSE!$AY$2:$AY$4001,"") | K14: =J14-I14 | L14: =SUMIFS(TERSE!$AW$2:$AW$4001,TERSE!$AZ$2:$AZ$4001,$A14,TERSE!$AV$2:$AV$4001,$C14,TERSE!$AY$2:$AY$4001,"") | M14: 1 - Gasoline | N14: line 6 | O14: =COUNTIFS(RATES!$A:$A,$A14,RATES!$B:$B,"<="&MonthStart,RATES!$C:$C,">="&MonthEnd)
A15: 006TE - Banks (TSPLOST Exempt) | B15: BANKS | C15: Diesel | D15: =IF($O15=1,SUMIFS(RATES!$E:$E,RATES!$A:$A,$A15,RATES!$B:$B,"<="&MonthStart,RATES!$C:$C,">="&MonthEnd),0) | E15: =ROUND(L15,0) | F15: =ROUND(SUMIFS(TERSE!$AX$2:$AX$4001,TERSE!$AZ$2:$AZ$4001,$A15,TERSE!$AV$2:$AV$4001,$C15,TERSE!$AY$2:$AY$4001,""),0) | G15: =E15-F15 | H15: =G15*IF($C15="Diesel",$C$2,$F$2) | I15: =H15*D15 | J15: =SUMIFS(TERSE!$AB$2:$AB$4001,TERSE!$AZ$2:$AZ$4001,$A15,TERSE!$AV$2:$AV$4001,$C15,TERSE!$AY$2:$AY$4001,"") | K15: =J15-I15 | L15: =SUMIFS(TERSE!$AW$2:$AW$4001,TERSE!$AZ$2:$AZ$4001,$A15,TERSE!$AV$2:$AV$4001,$C15,TERSE!$AY$2:$AY$4001,"") | M15: 2 - Diesel - Clear | N15: line 6 | O15: =COUNTIFS(RATES!$A:$A,$A15,RATES!$B:$B,"<="&MonthStart,RATES!$C:$C,">="&MonthEnd)
A16: 006TE - Banks (TSPLOST Exempt) | B16: BANKS | C16: Gas | D16: =IF($O16=1,SUMIFS(RATES!$E:$E,RATES!$A:$A,$A16,RATES!$B:$B,"<="&MonthStart,RATES!$C:$C,">="&MonthEnd),0) | E16: =ROUND(L16,0) | F16: =ROUND(SUMIFS(TERSE!$AX$2:$AX$4001,TERSE!$AZ$2:$AZ$4001,$A16,TERSE!$AV$2:$AV$4001,$C16,TERSE!$AY$2:$AY$4001,""),0) | G16: =E16-F16 | H16: =G16*IF($C16="Diesel",$C$2,$F$2) | I16: =H16*D16 | J16: =SUMIFS(TERSE!$AB$2:$AB$4001,TERSE!$AZ$2:$AZ$4001,$A16,TERSE!$AV$2:$AV$4001,$C16,TERSE!$AY$2:$AY$4001,"") | K16: =J16-I16 | L16: =SUMIFS(TERSE!$AW$2:$AW$4001,TERSE!$AZ$2:$AZ$4001,$A16,TERSE!$AV$2:$AV$4001,$C16,TERSE!$AY$2:$AY$4001,"") | M16: 1 - Gasoline | N16: line 6 | O16: =COUNTIFS(RATES!$A:$A,$A16,RATES!$B:$B,"<="&MonthStart,RATES!$C:$C,">="&MonthEnd)
... A336: 804 - Clayton - City of College Park | B336: CLAYTON (COLLEGE PARK) | C336: Gas | D336: =IF($O336=1,SUMIFS(RATES!$E:$E,RATES!$A:$A,$A336,RATES!$B:$B,"<="&MonthStart,RATES!$C:$C,">="&MonthEnd),0) | E336: =ROUND(L336,0) | F336: =ROUND(SUMIFS(TERSE!$AX$2:$AX$4001,TERSE!$AZ$2:$AZ$4001,$A336,TERSE!$AV$2:$AV$4001,$C336,TERSE!$AY$2:$AY$4001,""),0) | G336: =E336-F336 | H336: =G336*IF($C336="Diesel",$C$2,$F$2) | I336: =H336*D336 | J336: =SUMIFS(TERSE!$AB$2:$AB$4001,TERSE!$AZ$2:$AZ$4001,$A336,TERSE!$AV$2:$AV$4001,$C336,TERSE!$AY$2:$AY$4001,"") | K336: =J336-I336 | L336: =SUMIFS(TERSE!$AW$2:$AW$4001,TERSE!$AZ$2:$AZ$4001,$A336,TERSE!$AV$2:$AV$4001,$C336,TERSE!$AY$2:$AY$4001,"") | M336: 1 - Gasoline | N336: line 6 | O336: =COUNTIFS(RATES!$A:$A,$A336,RATES!$B:$B,"<="&MonthStart,RATES!$C:$C,">="&MonthEnd)
A339: Did every gallon land somewhere?
A340: Gallons on this return, exact | E340: =L4
A341: Above-the-rack gallons (left off, counted on REVIEW) | E341: =SUMIFS(TERSE!$AW$2:$AW$4001,TERSE!$AY$2:$AY$4001,"YES")
A342: All on-road fuel gallons on the TERSE | E342: =SUM(TERSE!$AW$2:$AW$4001)
A343: Difference (should be zero) | E343: =E340+E341-E342

Sheet REVIEW
A1: Review, anything marked LOOK needs you
B2: Things that need a look | E2: =COUNTIF(D4:D34,"LOOK")
A3: 1. Did the reports paste in the expected shape? | D3: Look?
B4: All 14 key columns are where they should be | D4: =IF(COUNTIF(E5:E18,"OK")=14,"","LOOK") | E4: =IF(D4="","OK","a column moved") | F4: the checks are folded underneath; click the + on the left to open them
B5: AR SALES column H should be "Tax Name" | E5: =IF('AR SALES'!$H$1="Tax Name","OK","LOOK: a column moved, stop and check the paste")
B6: AR SALES column J should be "Tax Exemption" | E6: =IF('AR SALES'!$J$1="Tax Exemption","OK","LOOK: a column moved, stop and check the paste")
B7: AR SALES column L should be "Order Number" | E7: =IF('AR SALES'!$L$1="Order Number","OK","LOOK: a column moved, stop and check the paste")
B8: AR SALES column S should be "County" | E8: =IF('AR SALES'!$S$1="County","OK","LOOK: a column moved, stop and check the paste")
B9: AR SALES column Y should be "Taxable Sales" | E9: =IF('AR SALES'!$Y$1="Taxable Sales","OK","LOOK: a column moved, stop and check the paste")
B10: AR SALES column Z should be "Tax Rate" | E10: =IF('AR SALES'!$Z$1="Tax Rate","OK","LOOK: a column moved, stop and check the paste")
B11: AR SALES column AA should be "Total Sales Tax" | E11: =IF('AR SALES'!$AA$1="Total Sales Tax","OK","LOOK: a column moved, stop and check the paste")
B12: TERSE column E should be "Ship To County" | E12: =IF(TERSE!$E$1="Ship To County","OK","LOOK: a column moved, stop and check the paste")
B13: TERSE column F should be "Product Type" | E13: =IF(TERSE!$F$1="Product Type","OK","LOOK: a column moved, stop and check the paste")
B14: TERSE column L should be "Order Number" | E14: =IF(TERSE!$L$1="Order Number","OK","LOOK: a column moved, stop and check the paste")
B15: TERSE column R should be "Sold Qty" | E15: =IF(TERSE!$R$1="Sold Qty","OK","LOOK: a column moved, stop and check the paste")
B16: TERSE column Z should be "Total Taxes" | E16: =IF(TERSE!$Z$1="Total Taxes","OK","LOOK: a column moved, stop and check the paste")
B17: TERSE column AB should be "Total Sales Taxes" | E17: =IF(TERSE!$AB$1="Total Sales Taxes","OK","LOOK: a column moved, stop and check the paste")
B18: TERSE column AE should be "Total Product Excise" | E18: =IF(TERSE!$AE$1="Total Product Excise","OK","LOOK: a column moved, stop and check the paste")
A20: 2. Month health checks
B21: Rates on RATES cover RECAP's month | D21: =IF(E21<>"yes","LOOK","") | E21: =IF(AND(ISNUMBER(MonthStart),ISNUMBER(RATES!$H$2)),IF(AND(MonthStart>=RATES!$H$2,MonthEnd<=RATES!$I$2),"yes","no"),"no") | F21: type the month on RECAP; then press Get rates and pick the template for the month's quarter
B22: Off-road sales with no state code (AR) | D22: =IF(E22<>0,"LOOK","") | E22: =SUMIFS('AR SALES'!$Y$2:$Y$2501,'AR SALES'!$AD$2:$AD$2501,"OFF",'AR SALES'!$AI$2:$AI$2501,"NO CODE") | F22: filter AR SALES column AI for NO CODE; its rate area in column AH needs a row on CODES
B23: Off-road sales that didn't land on the return | D23: =IF(E23<>0,"LOOK","") | E23: =ROUND(SUMIFS('AR SALES'!$Y$2:$Y$2501,'AR SALES'!$AD$2:$AD$2501,"OFF")-'OFF ROAD RETURN'!E4,2) | F23: the line above names them, or a code on CODES is missing from the return tab
B24: State codes with sales but not exactly one rate | D24: =IF(E24<>0,"LOOK","") | E24: =SUMPRODUCT((ROUND('OFF ROAD RETURN'!$G$5:$G$170,2)<>0)*('OFF ROAD RETURN'!$L$5:$L$170<>1))+SUMPRODUCT(('ON ROAD RETURN'!$E$5:$E$336<>0)*('ON ROAD RETURN'!$O$5:$O$336<>1)) | F24: the template has no rate, or two, for that code and month; open RATES and look the code up
B25: AR lines charged a rate that isn't the state's | D25: =IF(E25<>0,"LOOK","") | E25: =COUNTIF('AR SALES'!$AK$2:$AK$2501,"DIFFERS") | F25: filter AR SALES column AK for DIFFERS; column AJ has the state's rate. The return uses the state's
B26: Pipeline orders left off the returns | E26: =COUNTIF(TERSE!$AY$2:$AY$4001,"YES") | F26: never a LOOK by itself; filter TERSE column AY to eyeball them
B27: Off-road stale-tax variance, dollars of base | E27: ='OFF ROAD RETURN'!G174 | F27: how far off the stale orders are; the line below lights up when this isn't 0
B28: Stale-tax rows flagged on the TERSE | D28: =IF(OR(E28<>0,ROUND(E27,2)<>0),"LOOK","") | E28: =COUNTIF(TERSE!$BA$2:$BA$4001,"STALE") | F28: filter TERSE column BA for STALE; small ones get filed as collected, no rebill
B29: Untaxed fuel with no exemption reason (TERSE) | D29: =IF(E29<>0,"LOOK","") | E29: =COUNTIF(TERSE!$BB$2:$BB$4001,"NO EXEMPTION") | F29: tax may have been missed; filter TERSE column BB for NO EXEMPTION
B30: On-road gallons with no state code (TERSE) | D30: =IF(ROUND(E30,1)<>0,"LOOK","") | E30: =SUMIFS(TERSE!$AW$2:$AW$4001,TERSE!$AZ$2:$AZ$4001,"NO CODE") | F30: filter TERSE column AZ for NO CODE; its rate area in column AU needs a row on CODES
B31: On-road variance, collected minus calculated | D31: =IF(ABS(E31)>=1,"LOOK","") | E31: ='ON ROAD RETURN'!K4 | F31: under a dollar is rounding; a dollar or more means a wrong rate or stale tax
B32: On-road gallons that landed nowhere | D32: =IF(ROUND(E32,1)<>0,"LOOK","") | E32: ='ON ROAD RETURN'!E343 | F32: the line above names them, or the TERSE has fuel outside Georgia
B33: Recap leftover | D33: =IF(ABS(E33)>=1,"LOOK","") | E33: =RECAP!D14 | F33: under a dollar is rounding; type the GL number first

Sheet AR SALES
A1: Tax State | B1: Tax State Name | C1: Destination State | D1: Destination State Name | E1: Category | F1: Import Export | G1: Category Import Export | H1: Tax Name | I1: Tax Class | J1: Tax Exemption | K1: Invoice Date | L1: Order Number | M1: Customer Name | N1: Ship To Name | O1: Address 1 | P1: Ship To City | Q1: Ship To State | R1: Ship To City State | S1: County | T1: Account Number | U1: Ship To Number | V1: Account Ship To | W1: Invoice Total | X1: Non Taxable Sales | Y1: Taxable Sales | Z1: Tax Rate | AA1: Total Sales Tax | AB1: lng Tax Class ID | AC1: cnt Tax ID | AD1: Road (helper) | AE1: On-road order key (helper) | AF1: Exempt (helper) | AG1: County on the tax line (helper) | AH1: Rate area (helper) | AI1: State code (helper) | AJ1: State's rate (helper) | AK1: Charged a different rate? (helper)
AD2: =IF($L2="","",IF(ISNUMBER(SEARCH("OFF ROAD",$H2)),"OFF",IF(ISNUMBER(SEARCH("ON ROAD",$H2)),"ON",""))) | AE2: =IF($AD2="ON",""&$L2,"") | AF2: =IF($L2="","",IF($J2<>"","Y","")) | AG2: =IF($L2="","",IFERROR(TRIM(MID($H2,4,SEARCH(" CO ",$H2)-4)),""&$S2)) | AH2: =IF($AG2="","",IF($AG2="FULTON",IF(ISNUMBER(SEARCH("COLLEGE PARK",$H2)),"FULTON (COLLEGE PARK)",IF(ISNUMBER(SEARCH("HAPEVILLE",$H2)),"FULTON (HAPEVILLE)",IF(ISNUMBER(SEARCH("EAST POINT",$H2)),"FULTON (EAST POINT)",IF(ISNUMBER(SEARCH("ATLANTA",$H2)),"FULTON (ATL LIMITS)","FULTON")))),IF($AG2="DEKALB",IF(ISNUMBER(SEARCH("ATLANTA",$H2)),"DEKALB (ATL LIMITS)","DEKALB"),IF(AND($AG2="CLAYTON",ISNUMBER(SEARCH("COLLEGE PARK",$H2))),"CLAYTON (COLLEGE PARK)",$AG2)))) | AI2: =IF(OR($AH2="",$AD2=""),"",IFERROR(VLOOKUP($AH2,CODES!$A:$B,2,FALSE),"NO CODE")) | AJ2: =IF(OR($AI2="",$AI2="NO CODE"),"",IF(COUNTIFS(RATES!$A:$A,$AI2,RATES!$B:$B,"<="&MonthStart,RATES!$C:$C,">="&MonthEnd)<>1,"NO RATE",IF($AD2="OFF",SUMIFS(RATES!$F:$F,RATES!$A:$A,$AI2,RATES!$B:$B,"<="&MonthStart,RATES!$C:$C,">="&MonthEnd),SUMIFS(RATES!$E:$E,RATES!$A:$A,$AI2,RATES!$B:$B,"<="&MonthStart,RATES!$C:$C,">="&MonthEnd)))) | AK2: =IF(OR(NOT(ISNUMBER($AJ2)),N($AA2)=0),"",IF(ABS(N($Z2)/100-$AJ2)>0.0000001,"DIFFERS",""))
AD3: =IF($L3="","",IF(ISNUMBER(SEARCH("OFF ROAD",$H3)),"OFF",IF(ISNUMBER(SEARCH("ON ROAD",$H3)),"ON",""))) | AE3: =IF($AD3="ON",""&$L3,"") | AF3: =IF($L3="","",IF($J3<>"","Y","")) | AG3: =IF($L3="","",IFERROR(TRIM(MID($H3,4,SEARCH(" CO ",$H3)-4)),""&$S3)) | AH3: =IF($AG3="","",IF($AG3="FULTON",IF(ISNUMBER(SEARCH("COLLEGE PARK",$H3)),"FULTON (COLLEGE PARK)",IF(ISNUMBER(SEARCH("HAPEVILLE",$H3)),"FULTON (HAPEVILLE)",IF(ISNUMBER(SEARCH("EAST POINT",$H3)),"FULTON (EAST POINT)",IF(ISNUMBER(SEARCH("ATLANTA",$H3)),"FULTON (ATL LIMITS)","FULTON")))),IF($AG3="DEKALB",IF(ISNUMBER(SEARCH("ATLANTA",$H3)),"DEKALB (ATL LIMITS)","DEKALB"),IF(AND($AG3="CLAYTON",ISNUMBER(SEARCH("COLLEGE PARK",$H3))),"CLAYTON (COLLEGE PARK)",$AG3)))) | AI3: =IF(OR($AH3="",$AD3=""),"",IFERROR(VLOOKUP($AH3,CODES!$A:$B,2,FALSE),"NO CODE")) | AJ3: =IF(OR($AI3="",$AI3="NO CODE"),"",IF(COUNTIFS(RATES!$A:$A,$AI3,RATES!$B:$B,"<="&MonthStart,RATES!$C:$C,">="&MonthEnd)<>1,"NO RATE",IF($AD3="OFF",SUMIFS(RATES!$F:$F,RATES!$A:$A,$AI3,RATES!$B:$B,"<="&MonthStart,RATES!$C:$C,">="&MonthEnd),SUMIFS(RATES!$E:$E,RATES!$A:$A,$AI3,RATES!$B:$B,"<="&MonthStart,RATES!$C:$C,">="&MonthEnd)))) | AK3: =IF(OR(NOT(ISNUMBER($AJ3)),N($AA3)=0),"",IF(ABS(N($Z3)/100-$AJ3)>0.0000001,"DIFFERS",""))
AD4: =IF($L4="","",IF(ISNUMBER(SEARCH("OFF ROAD",$H4)),"OFF",IF(ISNUMBER(SEARCH("ON ROAD",$H4)),"ON",""))) | AE4: =IF($AD4="ON",""&$L4,"") | AF4: =IF($L4="","",IF($J4<>"","Y","")) | AG4: =IF($L4="","",IFERROR(TRIM(MID($H4,4,SEARCH(" CO ",$H4)-4)),""&$S4)) | AH4: =IF($AG4="","",IF($AG4="FULTON",IF(ISNUMBER(SEARCH("COLLEGE PARK",$H4)),"FULTON (COLLEGE PARK)",IF(ISNUMBER(SEARCH("HAPEVILLE",$H4)),"FULTON (HAPEVILLE)",IF(ISNUMBER(SEARCH("EAST POINT",$H4)),"FULTON (EAST POINT)",IF(ISNUMBER(SEARCH("ATLANTA",$H4)),"FULTON (ATL LIMITS)","FULTON")))),IF($AG4="DEKALB",IF(ISNUMBER(SEARCH("ATLANTA",$H4)),"DEKALB (ATL LIMITS)","DEKALB"),IF(AND($AG4="CLAYTON",ISNUMBER(SEARCH("COLLEGE PARK",$H4))),"CLAYTON (COLLEGE PARK)",$AG4)))) | AI4: =IF(OR($AH4="",$AD4=""),"",IFERROR(VLOOKUP($AH4,CODES!$A:$B,2,FALSE),"NO CODE")) | AJ4: =IF(OR($AI4="",$AI4="NO CODE"),"",IF(COUNTIFS(RATES!$A:$A,$AI4,RATES!$B:$B,"<="&MonthStart,RATES!$C:$C,">="&MonthEnd)<>1,"NO RATE",IF($AD4="OFF",SUMIFS(RATES!$F:$F,RATES!$A:$A,$AI4,RATES!$B:$B,"<="&MonthStart,RATES!$C:$C,">="&MonthEnd),SUMIFS(RATES!$E:$E,RATES!$A:$A,$AI4,RATES!$B:$B,"<="&MonthStart,RATES!$C:$C,">="&MonthEnd)))) | AK4: =IF(OR(NOT(ISNUMBER($AJ4)),N($AA4)=0),"",IF(ABS(N($Z4)/100-$AJ4)>0.0000001,"DIFFERS",""))
AD5: =IF($L5="","",IF(ISNUMBER(SEARCH("OFF ROAD",$H5)),"OFF",IF(ISNUMBER(SEARCH("ON ROAD",$H5)),"ON",""))) | AE5: =IF($AD5="ON",""&$L5,"") | AF5: =IF($L5="","",IF($J5<>"","Y","")) | AG5: =IF($L5="","",IFERROR(TRIM(MID($H5,4,SEARCH(" CO ",$H5)-4)),""&$S5)) | AH5: =IF($AG5="","",IF($AG5="FULTON",IF(ISNUMBER(SEARCH("COLLEGE PARK",$H5)),"FULTON (COLLEGE PARK)",IF(ISNUMBER(SEARCH("HAPEVILLE",$H5)),"FULTON (HAPEVILLE)",IF(ISNUMBER(SEARCH("EAST POINT",$H5)),"FULTON (EAST POINT)",IF(ISNUMBER(SEARCH("ATLANTA",$H5)),"FULTON (ATL LIMITS)","FULTON")))),IF($AG5="DEKALB",IF(ISNUMBER(SEARCH("ATLANTA",$H5)),"DEKALB (ATL LIMITS)","DEKALB"),IF(AND($AG5="CLAYTON",ISNUMBER(SEARCH("COLLEGE PARK",$H5))),"CLAYTON (COLLEGE PARK)",$AG5)))) | AI5: =IF(OR($AH5="",$AD5=""),"",IFERROR(VLOOKUP($AH5,CODES!$A:$B,2,FALSE),"NO CODE")) | AJ5: =IF(OR($AI5="",$AI5="NO CODE"),"",IF(COUNTIFS(RATES!$A:$A,$AI5,RATES!$B:$B,"<="&MonthStart,RATES!$C:$C,">="&MonthEnd)<>1,"NO RATE",IF($AD5="OFF",SUMIFS(RATES!$F:$F,RATES!$A:$A,$AI5,RATES!$B:$B,"<="&MonthStart,RATES!$C:$C,">="&MonthEnd),SUMIFS(RATES!$E:$E,RATES!$A:$A,$AI5,RATES!$B:$B,"<="&MonthStart,RATES!$C:$C,">="&MonthEnd)))) | AK5: =IF(OR(NOT(ISNUMBER($AJ5)),N($AA5)=0),"",IF(ABS(N($Z5)/100-$AJ5)>0.0000001,"DIFFERS",""))
AD6: =IF($L6="","",IF(ISNUMBER(SEARCH("OFF ROAD",$H6)),"OFF",IF(ISNUMBER(SEARCH("ON ROAD",$H6)),"ON",""))) | AE6: =IF($AD6="ON",""&$L6,"") | AF6: =IF($L6="","",IF($J6<>"","Y","")) | AG6: =IF($L6="","",IFERROR(TRIM(MID($H6,4,SEARCH(" CO ",$H6)-4)),""&$S6)) | AH6: =IF($AG6="","",IF($AG6="FULTON",IF(ISNUMBER(SEARCH("COLLEGE PARK",$H6)),"FULTON (COLLEGE PARK)",IF(ISNUMBER(SEARCH("HAPEVILLE",$H6)),"FULTON (HAPEVILLE)",IF(ISNUMBER(SEARCH("EAST POINT",$H6)),"FULTON (EAST POINT)",IF(ISNUMBER(SEARCH("ATLANTA",$H6)),"FULTON (ATL LIMITS)","FULTON")))),IF($AG6="DEKALB",IF(ISNUMBER(SEARCH("ATLANTA",$H6)),"DEKALB (ATL LIMITS)","DEKALB"),IF(AND($AG6="CLAYTON",ISNUMBER(SEARCH("COLLEGE PARK",$H6))),"CLAYTON (COLLEGE PARK)",$AG6)))) | AI6: =IF(OR($AH6="",$AD6=""),"",IFERROR(VLOOKUP($AH6,CODES!$A:$B,2,FALSE),"NO CODE")) | AJ6: =IF(OR($AI6="",$AI6="NO CODE"),"",IF(COUNTIFS(RATES!$A:$A,$AI6,RATES!$B:$B,"<="&MonthStart,RATES!$C:$C,">="&MonthEnd)<>1,"NO RATE",IF($AD6="OFF",SUMIFS(RATES!$F:$F,RATES!$A:$A,$AI6,RATES!$B:$B,"<="&MonthStart,RATES!$C:$C,">="&MonthEnd),SUMIFS(RATES!$E:$E,RATES!$A:$A,$AI6,RATES!$B:$B,"<="&MonthStart,RATES!$C:$C,">="&MonthEnd)))) | AK6: =IF(OR(NOT(ISNUMBER($AJ6)),N($AA6)=0),"",IF(ABS(N($Z6)/100-$AJ6)>0.0000001,"DIFFERS",""))
AD7: =IF($L7="","",IF(ISNUMBER(SEARCH("OFF ROAD",$H7)),"OFF",IF(ISNUMBER(SEARCH("ON ROAD",$H7)),"ON",""))) | AE7: =IF($AD7="ON",""&$L7,"") | AF7: =IF($L7="","",IF($J7<>"","Y","")) | AG7: =IF($L7="","",IFERROR(TRIM(MID($H7,4,SEARCH(" CO ",$H7)-4)),""&$S7)) | AH7: =IF($AG7="","",IF($AG7="FULTON",IF(ISNUMBER(SEARCH("COLLEGE PARK",$H7)),"FULTON (COLLEGE PARK)",IF(ISNUMBER(SEARCH("HAPEVILLE",$H7)),"FULTON (HAPEVILLE)",IF(ISNUMBER(SEARCH("EAST POINT",$H7)),"FULTON (EAST POINT)",IF(ISNUMBER(SEARCH("ATLANTA",$H7)),"FULTON (ATL LIMITS)","FULTON")))),IF($AG7="DEKALB",IF(ISNUMBER(SEARCH("ATLANTA",$H7)),"DEKALB (ATL LIMITS)","DEKALB"),IF(AND($AG7="CLAYTON",ISNUMBER(SEARCH("COLLEGE PARK",$H7))),"CLAYTON (COLLEGE PARK)",$AG7)))) | AI7: =IF(OR($AH7="",$AD7=""),"",IFERROR(VLOOKUP($AH7,CODES!$A:$B,2,FALSE),"NO CODE")) | AJ7: =IF(OR($AI7="",$AI7="NO CODE"),"",IF(COUNTIFS(RATES!$A:$A,$AI7,RATES!$B:$B,"<="&MonthStart,RATES!$C:$C,">="&MonthEnd)<>1,"NO RATE",IF($AD7="OFF",SUMIFS(RATES!$F:$F,RATES!$A:$A,$AI7,RATES!$B:$B,"<="&MonthStart,RATES!$C:$C,">="&MonthEnd),SUMIFS(RATES!$E:$E,RATES!$A:$A,$AI7,RATES!$B:$B,"<="&MonthStart,RATES!$C:$C,">="&MonthEnd)))) | AK7: =IF(OR(NOT(ISNUMBER($AJ7)),N($AA7)=0),"",IF(ABS(N($Z7)/100-$AJ7)>0.0000001,"DIFFERS",""))
AD8: =IF($L8="","",IF(ISNUMBER(SEARCH("OFF ROAD",$H8)),"OFF",IF(ISNUMBER(SEARCH("ON ROAD",$H8)),"ON",""))) | AE8: =IF($AD8="ON",""&$L8,"") | AF8: =IF($L8="","",IF($J8<>"","Y","")) | AG8: =IF($L8="","",IFERROR(TRIM(MID($H8,4,SEARCH(" CO ",$H8)-4)),""&$S8)) | AH8: =IF($AG8="","",IF($AG8="FULTON",IF(ISNUMBER(SEARCH("COLLEGE PARK",$H8)),"FULTON (COLLEGE PARK)",IF(ISNUMBER(SEARCH("HAPEVILLE",$H8)),"FULTON (HAPEVILLE)",IF(ISNUMBER(SEARCH("EAST POINT",$H8)),"FULTON (EAST POINT)",IF(ISNUMBER(SEARCH("ATLANTA",$H8)),"FULTON (ATL LIMITS)","FULTON")))),IF($AG8="DEKALB",IF(ISNUMBER(SEARCH("ATLANTA",$H8)),"DEKALB (ATL LIMITS)","DEKALB"),IF(AND($AG8="CLAYTON",ISNUMBER(SEARCH("COLLEGE PARK",$H8))),"CLAYTON (COLLEGE PARK)",$AG8)))) | AI8: =IF(OR($AH8="",$AD8=""),"",IFERROR(VLOOKUP($AH8,CODES!$A:$B,2,FALSE),"NO CODE")) | AJ8: =IF(OR($AI8="",$AI8="NO CODE"),"",IF(COUNTIFS(RATES!$A:$A,$AI8,RATES!$B:$B,"<="&MonthStart,RATES!$C:$C,">="&MonthEnd)<>1,"NO RATE",IF($AD8="OFF",SUMIFS(RATES!$F:$F,RATES!$A:$A,$AI8,RATES!$B:$B,"<="&MonthStart,RATES!$C:$C,">="&MonthEnd),SUMIFS(RATES!$E:$E,RATES!$A:$A,$AI8,RATES!$B:$B,"<="&MonthStart,RATES!$C:$C,">="&MonthEnd)))) | AK8: =IF(OR(NOT(ISNUMBER($AJ8)),N($AA8)=0),"",IF(ABS(N($Z8)/100-$AJ8)>0.0000001,"DIFFERS",""))
AD9: =IF($L9="","",IF(ISNUMBER(SEARCH("OFF ROAD",$H9)),"OFF",IF(ISNUMBER(SEARCH("ON ROAD",$H9)),"ON",""))) | AE9: =IF($AD9="ON",""&$L9,"") | AF9: =IF($L9="","",IF($J9<>"","Y","")) | AG9: =IF($L9="","",IFERROR(TRIM(MID($H9,4,SEARCH(" CO ",$H9)-4)),""&$S9)) | AH9: =IF($AG9="","",IF($AG9="FULTON",IF(ISNUMBER(SEARCH("COLLEGE PARK",$H9)),"FULTON (COLLEGE PARK)",IF(ISNUMBER(SEARCH("HAPEVILLE",$H9)),"FULTON (HAPEVILLE)",IF(ISNUMBER(SEARCH("EAST POINT",$H9)),"FULTON (EAST POINT)",IF(ISNUMBER(SEARCH("ATLANTA",$H9)),"FULTON (ATL LIMITS)","FULTON")))),IF($AG9="DEKALB",IF(ISNUMBER(SEARCH("ATLANTA",$H9)),"DEKALB (ATL LIMITS)","DEKALB"),IF(AND($AG9="CLAYTON",ISNUMBER(SEARCH("COLLEGE PARK",$H9))),"CLAYTON (COLLEGE PARK)",$AG9)))) | AI9: =IF(OR($AH9="",$AD9=""),"",IFERROR(VLOOKUP($AH9,CODES!$A:$B,2,FALSE),"NO CODE")) | AJ9: =IF(OR($AI9="",$AI9="NO CODE"),"",IF(COUNTIFS(RATES!$A:$A,$AI9,RATES!$B:$B,"<="&MonthStart,RATES!$C:$C,">="&MonthEnd)<>1,"NO RATE",IF($AD9="OFF",SUMIFS(RATES!$F:$F,RATES!$A:$A,$AI9,RATES!$B:$B,"<="&MonthStart,RATES!$C:$C,">="&MonthEnd),SUMIFS(RATES!$E:$E,RATES!$A:$A,$AI9,RATES!$B:$B,"<="&MonthStart,RATES!$C:$C,">="&MonthEnd)))) | AK9: =IF(OR(NOT(ISNUMBER($AJ9)),N($AA9)=0),"",IF(ABS(N($Z9)/100-$AJ9)>0.0000001,"DIFFERS",""))
AD10: =IF($L10="","",IF(ISNUMBER(SEARCH("OFF ROAD",$H10)),"OFF",IF(ISNUMBER(SEARCH("ON ROAD",$H10)),"ON",""))) | AE10: =IF($AD10="ON",""&$L10,"") | AF10: =IF($L10="","",IF($J10<>"","Y","")) | AG10: =IF($L10="","",IFERROR(TRIM(MID($H10,4,SEARCH(" CO ",$H10)-4)),""&$S10)) | AH10: =IF($AG10="","",IF($AG10="FULTON",IF(ISNUMBER(SEARCH("COLLEGE PARK",$H10)),"FULTON (COLLEGE PARK)",IF(ISNUMBER(SEARCH("HAPEVILLE",$H10)),"FULTON (HAPEVILLE)",IF(ISNUMBER(SEARCH("EAST POINT",$H10)),"FULTON (EAST POINT)",IF(ISNUMBER(SEARCH("ATLANTA",$H10)),"FULTON (ATL LIMITS)","FULTON")))),IF($AG10="DEKALB",IF(ISNUMBER(SEARCH("ATLANTA",$H10)),"DEKALB (ATL LIMITS)","DEKALB"),IF(AND($AG10="CLAYTON",ISNUMBER(SEARCH("COLLEGE PARK",$H10))),"CLAYTON (COLLEGE PARK)",$AG10)))) | AI10: =IF(OR($AH10="",$AD10=""),"",IFERROR(VLOOKUP($AH10,CODES!$A:$B,2,FALSE),"NO CODE")) | AJ10: =IF(OR($AI10="",$AI10="NO CODE"),"",IF(COUNTIFS(RATES!$A:$A,$AI10,RATES!$B:$B,"<="&MonthStart,RATES!$C:$C,">="&MonthEnd)<>1,"NO RATE",IF($AD10="OFF",SUMIFS(RATES!$F:$F,RATES!$A:$A,$AI10,RATES!$B:$B,"<="&MonthStart,RATES!$C:$C,">="&MonthEnd),SUMIFS(RATES!$E:$E,RATES!$A:$A,$AI10,RATES!$B:$B,"<="&MonthStart,RATES!$C:$C,">="&MonthEnd)))) | AK10: =IF(OR(NOT(ISNUMBER($AJ10)),N($AA10)=0),"",IF(ABS(N($Z10)/100-$AJ10)>0.0000001,"DIFFERS",""))
AD11: =IF($L11="","",IF(ISNUMBER(SEARCH("OFF ROAD",$H11)),"OFF",IF(ISNUMBER(SEARCH("ON ROAD",$H11)),"ON",""))) | AE11: =IF($AD11="ON",""&$L11,"") | AF11: =IF($L11="","",IF($J11<>"","Y","")) | AG11: =IF($L11="","",IFERROR(TRIM(MID($H11,4,SEARCH(" CO ",$H11)-4)),""&$S11)) | AH11: =IF($AG11="","",IF($AG11="FULTON",IF(ISNUMBER(SEARCH("COLLEGE PARK",$H11)),"FULTON (COLLEGE PARK)",IF(ISNUMBER(SEARCH("HAPEVILLE",$H11)),"FULTON (HAPEVILLE)",IF(ISNUMBER(SEARCH("EAST POINT",$H11)),"FULTON (EAST POINT)",IF(ISNUMBER(SEARCH("ATLANTA",$H11)),"FULTON (ATL LIMITS)","FULTON")))),IF($AG11="DEKALB",IF(ISNUMBER(SEARCH("ATLANTA",$H11)),"DEKALB (ATL LIMITS)","DEKALB"),IF(AND($AG11="CLAYTON",ISNUMBER(SEARCH("COLLEGE PARK",$H11))),"CLAYTON (COLLEGE PARK)",$AG11)))) | AI11: =IF(OR($AH11="",$AD11=""),"",IFERROR(VLOOKUP($AH11,CODES!$A:$B,2,FALSE),"NO CODE")) | AJ11: =IF(OR($AI11="",$AI11="NO CODE"),"",IF(COUNTIFS(RATES!$A:$A,$AI11,RATES!$B:$B,"<="&MonthStart,RATES!$C:$C,">="&MonthEnd)<>1,"NO RATE",IF($AD11="OFF",SUMIFS(RATES!$F:$F,RATES!$A:$A,$AI11,RATES!$B:$B,"<="&MonthStart,RATES!$C:$C,">="&MonthEnd),SUMIFS(RATES!$E:$E,RATES!$A:$A,$AI11,RATES!$B:$B,"<="&MonthStart,RATES!$C:$C,">="&MonthEnd)))) | AK11: =IF(OR(NOT(ISNUMBER($AJ11)),N($AA11)=0),"",IF(ABS(N($Z11)/100-$AJ11)>0.0000001,"DIFFERS",""))
AD12: =IF($L12="","",IF(ISNUMBER(SEARCH("OFF ROAD",$H12)),"OFF",IF(ISNUMBER(SEARCH("ON ROAD",$H12)),"ON",""))) | AE12: =IF($AD12="ON",""&$L12,"") | AF12: =IF($L12="","",IF($J12<>"","Y","")) | AG12: =IF($L12="","",IFERROR(TRIM(MID($H12,4,SEARCH(" CO ",$H12)-4)),""&$S12)) | AH12: =IF($AG12="","",IF($AG12="FULTON",IF(ISNUMBER(SEARCH("COLLEGE PARK",$H12)),"FULTON (COLLEGE PARK)",IF(ISNUMBER(SEARCH("HAPEVILLE",$H12)),"FULTON (HAPEVILLE)",IF(ISNUMBER(SEARCH("EAST POINT",$H12)),"FULTON (EAST POINT)",IF(ISNUMBER(SEARCH("ATLANTA",$H12)),"FULTON (ATL LIMITS)","FULTON")))),IF($AG12="DEKALB",IF(ISNUMBER(SEARCH("ATLANTA",$H12)),"DEKALB (ATL LIMITS)","DEKALB"),IF(AND($AG12="CLAYTON",ISNUMBER(SEARCH("COLLEGE PARK",$H12))),"CLAYTON (COLLEGE PARK)",$AG12)))) | AI12: =IF(OR($AH12="",$AD12=""),"",IFERROR(VLOOKUP($AH12,CODES!$A:$B,2,FALSE),"NO CODE")) | AJ12: =IF(OR($AI12="",$AI12="NO CODE"),"",IF(COUNTIFS(RATES!$A:$A,$AI12,RATES!$B:$B,"<="&MonthStart,RATES!$C:$C,">="&MonthEnd)<>1,"NO RATE",IF($AD12="OFF",SUMIFS(RATES!$F:$F,RATES!$A:$A,$AI12,RATES!$B:$B,"<="&MonthStart,RATES!$C:$C,">="&MonthEnd),SUMIFS(RATES!$E:$E,RATES!$A:$A,$AI12,RATES!$B:$B,"<="&MonthStart,RATES!$C:$C,">="&MonthEnd)))) | AK12: =IF(OR(NOT(ISNUMBER($AJ12)),N($AA12)=0),"",IF(ABS(N($Z12)/100-$AJ12)>0.0000001,"DIFFERS",""))
AD13: =IF($L13="","",IF(ISNUMBER(SEARCH("OFF ROAD",$H13)),"OFF",IF(ISNUMBER(SEARCH("ON ROAD",$H13)),"ON",""))) | AE13: =IF($AD13="ON",""&$L13,"") | AF13: =IF($L13="","",IF($J13<>"","Y","")) | AG13: =IF($L13="","",IFERROR(TRIM(MID($H13,4,SEARCH(" CO ",$H13)-4)),""&$S13)) | AH13: =IF($AG13="","",IF($AG13="FULTON",IF(ISNUMBER(SEARCH("COLLEGE PARK",$H13)),"FULTON (COLLEGE PARK)",IF(ISNUMBER(SEARCH("HAPEVILLE",$H13)),"FULTON (HAPEVILLE)",IF(ISNUMBER(SEARCH("EAST POINT",$H13)),"FULTON (EAST POINT)",IF(ISNUMBER(SEARCH("ATLANTA",$H13)),"FULTON (ATL LIMITS)","FULTON")))),IF($AG13="DEKALB",IF(ISNUMBER(SEARCH("ATLANTA",$H13)),"DEKALB (ATL LIMITS)","DEKALB"),IF(AND($AG13="CLAYTON",ISNUMBER(SEARCH("COLLEGE PARK",$H13))),"CLAYTON (COLLEGE PARK)",$AG13)))) | AI13: =IF(OR($AH13="",$AD13=""),"",IFERROR(VLOOKUP($AH13,CODES!$A:$B,2,FALSE),"NO CODE")) | AJ13: =IF(OR($AI13="",$AI13="NO CODE"),"",IF(COUNTIFS(RATES!$A:$A,$AI13,RATES!$B:$B,"<="&MonthStart,RATES!$C:$C,">="&MonthEnd)<>1,"NO RATE",IF($AD13="OFF",SUMIFS(RATES!$F:$F,RATES!$A:$A,$AI13,RATES!$B:$B,"<="&MonthStart,RATES!$C:$C,">="&MonthEnd),SUMIFS(RATES!$E:$E,RATES!$A:$A,$AI13,RATES!$B:$B,"<="&MonthStart,RATES!$C:$C,">="&MonthEnd)))) | AK13: =IF(OR(NOT(ISNUMBER($AJ13)),N($AA13)=0),"",IF(ABS(N($Z13)/100-$AJ13)>0.0000001,"DIFFERS",""))
... AD2501: =IF($L2501="","",IF(ISNUMBER(SEARCH("OFF ROAD",$H2501)),"OFF",IF(ISNUMBER(SEARCH("ON ROAD",$H2501)),"ON",""))) | AE2501: =IF($AD2501="ON",""&$L2501,"") | AF2501: =IF($L2501="","",IF($J2501<>"","Y","")) | AG2501: =IF($L2501="","",IFERROR(TRIM(MID($H2501,4,SEARCH(" CO ",$H2501)-4)),""&$S2501)) | AH2501: =IF($AG2501="","",IF($AG2501="FULTON",IF(ISNUMBER(SEARCH("COLLEGE PARK",$H2501)),"FULTON (COLLEGE PARK)",IF(ISNUMBER(SEARCH("HAPEVILLE",$H2501)),"FULTON (HAPEVILLE)",IF(ISNUMBER(SEARCH("EAST POINT",$H2501)),"FULTON (EAST POINT)",IF(ISNUMBER(SEARCH("ATLANTA",$H2501)),"FULTON (ATL LIMITS)","FULTON")))),IF($AG2501="DEKALB",IF(ISNUMBER(SEARCH("ATLANTA",$H2501)),"DEKALB (ATL LIMITS)","DEKALB"),IF(AND($AG2501="CLAYTON",ISNUMBER(SEARCH("COLLEGE PARK",$H2501))),"CLAYTON (COLLEGE PARK)",$AG2501)))) | AI2501: =IF(OR($AH2501="",$AD2501=""),"",IFERROR(VLOOKUP($AH2501,CODES!$A:$B,2,FALSE),"NO CODE")) | AJ2501: =IF(OR($AI2501="",$AI2501="NO CODE"),"",IF(COUNTIFS(RATES!$A:$A,$AI2501,RATES!$B:$B,"<="&MonthStart,RATES!$C:$C,">="&MonthEnd)<>1,"NO RATE",IF($AD2501="OFF",SUMIFS(RATES!$F:$F,RATES!$A:$A,$AI2501,RATES!$B:$B,"<="&MonthStart,RATES!$C:$C,">="&MonthEnd),SUMIFS(RATES!$E:$E,RATES!$A:$A,$AI2501,RATES!$B:$B,"<="&MonthStart,RATES!$C:$C,">="&MonthEnd)))) | AK2501: =IF(OR(NOT(ISNUMBER($AJ2501)),N($AA2501)=0),"",IF(ABS(N($Z2501)/100-$AJ2501)>0.0000001,"DIFFERS",""))

Sheet TERSE
A1: Ship To State | B1: Ship To State Name | C1: Ship To City | D1: lng City ID | E1: Ship To County | F1: Product Type | G1: Product Type Name | H1: Customer Name | I1: Account Number | J1: Ship To Number | K1: Account Ship To | L1: Order Number | M1: Carrier | N1: Marketing Consultant | O1: Product | P1: Invoice Date | Q1: Ordered Qty | R1: Sold Qty | S1: Metered Qty | T1: Gross Profit | U1: Sold As | V1: Unit Price | W1: Qty Price | X1: Total Taxes Now | Y1: Total Taxes Deferred | Z1: Total Taxes | AA1: Total Excise Taxes | AB1: Total Sales Taxes | AC1: Line Total | AD1: Total Product | AE1: Total Product Excise | AF1: Ship To Name | AG1: Address 1 | AH1: Destination State | AI1: Bid ID | AJ1: Firm Contract | AK1: Firm Contract Adjustment | AL1: NYMEX Weekly Adjustment | AM1: Sold Qty No Svc | AN1: Gross Profit No Svc | AO1: Total Product No Svc | AP1: Total Product Excise No Svc | AQ1: Line Total No Svc | AR1: cnt Order Item ID | AS1: cnt Order ID | AT1: On-road tax line of the order (helper) | AU1: Rate area (helper) | AV1: Fuel (helper) | AW1: Gallons (helper) | AX1: Exempt gallons (helper) | AY1: Above the rack? (helper) | AZ1: State code (helper) | BA1: Stale off-road tax? (helper) | BB1: Untaxed with no exemption? (helper)
AT2: =IF($L2="","",IFERROR(INDEX('AR SALES'!$H$2:$H$2501,MATCH(""&$L2,'AR SALES'!$AE$2:$AE$2501,0)),"")) | AU2: =IF($L2="","",IF($A2<>"GA","",IF($E2="FULTON",IF(ISNUMBER(SEARCH("COLLEGE PARK",$AT2)),"FULTON (COLLEGE PARK)",IF(ISNUMBER(SEARCH("HAPEVILLE",$AT2)),"FULTON (HAPEVILLE)",IF(ISNUMBER(SEARCH("EAST POINT",$AT2)),"FULTON (EAST POINT)",IF(ISNUMBER(SEARCH("ATLANTA",$AT2)),"FULTON (ATL LIMITS)","FULTON")))),IF($E2="DEKALB",IF(ISNUMBER(SEARCH("ATLANTA",$AT2)),"DEKALB (ATL LIMITS)","DEKALB"),IF(AND($E2="CLAYTON",ISNUMBER(SEARCH("COLLEGE PARK",$AT2))),"CLAYTON (COLLEGE PARK)",$E2))))) | AV2: =IF($L2="","",IF(""&$F2="2","DIESEL",IF(OR(""&$F2="G",""&$F2="H"),"GAS",""))) | AW2: =IF($AV2="","",$R2) | AX2: =IF($AV2="","",IF($AB2=0,$R2,0)) | AY2: =IF($AV2="","",IF(AND($Z2=0,COUNTIF('AR SALES'!$L$2:$L$2501,$L2)=0),"YES","")) | AZ2: =IF($AV2="","",IFERROR(VLOOKUP($AU2,CODES!$A:$B,2,FALSE),"NO CODE")) | BA2: =IF(""&$F2<>"4","",IF($AY2="YES","",IF(ROUND(SUMIFS($AE$2:$AE$4001,$L$2:$L$4001,$L2,$F$2:$F$4001,"4")-SUMIFS('AR SALES'!$Y$2:$Y$2501,'AR SALES'!$L$2:$L$2501,$L2,'AR SALES'!$AD$2:$AD$2501,"OFF"),2)=0,"","STALE"))) | BB2: =IF(OR(""&$F2="2",""&$F2="4",""&$F2="G",""&$F2="H"),IF($AY2="YES","",IF($AB2<>0,"",IF(COUNTIFS('AR SALES'!$L$2:$L$2501,$L2,'AR SALES'!$AD$2:$AD$2501,IF(""&$F2="4","OFF","ON"),'AR SALES'!$AF$2:$AF$2501,"Y")>0,"","NO EXEMPTION"))),"")
AT3: =IF($L3="","",IFERROR(INDEX('AR SALES'!$H$2:$H$2501,MATCH(""&$L3,'AR SALES'!$AE$2:$AE$2501,0)),"")) | AU3: =IF($L3="","",IF($A3<>"GA","",IF($E3="FULTON",IF(ISNUMBER(SEARCH("COLLEGE PARK",$AT3)),"FULTON (COLLEGE PARK)",IF(ISNUMBER(SEARCH("HAPEVILLE",$AT3)),"FULTON (HAPEVILLE)",IF(ISNUMBER(SEARCH("EAST POINT",$AT3)),"FULTON (EAST POINT)",IF(ISNUMBER(SEARCH("ATLANTA",$AT3)),"FULTON (ATL LIMITS)","FULTON")))),IF($E3="DEKALB",IF(ISNUMBER(SEARCH("ATLANTA",$AT3)),"DEKALB (ATL LIMITS)","DEKALB"),IF(AND($E3="CLAYTON",ISNUMBER(SEARCH("COLLEGE PARK",$AT3))),"CLAYTON (COLLEGE PARK)",$E3))))) | AV3: =IF($L3="","",IF(""&$F3="2","DIESEL",IF(OR(""&$F3="G",""&$F3="H"),"GAS",""))) | AW3: =IF($AV3="","",$R3) | AX3: =IF($AV3="","",IF($AB3=0,$R3,0)) | AY3: =IF($AV3="","",IF(AND($Z3=0,COUNTIF('AR SALES'!$L$2:$L$2501,$L3)=0),"YES","")) | AZ3: =IF($AV3="","",IFERROR(VLOOKUP($AU3,CODES!$A:$B,2,FALSE),"NO CODE")) | BA3: =IF(""&$F3<>"4","",IF($AY3="YES","",IF(ROUND(SUMIFS($AE$2:$AE$4001,$L$2:$L$4001,$L3,$F$2:$F$4001,"4")-SUMIFS('AR SALES'!$Y$2:$Y$2501,'AR SALES'!$L$2:$L$2501,$L3,'AR SALES'!$AD$2:$AD$2501,"OFF"),2)=0,"","STALE"))) | BB3: =IF(OR(""&$F3="2",""&$F3="4",""&$F3="G",""&$F3="H"),IF($AY3="YES","",IF($AB3<>0,"",IF(COUNTIFS('AR SALES'!$L$2:$L$2501,$L3,'AR SALES'!$AD$2:$AD$2501,IF(""&$F3="4","OFF","ON"),'AR SALES'!$AF$2:$AF$2501,"Y")>0,"","NO EXEMPTION"))),"")
AT4: =IF($L4="","",IFERROR(INDEX('AR SALES'!$H$2:$H$2501,MATCH(""&$L4,'AR SALES'!$AE$2:$AE$2501,0)),"")) | AU4: =IF($L4="","",IF($A4<>"GA","",IF($E4="FULTON",IF(ISNUMBER(SEARCH("COLLEGE PARK",$AT4)),"FULTON (COLLEGE PARK)",IF(ISNUMBER(SEARCH("HAPEVILLE",$AT4)),"FULTON (HAPEVILLE)",IF(ISNUMBER(SEARCH("EAST POINT",$AT4)),"FULTON (EAST POINT)",IF(ISNUMBER(SEARCH("ATLANTA",$AT4)),"FULTON (ATL LIMITS)","FULTON")))),IF($E4="DEKALB",IF(ISNUMBER(SEARCH("ATLANTA",$AT4)),"DEKALB (ATL LIMITS)","DEKALB"),IF(AND($E4="CLAYTON",ISNUMBER(SEARCH("COLLEGE PARK",$AT4))),"CLAYTON (COLLEGE PARK)",$E4))))) | AV4: =IF($L4="","",IF(""&$F4="2","DIESEL",IF(OR(""&$F4="G",""&$F4="H"),"GAS",""))) | AW4: =IF($AV4="","",$R4) | AX4: =IF($AV4="","",IF($AB4=0,$R4,0)) | AY4: =IF($AV4="","",IF(AND($Z4=0,COUNTIF('AR SALES'!$L$2:$L$2501,$L4)=0),"YES","")) | AZ4: =IF($AV4="","",IFERROR(VLOOKUP($AU4,CODES!$A:$B,2,FALSE),"NO CODE")) | BA4: =IF(""&$F4<>"4","",IF($AY4="YES","",IF(ROUND(SUMIFS($AE$2:$AE$4001,$L$2:$L$4001,$L4,$F$2:$F$4001,"4")-SUMIFS('AR SALES'!$Y$2:$Y$2501,'AR SALES'!$L$2:$L$2501,$L4,'AR SALES'!$AD$2:$AD$2501,"OFF"),2)=0,"","STALE"))) | BB4: =IF(OR(""&$F4="2",""&$F4="4",""&$F4="G",""&$F4="H"),IF($AY4="YES","",IF($AB4<>0,"",IF(COUNTIFS('AR SALES'!$L$2:$L$2501,$L4,'AR SALES'!$AD$2:$AD$2501,IF(""&$F4="4","OFF","ON"),'AR SALES'!$AF$2:$AF$2501,"Y")>0,"","NO EXEMPTION"))),"")
AT5: =IF($L5="","",IFERROR(INDEX('AR SALES'!$H$2:$H$2501,MATCH(""&$L5,'AR SALES'!$AE$2:$AE$2501,0)),"")) | AU5: =IF($L5="","",IF($A5<>"GA","",IF($E5="FULTON",IF(ISNUMBER(SEARCH("COLLEGE PARK",$AT5)),"FULTON (COLLEGE PARK)",IF(ISNUMBER(SEARCH("HAPEVILLE",$AT5)),"FULTON (HAPEVILLE)",IF(ISNUMBER(SEARCH("EAST POINT",$AT5)),"FULTON (EAST POINT)",IF(ISNUMBER(SEARCH("ATLANTA",$AT5)),"FULTON (ATL LIMITS)","FULTON")))),IF($E5="DEKALB",IF(ISNUMBER(SEARCH("ATLANTA",$AT5)),"DEKALB (ATL LIMITS)","DEKALB"),IF(AND($E5="CLAYTON",ISNUMBER(SEARCH("COLLEGE PARK",$AT5))),"CLAYTON (COLLEGE PARK)",$E5))))) | AV5: =IF($L5="","",IF(""&$F5="2","DIESEL",IF(OR(""&$F5="G",""&$F5="H"),"GAS",""))) | AW5: =IF($AV5="","",$R5) | AX5: =IF($AV5="","",IF($AB5=0,$R5,0)) | AY5: =IF($AV5="","",IF(AND($Z5=0,COUNTIF('AR SALES'!$L$2:$L$2501,$L5)=0),"YES","")) | AZ5: =IF($AV5="","",IFERROR(VLOOKUP($AU5,CODES!$A:$B,2,FALSE),"NO CODE")) | BA5: =IF(""&$F5<>"4","",IF($AY5="YES","",IF(ROUND(SUMIFS($AE$2:$AE$4001,$L$2:$L$4001,$L5,$F$2:$F$4001,"4")-SUMIFS('AR SALES'!$Y$2:$Y$2501,'AR SALES'!$L$2:$L$2501,$L5,'AR SALES'!$AD$2:$AD$2501,"OFF"),2)=0,"","STALE"))) | BB5: =IF(OR(""&$F5="2",""&$F5="4",""&$F5="G",""&$F5="H"),IF($AY5="YES","",IF($AB5<>0,"",IF(COUNTIFS('AR SALES'!$L$2:$L$2501,$L5,'AR SALES'!$AD$2:$AD$2501,IF(""&$F5="4","OFF","ON"),'AR SALES'!$AF$2:$AF$2501,"Y")>0,"","NO EXEMPTION"))),"")
AT6: =IF($L6="","",IFERROR(INDEX('AR SALES'!$H$2:$H$2501,MATCH(""&$L6,'AR SALES'!$AE$2:$AE$2501,0)),"")) | AU6: =IF($L6="","",IF($A6<>"GA","",IF($E6="FULTON",IF(ISNUMBER(SEARCH("COLLEGE PARK",$AT6)),"FULTON (COLLEGE PARK)",IF(ISNUMBER(SEARCH("HAPEVILLE",$AT6)),"FULTON (HAPEVILLE)",IF(ISNUMBER(SEARCH("EAST POINT",$AT6)),"FULTON (EAST POINT)",IF(ISNUMBER(SEARCH("ATLANTA",$AT6)),"FULTON (ATL LIMITS)","FULTON")))),IF($E6="DEKALB",IF(ISNUMBER(SEARCH("ATLANTA",$AT6)),"DEKALB (ATL LIMITS)","DEKALB"),IF(AND($E6="CLAYTON",ISNUMBER(SEARCH("COLLEGE PARK",$AT6))),"CLAYTON (COLLEGE PARK)",$E6))))) | AV6: =IF($L6="","",IF(""&$F6="2","DIESEL",IF(OR(""&$F6="G",""&$F6="H"),"GAS",""))) | AW6: =IF($AV6="","",$R6) | AX6: =IF($AV6="","",IF($AB6=0,$R6,0)) | AY6: =IF($AV6="","",IF(AND($Z6=0,COUNTIF('AR SALES'!$L$2:$L$2501,$L6)=0),"YES","")) | AZ6: =IF($AV6="","",IFERROR(VLOOKUP($AU6,CODES!$A:$B,2,FALSE),"NO CODE")) | BA6: =IF(""&$F6<>"4","",IF($AY6="YES","",IF(ROUND(SUMIFS($AE$2:$AE$4001,$L$2:$L$4001,$L6,$F$2:$F$4001,"4")-SUMIFS('AR SALES'!$Y$2:$Y$2501,'AR SALES'!$L$2:$L$2501,$L6,'AR SALES'!$AD$2:$AD$2501,"OFF"),2)=0,"","STALE"))) | BB6: =IF(OR(""&$F6="2",""&$F6="4",""&$F6="G",""&$F6="H"),IF($AY6="YES","",IF($AB6<>0,"",IF(COUNTIFS('AR SALES'!$L$2:$L$2501,$L6,'AR SALES'!$AD$2:$AD$2501,IF(""&$F6="4","OFF","ON"),'AR SALES'!$AF$2:$AF$2501,"Y")>0,"","NO EXEMPTION"))),"")
AT7: =IF($L7="","",IFERROR(INDEX('AR SALES'!$H$2:$H$2501,MATCH(""&$L7,'AR SALES'!$AE$2:$AE$2501,0)),"")) | AU7: =IF($L7="","",IF($A7<>"GA","",IF($E7="FULTON",IF(ISNUMBER(SEARCH("COLLEGE PARK",$AT7)),"FULTON (COLLEGE PARK)",IF(ISNUMBER(SEARCH("HAPEVILLE",$AT7)),"FULTON (HAPEVILLE)",IF(ISNUMBER(SEARCH("EAST POINT",$AT7)),"FULTON (EAST POINT)",IF(ISNUMBER(SEARCH("ATLANTA",$AT7)),"FULTON (ATL LIMITS)","FULTON")))),IF($E7="DEKALB",IF(ISNUMBER(SEARCH("ATLANTA",$AT7)),"DEKALB (ATL LIMITS)","DEKALB"),IF(AND($E7="CLAYTON",ISNUMBER(SEARCH("COLLEGE PARK",$AT7))),"CLAYTON (COLLEGE PARK)",$E7))))) | AV7: =IF($L7="","",IF(""&$F7="2","DIESEL",IF(OR(""&$F7="G",""&$F7="H"),"GAS",""))) | AW7: =IF($AV7="","",$R7) | AX7: =IF($AV7="","",IF($AB7=0,$R7,0)) | AY7: =IF($AV7="","",IF(AND($Z7=0,COUNTIF('AR SALES'!$L$2:$L$2501,$L7)=0),"YES","")) | AZ7: =IF($AV7="","",IFERROR(VLOOKUP($AU7,CODES!$A:$B,2,FALSE),"NO CODE")) | BA7: =IF(""&$F7<>"4","",IF($AY7="YES","",IF(ROUND(SUMIFS($AE$2:$AE$4001,$L$2:$L$4001,$L7,$F$2:$F$4001,"4")-SUMIFS('AR SALES'!$Y$2:$Y$2501,'AR SALES'!$L$2:$L$2501,$L7,'AR SALES'!$AD$2:$AD$2501,"OFF"),2)=0,"","STALE"))) | BB7: =IF(OR(""&$F7="2",""&$F7="4",""&$F7="G",""&$F7="H"),IF($AY7="YES","",IF($AB7<>0,"",IF(COUNTIFS('AR SALES'!$L$2:$L$2501,$L7,'AR SALES'!$AD$2:$AD$2501,IF(""&$F7="4","OFF","ON"),'AR SALES'!$AF$2:$AF$2501,"Y")>0,"","NO EXEMPTION"))),"")
