Workbook
Name StateList: States!$A$2:$A$52

Sheet State
B1: State info
B2: Pick a state in the yellow box. Everything below comes from the other tabs; make changes there.
B3: State | C3: GA | D3: =IF($A$4="","",INDEX(States!$B$2:$B$1000,$A$4)) -> Georgia
A4: =IFERROR(MATCH($C$3,States!$A$2:$A$1000,0),"") -> 11
B5: Basics
B6: Tax agency | C6: =IF($A$4="","",IF(INDEX(States!C$2:C$1000,$A$4)="","",INDEX(States!C$2:C$1000,$A$4))) -> Georgia Department of Revenue
B7: Website | C7: =IF($A$4="","",IF(INDEX(States!D$2:D$1000,$A$4)="","",IF(OR(LEFT(INDEX(States!D$2:D$1000,$A$4),4)="http",LEFT(INDEX(States!D$2:D$1000,$A$4),2)="\\",MID(INDEX(States!D$2:D$1000,$A$4),2,1)=":"),HYPERLINK(INDEX(States!D$2:D$1000,$A$4),INDEX(States!D$2:D$1000,$A$4)),INDEX(States!D$2:D$1000,$A$4)))) -> https://dor.georgia.gov
B8: Filing site | C8: =IF($A$4="","",IF(INDEX(States!E$2:E$1000,$A$4)="","",IF(OR(LEFT(INDEX(States!E$2:E$1000,$A$4),4)="http",LEFT(INDEX(States!E$2:E$1000,$A$4),2)="\\",MID(INDEX(States!E$2:E$1000,$A$4),2,1)=":"),HYPERLINK(INDEX(States!E$2:E$1000,$A$4),INDEX(States!E$2:E$1000,$A$4)),INDEX(States!E$2:E$1000,$A$4)))) -> https://gtc.dor.ga.gov
B9: Main phone | C9: =IF($A$4="","",IF(INDEX(States!F$2:F$1000,$A$4)="","",INDEX(States!F$2:F$1000,$A$4))) -> (877) 423-6711
B10: Bond required | C10: =IF($A$4="","",IF(INDEX(States!G$2:G$1000,$A$4)="","",INDEX(States!G$2:G$1000,$A$4)))
B11: Where the files live | C11: =IF($A$4="","",IF(INDEX(States!H$2:H$1000,$A$4)="","",IF(OR(LEFT(INDEX(States!H$2:H$1000,$A$4),4)="http",LEFT(INDEX(States!H$2:H$1000,$A$4),2)="\\",MID(INDEX(States!H$2:H$1000,$A$4),2,1)=":"),HYPERLINK(INDEX(States!H$2:H$1000,$A$4),INDEX(States!H$2:H$1000,$A$4)),INDEX(States!H$2:H$1000,$A$4))))
B12: Quirks | C12: =IF($A$4="","",IF(INDEX(States!I$2:I$1000,$A$4)="","",INDEX(States!I$2:I$1000,$A$4))) -> Two sales tax returns, on-road and off-road, both laid out like the ST-3. On-road is gallons by county, two lines per county, and Fulton County splits by rate. State excise suspended Sept 29 to Nov 5, 2026, and state penalties for dyed diesel on the road waived Oct 6 to Nov 5.
B13: Source | C13: =IF($A$4="","",IF(INDEX(States!J$2:J$1000,$A$4)="","",IF(OR(LEFT(INDEX(States!J$2:J$1000,$A$4),4)="http",LEFT(INDEX(States!J$2:J$1000,$A$4),2)="\\",MID(INDEX(States!J$2:J$1000,$A$4),2,1)=":"),HYPERLINK(INDEX(States!J$2:J$1000,$A$4),INDEX(States!J$2:J$1000,$A$4)),INDEX(States!J$2:J$1000,$A$4)))) -> https://dor.georgia.gov/find-contact-information-topic
B14: Last checked | C14: =IF($A$4="","",IF(INDEX(States!K$2:K$1000,$A$4)="","",INDEX(States!K$2:K$1000,$A$4))) -> 46305
B16: ="Returns ("&COUNTIF(Returns!$A$2:$A$1000,$C$3)&")" -> Returns (4)
B17: Return | C17: Form | D17: Tax | E17: How often | F17: How to file | G17: How to pay | H17: Notes
A18: =IFERROR(_xlfn.AGGREGATE(15,6,(ROW(Returns!$A$2:$A$1000)-1)/(Returns!$A$2:$A$1000=$C$3),1),"") -> 1 | B18: =IF($A18="","",IF(INDEX(Returns!B$2:B$1000,$A18)="","",INDEX(Returns!B$2:B$1000,$A18))) -> Sales and use tax, on-road | C18: =IF($A18="","",IF(INDEX(Returns!C$2:C$1000,$A18)="","",INDEX(Returns!C$2:C$1000,$A18))) -> ST-3 layout | D18: =IF($A18="","",IF(INDEX(Returns!D$2:D$1000,$A18)="","",INDEX(Returns!D$2:D$1000,$A18))) -> Sales tax, mostly prepaid local | E18: =IF($A18="","",IF(INDEX(Returns!E$2:E$1000,$A18)="","",INDEX(Returns!E$2:E$1000,$A18))) -> Monthly | F18: =IF($A18="","",IF(INDEX(Returns!F$2:F$1000,$A18)="","",INDEX(Returns!F$2:F$1000,$A18))) -> Georgia Tax Center | G18: =IF($A18="","",IF(INDEX(Returns!G$2:G$1000,$A18)="","",INDEX(Returns!G$2:G$1000,$A18))) | H18: =IF($A18="","",IF(INDEX(Returns!H$2:H$1000,$A18)="","",INDEX(Returns!H$2:H$1000,$A18))) -> Gallons by county and product, two lines per county. College Park goes on line 4, every other county on line 6. Fulton County splits by rate.
A19: =IFERROR(_xlfn.AGGREGATE(15,6,(ROW(Returns!$A$2:$A$1000)-1)/(Returns!$A$2:$A$1000=$C$3),2),"") -> 2 | B19: =IF($A19="","",IF(INDEX(Returns!B$2:B$1000,$A19)="","",INDEX(Returns!B$2:B$1000,$A19))) -> Sales and use tax, off-road | C19: =IF($A19="","",IF(INDEX(Returns!C$2:C$1000,$A19)="","",INDEX(Returns!C$2:C$1000,$A19))) -> ST-3 layout | D19: =IF($A19="","",IF(INDEX(Returns!D$2:D$1000,$A19)="","",INDEX(Returns!D$2:D$1000,$A19))) -> Sales and use tax | E19: =IF($A19="","",IF(INDEX(Returns!E$2:E$1000,$A19)="","",INDEX(Returns!E$2:E$1000,$A19))) -> Monthly | F19: =IF($A19="","",IF(INDEX(Returns!F$2:F$1000,$A19)="","",INDEX(Returns!F$2:F$1000,$A19))) -> Georgia Tax Center | G19: =IF($A19="","",IF(INDEX(Returns!G$2:G$1000,$A19)="","",INDEX(Returns!G$2:G$1000,$A19))) | H19: =IF($A19="","",IF(INDEX(Returns!H$2:H$1000,$A19)="","",INDEX(Returns!H$2:H$1000,$A19))) -> Dyed fuel. Georgia taxes the small per-gallon fees too, so taxable sales are product cost plus fees.
A20: =IFERROR(_xlfn.AGGREGATE(15,6,(ROW(Returns!$A$2:$A$1000)-1)/(Returns!$A$2:$A$1000=$C$3),3),"") -> 3 | B20: =IF($A20="","",IF(INDEX(Returns!B$2:B$1000,$A20)="","",INDEX(Returns!B$2:B$1000,$A20))) -> Motor fuel excise, distributor return | C20: =IF($A20="","",IF(INDEX(Returns!C$2:C$1000,$A20)="","",INDEX(Returns!C$2:C$1000,$A20))) | D20: =IF($A20="","",IF(INDEX(Returns!D$2:D$1000,$A20)="","",INDEX(Returns!D$2:D$1000,$A20))) -> State motor fuel excise | E20: =IF($A20="","",IF(INDEX(Returns!E$2:E$1000,$A20)="","",INDEX(Returns!E$2:E$1000,$A20))) -> Monthly | F20: =IF($A20="","",IF(INDEX(Returns!F$2:F$1000,$A20)="","",INDEX(Returns!F$2:F$1000,$A20))) -> Georgia Tax Center | G20: =IF($A20="","",IF(INDEX(Returns!G$2:G$1000,$A20)="","",INDEX(Returns!G$2:G$1000,$A20))) | H20: =IF($A20="","",IF(INDEX(Returns!H$2:H$1000,$A20)="","",INDEX(Returns!H$2:H$1000,$A20))) -> Schedules of Receipts and Disbursements. Sept 29 to Nov 5, 2026: report the gallons on both schedules, don't remit the excise.
A21: =IFERROR(_xlfn.AGGREGATE(15,6,(ROW(Returns!$A$2:$A$1000)-1)/(Returns!$A$2:$A$1000=$C$3),4),"") -> 4 | B21: =IF($A21="","",IF(INDEX(Returns!B$2:B$1000,$A21)="","",INDEX(Returns!B$2:B$1000,$A21))) -> Refund claim | C21: =IF($A21="","",IF(INDEX(Returns!C$2:C$1000,$A21)="","",INDEX(Returns!C$2:C$1000,$A21))) -> MFD-33, with MF-12 waivers | D21: =IF($A21="","",IF(INDEX(Returns!D$2:D$1000,$A21)="","",INDEX(Returns!D$2:D$1000,$A21))) -> Motor fuel excise refunds | E21: =IF($A21="","",IF(INDEX(Returns!E$2:E$1000,$A21)="","",INDEX(Returns!E$2:E$1000,$A21))) -> As needed | F21: =IF($A21="","",IF(INDEX(Returns!F$2:F$1000,$A21)="","",INDEX(Returns!F$2:F$1000,$A21))) -> Georgia Tax Center, as refund attachments | G21: =IF($A21="","",IF(INDEX(Returns!G$2:G$1000,$A21)="","",INDEX(Returns!G$2:G$1000,$A21))) | H21: =IF($A21="","",IF(INDEX(Returns!H$2:H$1000,$A21)="","",INDEX(Returns!H$2:H$1000,$A21))) -> One MF-12 per supplier per refund type, signed by the supplier before a notary. Each load's invoice copies go in merged into one PDF.
A22: =IFERROR(_xlfn.AGGREGATE(15,6,(ROW(Returns!$A$2:$A$1000)-1)/(Returns!$A$2:$A$1000=$C$3),5),"") | B22: =IF($A22="","",IF(INDEX(Returns!B$2:B$1000,$A22)="","",INDEX(Returns!B$2:B$1000,$A22))) | C22: =IF($A22="","",IF(INDEX(Returns!C$2:C$1000,$A22)="","",INDEX(Returns!C$2:C$1000,$A22))) | D22: =IF($A22="","",IF(INDEX(Returns!D$2:D$1000,$A22)="","",INDEX(Returns!D$2:D$1000,$A22))) | E22: =IF($A22="","",IF(INDEX(Returns!E$2:E$1000,$A22)="","",INDEX(Returns!E$2:E$1000,$A22))) | F22: =IF($A22="","",IF(INDEX(Returns!F$2:F$1000,$A22)="","",INDEX(Returns!F$2:F$1000,$A22))) | G22: =IF($A22="","",IF(INDEX(Returns!G$2:G$1000,$A22)="","",INDEX(Returns!G$2:G$1000,$A22))) | H22: =IF($A22="","",IF(INDEX(Returns!H$2:H$1000,$A22)="","",INDEX(Returns!H$2:H$1000,$A22)))
A23: =IFERROR(_xlfn.AGGREGATE(15,6,(ROW(Returns!$A$2:$A$1000)-1)/(Returns!$A$2:$A$1000=$C$3),6),"") | B23: =IF($A23="","",IF(INDEX(Returns!B$2:B$1000,$A23)="","",INDEX(Returns!B$2:B$1000,$A23))) | C23: =IF($A23="","",IF(INDEX(Returns!C$2:C$1000,$A23)="","",INDEX(Returns!C$2:C$1000,$A23))) | D23: =IF($A23="","",IF(INDEX(Returns!D$2:D$1000,$A23)="","",INDEX(Returns!D$2:D$1000,$A23))) | E23: =IF($A23="","",IF(INDEX(Returns!E$2:E$1000,$A23)="","",INDEX(Returns!E$2:E$1000,$A23))) | F23: =IF($A23="","",IF(INDEX(Returns!F$2:F$1000,$A23)="","",INDEX(Returns!F$2:F$1000,$A23))) | G23: =IF($A23="","",IF(INDEX(Returns!G$2:G$1000,$A23)="","",INDEX(Returns!G$2:G$1000,$A23))) | H23: =IF($A23="","",IF(INDEX(Returns!H$2:H$1000,$A23)="","",INDEX(Returns!H$2:H$1000,$A23)))
A24: =IFERROR(_xlfn.AGGREGATE(15,6,(ROW(Returns!$A$2:$A$1000)-1)/(Returns!$A$2:$A$1000=$C$3),7),"") | B24: =IF($A24="","",IF(INDEX(Returns!B$2:B$1000,$A24)="","",INDEX(Returns!B$2:B$1000,$A24))) | C24: =IF($A24="","",IF(INDEX(Returns!C$2:C$1000,$A24)="","",INDEX(Returns!C$2:C$1000,$A24))) | D24: =IF($A24="","",IF(INDEX(Returns!D$2:D$1000,$A24)="","",INDEX(Returns!D$2:D$1000,$A24))) | E24: =IF($A24="","",IF(INDEX(Returns!E$2:E$1000,$A24)="","",INDEX(Returns!E$2:E$1000,$A24))) | F24: =IF($A24="","",IF(INDEX(Returns!F$2:F$1000,$A24)="","",INDEX(Returns!F$2:F$1000,$A24))) | G24: =IF($A24="","",IF(INDEX(Returns!G$2:G$1000,$A24)="","",INDEX(Returns!G$2:G$1000,$A24))) | H24: =IF($A24="","",IF(INDEX(Returns!H$2:H$1000,$A24)="","",INDEX(Returns!H$2:H$1000,$A24)))
A25: =IFERROR(_xlfn.AGGREGATE(15,6,(ROW(Returns!$A$2:$A$1000)-1)/(Returns!$A$2:$A$1000=$C$3),8),"") | B25: =IF($A25="","",IF(INDEX(Returns!B$2:B$1000,$A25)="","",INDEX(Returns!B$2:B$1000,$A25))) | C25: =IF($A25="","",IF(INDEX(Returns!C$2:C$1000,$A25)="","",INDEX(Returns!C$2:C$1000,$A25))) | D25: =IF($A25="","",IF(INDEX(Returns!D$2:D$1000,$A25)="","",INDEX(Returns!D$2:D$1000,$A25))) | E25: =IF($A25="","",IF(INDEX(Returns!E$2:E$1000,$A25)="","",INDEX(Returns!E$2:E$1000,$A25))) | F25: =IF($A25="","",IF(INDEX(Returns!F$2:F$1000,$A25)="","",INDEX(Returns!F$2:F$1000,$A25))) | G25: =IF($A25="","",IF(INDEX(Returns!G$2:G$1000,$A25)="","",INDEX(Returns!G$2:G$1000,$A25))) | H25: =IF($A25="","",IF(INDEX(Returns!H$2:H$1000,$A25)="","",INDEX(Returns!H$2:H$1000,$A25)))
B26: =IF(COUNTIF(Returns!$A$2:$A$1000,$C$3)>8,"Plus "&(COUNTIF(Returns!$A$2:$A$1000,$C$3)-8)&" more on the Returns tab","")
B28: ="Licenses ("&COUNTIF(Licenses!$A$2:$A$1000,$C$3)&")" -> Licenses (1)
B29: License | C29: Number | D29: Expires | E29: Bond amount | F29: Renew how | H29: Notes
A30: =IFERROR(_xlfn.AGGREGATE(15,6,(ROW(Licenses!$A$2:$A$1000)-1)/(Licenses!$A$2:$A$1000=$C$3),1),"") -> 1 | B30: =IF($A30="","",IF(INDEX(Licenses!B$2:B$1000,$A30)="","",INDEX(Licenses!B$2:B$1000,$A30))) -> Motor fuel distributor | C30: =IF($A30="","",IF(INDEX(Licenses!C$2:C$1000,$A30)="","",INDEX(Licenses!C$2:C$1000,$A30))) | D30: =IF($A30="","",IF(INDEX(Licenses!D$2:D$1000,$A30)="","",INDEX(Licenses!D$2:D$1000,$A30))) | E30: =IF($A30="","",IF(INDEX(Licenses!E$2:E$1000,$A30)="","",INDEX(Licenses!E$2:E$1000,$A30))) | F30: =IF($A30="","",IF(INDEX(Licenses!F$2:F$1000,$A30)="","",INDEX(Licenses!F$2:F$1000,$A30))) | H30: =IF($A30="","",IF(INDEX(Licenses!G$2:G$1000,$A30)="","",INDEX(Licenses!G$2:G$1000,$A30))) -> Type the number and bond in at work.
A31: =IFERROR(_xlfn.AGGREGATE(15,6,(ROW(Licenses!$A$2:$A$1000)-1)/(Licenses!$A$2:$A$1000=$C$3),2),"") | B31: =IF($A31="","",IF(INDEX(Licenses!B$2:B$1000,$A31)="","",INDEX(Licenses!B$2:B$1000,$A31))) | C31: =IF($A31="","",IF(INDEX(Licenses!C$2:C$1000,$A31)="","",INDEX(Licenses!C$2:C$1000,$A31))) | D31: =IF($A31="","",IF(INDEX(Licenses!D$2:D$1000,$A31)="","",INDEX(Licenses!D$2:D$1000,$A31))) | E31: =IF($A31="","",IF(INDEX(Licenses!E$2:E$1000,$A31)="","",INDEX(Licenses!E$2:E$1000,$A31))) | F31: =IF($A31="","",IF(INDEX(Licenses!F$2:F$1000,$A31)="","",INDEX(Licenses!F$2:F$1000,$A31))) | H31: =IF($A31="","",IF(INDEX(Licenses!G$2:G$1000,$A31)="","",INDEX(Licenses!G$2:G$1000,$A31)))
A32: =IFERROR(_xlfn.AGGREGATE(15,6,(ROW(Licenses!$A$2:$A$1000)-1)/(Licenses!$A$2:$A$1000=$C$3),3),"") | B32: =IF($A32="","",IF(INDEX(Licenses!B$2:B$1000,$A32)="","",INDEX(Licenses!B$2:B$1000,$A32))) | C32: =IF($A32="","",IF(INDEX(Licenses!C$2:C$1000,$A32)="","",INDEX(Licenses!C$2:C$1000,$A32))) | D32: =IF($A32="","",IF(INDEX(Licenses!D$2:D$1000,$A32)="","",INDEX(Licenses!D$2:D$1000,$A32))) | E32: =IF($A32="","",IF(INDEX(Licenses!E$2:E$1000,$A32)="","",INDEX(Licenses!E$2:E$1000,$A32))) | F32: =IF($A32="","",IF(INDEX(Licenses!F$2:F$1000,$A32)="","",INDEX(Licenses!F$2:F$1000,$A32))) | H32: =IF($A32="","",IF(INDEX(Licenses!G$2:G$1000,$A32)="","",INDEX(Licenses!G$2:G$1000,$A32)))
A33: =IFERROR(_xlfn.AGGREGATE(15,6,(ROW(Licenses!$A$2:$A$1000)-1)/(Licenses!$A$2:$A$1000=$C$3),4),"") | B33: =IF($A33="","",IF(INDEX(Licenses!B$2:B$1000,$A33)="","",INDEX(Licenses!B$2:B$1000,$A33))) | C33: =IF($A33="","",IF(INDEX(Licenses!C$2:C$1000,$A33)="","",INDEX(Licenses!C$2:C$1000,$A33))) | D33: =IF($A33="","",IF(INDEX(Licenses!D$2:D$1000,$A33)="","",INDEX(Licenses!D$2:D$1000,$A33))) | E33: =IF($A33="","",IF(INDEX(Licenses!E$2:E$1000,$A33)="","",INDEX(Licenses!E$2:E$1000,$A33))) | F33: =IF($A33="","",IF(INDEX(Licenses!F$2:F$1000,$A33)="","",INDEX(Licenses!F$2:F$1000,$A33))) | H33: =IF($A33="","",IF(INDEX(Licenses!G$2:G$1000,$A33)="","",INDEX(Licenses!G$2:G$1000,$A33)))
A34: =IFERROR(_xlfn.AGGREGATE(15,6,(ROW(Licenses!$A$2:$A$1000)-1)/(Licenses!$A$2:$A$1000=$C$3),5),"") | B34: =IF($A34="","",IF(INDEX(Licenses!B$2:B$1000,$A34)="","",INDEX(Licenses!B$2:B$1000,$A34))) | C34: =IF($A34="","",IF(INDEX(Licenses!C$2:C$1000,$A34)="","",INDEX(Licenses!C$2:C$1000,$A34))) | D34: =IF($A34="","",IF(INDEX(Licenses!D$2:D$1000,$A34)="","",INDEX(Licenses!D$2:D$1000,$A34))) | E34: =IF($A34="","",IF(INDEX(Licenses!E$2:E$1000,$A34)="","",INDEX(Licenses!E$2:E$1000,$A34))) | F34: =IF($A34="","",IF(INDEX(Licenses!F$2:F$1000,$A34)="","",INDEX(Licenses!F$2:F$1000,$A34))) | H34: =IF($A34="","",IF(INDEX(Licenses!G$2:G$1000,$A34)="","",INDEX(Licenses!G$2:G$1000,$A34)))
A35: =IFERROR(_xlfn.AGGREGATE(15,6,(ROW(Licenses!$A$2:$A$1000)-1)/(Licenses!$A$2:$A$1000=$C$3),6),"") | B35: =IF($A35="","",IF(INDEX(Licenses!B$2:B$1000,$A35)="","",INDEX(Licenses!B$2:B$1000,$A35))) | C35: =IF($A35="","",IF(INDEX(Licenses!C$2:C$1000,$A35)="","",INDEX(Licenses!C$2:C$1000,$A35))) | D35: =IF($A35="","",IF(INDEX(Licenses!D$2:D$1000,$A35)="","",INDEX(Licenses!D$2:D$1000,$A35))) | E35: =IF($A35="","",IF(INDEX(Licenses!E$2:E$1000,$A35)="","",INDEX(Licenses!E$2:E$1000,$A35))) | F35: =IF($A35="","",IF(INDEX(Licenses!F$2:F$1000,$A35)="","",INDEX(Licenses!F$2:F$1000,$A35))) | H35: =IF($A35="","",IF(INDEX(Licenses!G$2:G$1000,$A35)="","",INDEX(Licenses!G$2:G$1000,$A35)))
B36: =IF(COUNTIF(Licenses!$A$2:$A$1000,$C$3)>6,"Plus "&(COUNTIF(Licenses!$A$2:$A$1000,$C$3)-6)&" more on the Licenses tab","")
B38: ="Current rates ("&SUMPRODUCT(((Rates!$A$2:$A$1000=$C$3)*((Rates!$G$2:$G$1000="")+(Rates!$G$2:$G$1000>=TODAY()))))&")" -> Current rates (5)
B39: Product | C39: Tax | D39: Rate | E39: Per | F39: From | G39: To | H39: Notes
A40: =IFERROR(_xlfn.AGGREGATE(15,6,(ROW(Rates!$A$2:$A$1000)-1)/((Rates!$A$2:$A$1000=$C$3)*((Rates!$G$2:$G$1000="")+(Rates!$G$2:$G$1000>=TODAY()))),1),"") -> 1 | B40: =IF($A40="","",IF(INDEX(Rates!B$2:B$1000,$A40)="","",INDEX(Rates!B$2:B$1000,$A40))) -> Gasoline | C40: =IF($A40="","",IF(INDEX(Rates!C$2:C$1000,$A40)="","",INDEX(Rates!C$2:C$1000,$A40))) -> State excise | D40: =IF($A40="","",IF(INDEX(Rates!D$2:D$1000,$A40)="","",INDEX(Rates!D$2:D$1000,$A40))) -> 0.333 | E40: =IF($A40="","",IF(INDEX(Rates!E$2:E$1000,$A40)="","",INDEX(Rates!E$2:E$1000,$A40))) -> $ a gallon | F40: =IF($A40="","",IF(INDEX(Rates!F$2:F$1000,$A40)="","",INDEX(Rates!F$2:F$1000,$A40))) | G40: =IF($A40="","",IF(INDEX(Rates!G$2:G$1000,$A40)="","",INDEX(Rates!G$2:G$1000,$A40))) | H40: =IF($A40="","",IF(INDEX(Rates!H$2:H$1000,$A40)="","",INDEX(Rates!H$2:H$1000,$A40))) -> The rate at the Sept 2026 suspension. Georgia resets it every Jan 1.
A41: =IFERROR(_xlfn.AGGREGATE(15,6,(ROW(Rates!$A$2:$A$1000)-1)/((Rates!$A$2:$A$1000=$C$3)*((Rates!$G$2:$G$1000="")+(Rates!$G$2:$G$1000>=TODAY()))),2),"") -> 2 | B41: =IF($A41="","",IF(INDEX(Rates!B$2:B$1000,$A41)="","",INDEX(Rates!B$2:B$1000,$A41))) -> Diesel | C41: =IF($A41="","",IF(INDEX(Rates!C$2:C$1000,$A41)="","",INDEX(Rates!C$2:C$1000,$A41))) -> State excise | D41: =IF($A41="","",IF(INDEX(Rates!D$2:D$1000,$A41)="","",INDEX(Rates!D$2:D$1000,$A41))) -> 0.373 | E41: =IF($A41="","",IF(INDEX(Rates!E$2:E$1000,$A41)="","",INDEX(Rates!E$2:E$1000,$A41))) -> $ a gallon | F41: =IF($A41="","",IF(INDEX(Rates!F$2:F$1000,$A41)="","",INDEX(Rates!F$2:F$1000,$A41))) | G41: =IF($A41="","",IF(INDEX(Rates!G$2:G$1000,$A41)="","",INDEX(Rates!G$2:G$1000,$A41))) | H41: =IF($A41="","",IF(INDEX(Rates!H$2:H$1000,$A41)="","",INDEX(Rates!H$2:H$1000,$A41))) -> The rate at the Sept 2026 suspension. Georgia resets it every Jan 1.
A42: =IFERROR(_xlfn.AGGREGATE(15,6,(ROW(Rates!$A$2:$A$1000)-1)/((Rates!$A$2:$A$1000=$C$3)*((Rates!$G$2:$G$1000="")+(Rates!$G$2:$G$1000>=TODAY()))),3),"") -> 3 | B42: =IF($A42="","",IF(INDEX(Rates!B$2:B$1000,$A42)="","",INDEX(Rates!B$2:B$1000,$A42))) -> Gasoline and diesel | C42: =IF($A42="","",IF(INDEX(Rates!C$2:C$1000,$A42)="","",INDEX(Rates!C$2:C$1000,$A42))) -> State excise, suspended | D42: =IF($A42="","",IF(INDEX(Rates!D$2:D$1000,$A42)="","",INDEX(Rates!D$2:D$1000,$A42))) -> 0 | E42: =IF($A42="","",IF(INDEX(Rates!E$2:E$1000,$A42)="","",INDEX(Rates!E$2:E$1000,$A42))) -> $ a gallon | F42: =IF($A42="","",IF(INDEX(Rates!F$2:F$1000,$A42)="","",INDEX(Rates!F$2:F$1000,$A42))) -> 46294 | G42: =IF($A42="","",IF(INDEX(Rates!G$2:G$1000,$A42)="","",INDEX(Rates!G$2:G$1000,$A42))) -> 46331 | H42: =IF($A42="","",IF(INDEX(Rates!H$2:H$1000,$A42)="","",INDEX(Rates!H$2:H$1000,$A42))) -> Governor's order EO 09.28.26.01, extended to Nov 5 by EO 10.06.26.01. Gallons still get reported. Prepaid local tax isn't suspended.
A43: =IFERROR(_xlfn.AGGREGATE(15,6,(ROW(Rates!$A$2:$A$1000)-1)/((Rates!$A$2:$A$1000=$C$3)*((Rates!$G$2:$G$1000="")+(Rates!$G$2:$G$1000>=TODAY()))),4),"") -> 4 | B43: =IF($A43="","",IF(INDEX(Rates!B$2:B$1000,$A43)="","",INDEX(Rates!B$2:B$1000,$A43))) -> Gasoline and diesel | C43: =IF($A43="","",IF(INDEX(Rates!C$2:C$1000,$A43)="","",INDEX(Rates!C$2:C$1000,$A43))) -> Prepaid local sales tax | D43: =IF($A43="","",IF(INDEX(Rates!D$2:D$1000,$A43)="","",INDEX(Rates!D$2:D$1000,$A43))) | E43: =IF($A43="","",IF(INDEX(Rates!E$2:E$1000,$A43)="","",INDEX(Rates!E$2:E$1000,$A43))) -> see notes | F43: =IF($A43="","",IF(INDEX(Rates!F$2:F$1000,$A43)="","",INDEX(Rates!F$2:F$1000,$A43))) | G43: =IF($A43="","",IF(INDEX(Rates!G$2:G$1000,$A43)="","",INDEX(Rates!G$2:G$1000,$A43))) | H43: =IF($A43="","",IF(INDEX(Rates!H$2:H$1000,$A43)="","",INDEX(Rates!H$2:H$1000,$A43))) -> The local rate times a state-set price per gallon, reset each Jan 1 and July 1 and never over $3.00. $3.00 for gas and diesel from July 1, 2026.
...

Sheet States
A1: State | B1: Name | C1: Tax agency | D1: Website | E1: Filing site | F1: Main phone | G1: Bond required | H1: Where the files live | I1: Quirks | J1: Source | K1: Last checked
A2: AL | B2: Alabama
A3: AK | B3: Alaska
A4: AZ | B4: Arizona
A5: AR | B5: Arkansas
A6: CA | B6: California
A7: CO | B7: Colorado
A8: CT | B8: Connecticut
A9: DE | B9: Delaware
A10: DC | B10: District of Columbia
A11: FL | B11: Florida
A12: GA | B12: Georgia | C12: Georgia Department of Revenue | D12: https://dor.georgia.gov | E12: https://gtc.dor.ga.gov | F12: (877) 423-6711 | I12: Two sales tax returns, on-road and off-road, both laid out like the ST-3. On-road is gallons by county, two lines per county, and Fulton County splits by rate. State excise suspended Sept 29 to Nov 5, 2026, and state penalties for dyed diesel on the road waived Oct 6 to Nov 5. | J12: https://dor.georgia.gov/find-contact-information-topic | K12: 46305
A13: HI | B13: Hawaii
A14: ID | B14: Idaho
A15: IL | B15: Illinois
A16: IN | B16: Indiana
A17: IA | B17: Iowa
A18: KS | B18: Kansas
A19: KY | B19: Kentucky
A20: LA | B20: Louisiana
A21: ME | B21: Maine
A22: MD | B22: Maryland
A23: MA | B23: Massachusetts
A24: MI | B24: Michigan
... A52: WY | B52: Wyoming

Sheet Returns
A1: State | B1: Return | C1: Form | D1: Tax | E1: How often | F1: How to file | G1: How to pay | H1: Notes | I1: Source | J1: Last checked
A2: GA | B2: Sales and use tax, on-road | C2: ST-3 layout | D2: Sales tax, mostly prepaid local | E2: Monthly | F2: Georgia Tax Center | H2: Gallons by county and product, two lines per county. College Park goes on line 4, every other county on line 6. Fulton County splits by rate. | I2: DOR ST-3 instructions, rev 07/25/22 | J2: 46305
A3: GA | B3: Sales and use tax, off-road | C3: ST-3 layout | D3: Sales and use tax | E3: Monthly | F3: Georgia Tax Center | H3: Dyed fuel. Georgia taxes the small per-gallon fees too, so taxable sales are product cost plus fees. | I3: DOR ST-3 instructions, rev 07/25/22 | J3: 46305
A4: GA | B4: Motor fuel excise, distributor return | D4: State motor fuel excise | E4: Monthly | F4: Georgia Tax Center | H4: Schedules of Receipts and Disbursements. Sept 29 to Nov 5, 2026: report the gallons on both schedules, don't remit the excise. | I4: https://dor.georgia.gov/2026-suspension-georgia-motor-fuel-taxes-faqs | J4: 46305
A5: GA | B5: Refund claim | C5: MFD-33, with MF-12 waivers | D5: Motor fuel excise refunds | E5: As needed | F5: Georgia Tax Center, as refund attachments | H5: One MF-12 per supplier per refund type, signed by the supplier before a notary. Each load's invoice copies go in merged into one PDF. | I5: DOR form MF-12, rev 06/01/17 | J5: 46305

Sheet Licenses
A1: State | B1: License | C1: Number | D1: Expires | E1: Bond amount | F1: Renew how | G1: Notes | H1: Source | I1: Last checked
A2: GA | B2: Motor fuel distributor | G2: Type the number and bond in at work.

Sheet Rates
A1: State | B1: Product | C1: Tax | D1: Rate | E1: Per | F1: From | G1: To | H1: Notes | I1: Source | J1: Last checked
A2: GA | B2: Gasoline | C2: State excise | D2: 0.333 | E2: $ a gallon | H2: The rate at the Sept 2026 suspension. Georgia resets it every Jan 1. | I2: https://dor.georgia.gov/2026-suspension-georgia-motor-fuel-taxes-faqs | J2: 46305
A3: GA | B3: Diesel | C3: State excise | D3: 0.373 | E3: $ a gallon | H3: The rate at the Sept 2026 suspension. Georgia resets it every Jan 1. | I3: https://dor.georgia.gov/2026-suspension-georgia-motor-fuel-taxes-faqs | J3: 46305
A4: GA | B4: Gasoline and diesel | C4: State excise, suspended | D4: 0 | E4: $ a gallon | F4: 46294 | G4: 46331 | H4: Governor's order EO 09.28.26.01, extended to Nov 5 by EO 10.06.26.01. Gallons still get reported. Prepaid local tax isn't suspended. | I4: https://dor.georgia.gov/2026-suspension-georgia-motor-fuel-taxes-faqs | J4: 46305
A5: GA | B5: Gasoline and diesel | C5: Prepaid local sales tax | E5: see notes | H5: The local rate times a state-set price per gallon, reset each Jan 1 and July 1 and never over $3.00. $3.00 for gas and diesel from July 1, 2026. | I5: https://dor.georgia.gov/prepaid-local-tax-motor-fuel-sales-effective-july-1-2026 | J5: 46305
A6: GA | B6: Dyed diesel, road use | C6: State penalties waived | E6: see notes | F6: 46301 | G6: 46331 | H6: EO 10.06.26.01 and Bulletin MFT-2026-04 waive the 48-9-16(e) penalties for dyed fuel on the road. The $100 a month notice penalty in (f) still applies. | I6: https://dor.georgia.gov/mft-2026-04-temporary-waiver-state-dyed-fuel-penalties | J6: 46305

Sheet Contacts
A1: State | B1: Who | C1: Phone | D1: Email | E1: Hours | F1: What for | G1: Source | H1: Last checked
A2: GA | B2: Taxpayer Services, motor fuel | C2: (877) 423-6711 | E2: 8 to 5, weekdays | F2: Motor fuel tax questions | G2: https://dor.georgia.gov/find-contact-information-topic | H2: 46305

Sheet Setups
A1: State | B1: Setup | C1: Product | D1: What it charges | E1: Code in the system | F1: Notes | G1: Last checked

Sheet How to use
B1: How this workbook works
B3: The State tab shows one state at a time. Pick the state in its yellow box and everything about that state shows up, pulled from the other tabs.
B5: Only the yellow box on the State tab takes typing. Type everything else on the tab it belongs to: States, Returns, Licenses, Rates, Contacts or Setups.
B7: Every row starts with the state's two-letter code. The State column only takes codes from the list, so spellings can't drift apart.
B9: A state with more of something just gets more rows. Four Georgia returns are four rows on Returns.
B11: To add a row, type in the first empty row right under a list, and the list grows to take it.
B13: A new kind of info is a new column at the right end of that tab's list. It shows on the State tab once someone adds it there too.
B15: Rates keep their history. When a rate changes, give the old row a To date and add a new row with its From date. The State tab shows only current rates: no To date, or a To date still ahead. Old ones stay on the Rates tab.
B17: Source and Last checked: put the page you checked and the date, so anyone can recheck it in seconds.
B19: The State tab has room for 8 returns, 6 licenses, 8 current rates, 5 contacts and 6 tax setups per state, and says so when a state has more. It shows two lines of each note; the whole note is on its tab.
B21: The State tab is locked so nobody types over it by accident. No password: Review, then Unprotect Sheet, if it ever needs changing.
B23: Company numbers, like license and account numbers and bond amounts, get typed in here at work.
B25: Never put passwords or logins in this workbook.
