Workbook

Sheet READ ME
B2: Missouri use tax | E2: HOW TO USE IT
E3: Yellow cells are the only ones you type in. Everything else adds itself up.
B4: Quarter starts
E5: Once a quarter: type the quarter's first day in C4, like 7/1/2026 for the 3rd quarter.
B6: =IF('READ ME'!$C$4="","Type the quarter's first day in C4, like 7/1/2026.",IF(COUNTIF($D$34:$D$67,"LOOK")=0,"All clear. Months pasted: "&(SIGN(COUNT('AR MONTH 1'!$K$2:$K$1500)+COUNT('TERSE MONTH 1'!$P$2:$P$3000))+SIGN(COUNT('AR MONTH 2'!$K$2:$K$1500)+COUNT('TERSE MONTH 2'!$P$2:$P$3000))+SIGN(COUNT('AR MONTH 3'!$K$2:$K$1500)+COUNT('TERSE MONTH 3'!$P$2:$P$3000)))&" of 3.","RED: "&INDEX($E$34:$E$67,MATCH("LOOK",$D$34:$D$67,0))&IF(COUNTIF($D$34:$D$67,"LOOK")>1," ("&(COUNTIF($D$34:$D$67,"LOOK")-1)&" more in the checks below)",""))) -> Type the quarter's first day in C4, like 7/1/2026.
E7: EVERY MONTH, as the reports come out:
E8: 1. Run the Missouri TERSE sales report for the month. Click in the report, press Ctrl+A once
E9: (not the corner button), copy, and paste at A1 of TERSE MONTH 1, 2 or 3.
E10: 1 is the quarter's first month, so July for Q3.
E11: 2. Run the AR sales taxes by county report for Missouri, same month. Click in it, press Ctrl+A
E12: once, copy, and paste at A1 of AR MONTH 1, 2 or 3.
E13: 3. Look at the light. Green is all clear. RECAP has the month and the quarter for the return.
E15: WHEN THE LIGHT IS RED, it says what is wrong. The usual ones:
E16: - A county and rate not on the list: add it on LISTS in the first empty yellow row.
E17: The AR report's Tax Rate 6.1 goes in as 6.1%.
E18: - Dates outside the month: the wrong month went on that tab, or C4 is wrong.
E19: - Wrong shape: paste again at A1, headers and all, nothing above them.
... E29: Exempt sales: total sales less taxable sales.
B32: The checks behind the light (click the + at the left to open them)
B33: Check | C33: Result | D33: Look? | E33: What to do
B34: Quarter starts on the first of Jan, Apr, Jul or Oct | C34: =IF('READ ME'!$C$4="","OK",IF(AND(DAY('READ ME'!$C$4)=1,MOD(MONTH('READ ME'!$C$4)-1,3)=0),"OK","LOOK")) -> OK | D34: =IF(C34<>"OK","LOOK","") | E34: =IF(D34="LOOK","C4 should be the first day of the quarter, like 7/1/2026.","")
B35: TERSE MONTH 1: headers where they should be, report not too long | C35: =IF(AND(AND(TRIM('TERSE MONTH 1'!$G$1)="Product Type Name",TRIM('TERSE MONTH 1'!$P$1)="Invoice Date",TRIM('TERSE MONTH 1'!$AB$1)="Total Sales Taxes",TRIM('TERSE MONTH 1'!$AD$1)="Total Product"),COUNTA('TERSE MONTH 1'!$A$3001:$A$5000)=0),"OK","LOOK") -> OK | D35: =IF(C35<>"OK","LOOK","") | E35: =IF(D35="LOOK","TERSE MONTH 1: the paste is the wrong shape. Paste the whole report at A1, headers and all (over 3000 rows: copy the last row of the grey helper columns further down).","")
B36: TERSE MONTH 1: grey helper columns still there | C36: =IF(AND('TERSE MONTH 1'!$AU$1="Counted? (helper)"),"OK","LOOK") -> OK | D36: =IF(C36<>"OK","LOOK","") | E36: =IF(D36="LOOK","TERSE MONTH 1: the grey columns at the right are gone, so a whole sheet was pasted. Copy the grey columns over from the same tab of another month, or start from a fresh blank, then paste only the report's cells.","")
B37: TERSE MONTH 1: invoice dates outside the month | C37: =IF('READ ME'!$C$4="",0,COUNTIFS('TERSE MONTH 1'!$P$2:$P$3000,"<"&DATE(YEAR('READ ME'!$C$4),MONTH('READ ME'!$C$4)+0,1))+COUNTIFS('TERSE MONTH 1'!$P$2:$P$3000,">="&DATE(YEAR('READ ME'!$C$4),MONTH('READ ME'!$C$4)+1,1))+COUNTA('TERSE MONTH 1'!$P$2:$P$3000)-COUNT('TERSE MONTH 1'!$P$2:$P$3000)) -> 0 | D37: =IF(C37<>0,"LOOK","") | E37: =IF(D37="LOOK","TERSE MONTH 1: "&C37&" invoice dates fall outside "&TEXT(DATE(YEAR('READ ME'!$C$4),MONTH('READ ME'!$C$4)+0,1),"mmmm yyyy")&". Wrong month pasted, or the quarter in C4 is wrong.","")
B38: AR MONTH 1: headers where they should be, report not too long | C38: =IF(AND(AND(TRIM('AR MONTH 1'!$E$1)="Category",TRIM('AR MONTH 1'!$K$1)="Invoice Date",TRIM('AR MONTH 1'!$S$1)="County",TRIM('AR MONTH 1'!$Y$1)="Taxable Sales",TRIM('AR MONTH 1'!$Z$1)="Tax Rate",TRIM('AR MONTH 1'!$AA$1)="Total Sales Tax"),COUNTA('AR MONTH 1'!$A$1501:$A$3500)=0),"OK","LOOK") -> OK | D38: =IF(C38<>"OK","LOOK","") | E38: =IF(D38="LOOK","AR MONTH 1: the paste is the wrong shape. Paste the whole report at A1, headers and all (over 1500 rows: copy the last row of the grey helper columns further down).","")
B39: AR MONTH 1: grey helper columns still there | C39: =IF(AND('AR MONTH 1'!$AE$1="County (helper)",'AR MONTH 1'!$AF$1="Rate (helper)",'AR MONTH 1'!$AG$1="On the county list? (helper)",'AR MONTH 1'!$AH$1="County and rate (helper)"),"OK","LOOK") -> OK | D39: =IF(C39<>"OK","LOOK","") | E39: =IF(D39="LOOK","AR MONTH 1: the grey columns at the right are gone, so a whole sheet was pasted. Copy the grey columns over from the same tab of another month, or start from a fresh blank, then paste only the report's cells.","")
B40: AR MONTH 1: invoice dates outside the month | C40: =IF('READ ME'!$C$4="",0,COUNTIFS('AR MONTH 1'!$K$2:$K$1500,"<"&DATE(YEAR('READ ME'!$C$4),MONTH('READ ME'!$C$4)+0,1))+COUNTIFS('AR MONTH 1'!$K$2:$K$1500,">="&DATE(YEAR('READ ME'!$C$4),MONTH('READ ME'!$C$4)+1,1))+COUNTA('AR MONTH 1'!$K$2:$K$1500)-COUNT('AR MONTH 1'!$K$2:$K$1500)) -> 0 | D40: =IF(C40<>0,"LOOK","") | E40: =IF(D40="LOOK","AR MONTH 1: "&C40&" invoice dates fall outside "&TEXT(DATE(YEAR('READ ME'!$C$4),MONTH('READ ME'!$C$4)+0,1),"mmmm yyyy")&". Wrong month pasted, or the quarter in C4 is wrong.","")
B41: AR MONTH 1: Tax Paid lines not on the county list | C41: =COUNTIF('AR MONTH 1'!$AG$2:$AG$1500,"NOT ON LIST") -> 0 | D41: =IF(C41<>0,"LOOK","") | E41: =IF(D41="LOOK","AR MONTH 1: "&INDEX('AR MONTH 1'!$AH$2:$AH$1500,MATCH("NOT ON LIST",'AR MONTH 1'!$AG$2:$AG$1500,0))&" is not on the county list"&IF(C41>1," ("&C41&" lines in all)","")&". Add the county and rate on LISTS, or fix the county on the report.","")
B42: Month 1: taxable sales on RECAP less the AR Tax Paid lines | C42: =ROUND(RECAP!F30-SUMIFS('AR MONTH 1'!$Y$2:$Y$1500,'AR MONTH 1'!$E$2:$E$1500,"Tax Paid"),2) -> 0 | D42: =IF(AND(ROUND(C42,2)<>0,COUNTIF('AR MONTH 1'!$AG$2:$AG$1500,"NOT ON LIST")=0),"LOOK","") | E42: =IF(D42="LOOK","Month 1: taxable sales on RECAP are "&IF(C42>0,"over","under")&" the AR Tax Paid lines by "&TEXT(ABS(C42),"#,##0.00")&IF(C42>0,". A county and rate is on LISTS twice.",". Some Tax Paid lines are not being counted; check the grey columns on AR MONTH 1."),"")
B43: Month 1: tax on RECAP less the invoices' tax (rounding, under $1) | C43: =ROUND(RECAP!G30-SUMIFS('AR MONTH 1'!$AA$2:$AA$1500,'AR MONTH 1'!$E$2:$E$1500,"Tax Paid"),2) -> 0 | D43: =IF(AND(ABS(C43)>=1,COUNTIF('AR MONTH 1'!$AG$2:$AG$1500,"NOT ON LIST")=0),"LOOK","") | E43: =IF(D43="LOOK","Month 1: RECAP's tax is off from the invoices' tax by "&TEXT(C43,"#,##0.00")&". Check the rates on LISTS against the AR report's Tax Rate.","")
B44: Month 1: TERSE sales tax less AR sales tax | C44: =ROUND(SUM('TERSE MONTH 1'!$AB$2:$AB$3000)-SUM('AR MONTH 1'!$AA$2:$AA$1500),2) -> 0 | D44: =IF(ROUND(C44,2)<>0,"LOOK","") | E44: =IF(D44="LOOK","Month 1: the TERSE and AR reports' sales tax differ by "&TEXT(C44,"#,##0.00")&". Run both for the same dates.","")
B45: TERSE MONTH 1: product types not on either LISTS column | C45: =COUNTIF('TERSE MONTH 1'!$AU$2:$AU$3000,"NEW") -> 0 | D45: =IF(C45<>0,"LOOK","") | E45: =IF(D45="LOOK","TERSE MONTH 1: product type "&INDEX('TERSE MONTH 1'!$G$2:$G$3000,MATCH("NEW",'TERSE MONTH 1'!$AU$2:$AU$3000,0))&" is new. Add it on LISTS, counted in total sales or left out.","")
B46: TERSE MONTH 2: headers where they should be, report not too long | C46: =IF(AND(AND(TRIM('TERSE MONTH 2'!$G$1)="Product Type Name",TRIM('TERSE MONTH 2'!$P$1)="Invoice Date",TRIM('TERSE MONTH 2'!$AB$1)="Total Sales Taxes",TRIM('TERSE MONTH 2'!$AD$1)="Total Product"),COUNTA('TERSE MONTH 2'!$A$3001:$A$5000)=0),"OK","LOOK") -> OK | D46: =IF(C46<>"OK","LOOK","") | E46: =IF(D46="LOOK","TERSE MONTH 2: the paste is the wrong shape. Paste the whole report at A1, headers and all (over 3000 rows: copy the last row of the grey helper columns further down).","")
B47: TERSE MONTH 2: grey helper columns still there | C47: =IF(AND('TERSE MONTH 2'!$AU$1="Counted? (helper)"),"OK","LOOK") -> OK | D47: =IF(C47<>"OK","LOOK","") | E47: =IF(D47="LOOK","TERSE MONTH 2: the grey columns at the right are gone, so a whole sheet was pasted. Copy the grey columns over from the same tab of another month, or start from a fresh blank, then paste only the report's cells.","")
B48: TERSE MONTH 2: invoice dates outside the month | C48: =IF('READ ME'!$C$4="",0,COUNTIFS('TERSE MONTH 2'!$P$2:$P$3000,"<"&DATE(YEAR('READ ME'!$C$4),MONTH('READ ME'!$C$4)+1,1))+COUNTIFS('TERSE MONTH 2'!$P$2:$P$3000,">="&DATE(YEAR('READ ME'!$C$4),MONTH('READ ME'!$C$4)+2,1))+COUNTA('TERSE MONTH 2'!$P$2:$P$3000)-COUNT('TERSE MONTH 2'!$P$2:$P$3000)) -> 0 | D48: =IF(C48<>0,"LOOK","") | E48: =IF(D48="LOOK","TERSE MONTH 2: "&C48&" invoice dates fall outside "&TEXT(DATE(YEAR('READ ME'!$C$4),MONTH('READ ME'!$C$4)+1,1),"mmmm yyyy")&". Wrong month pasted, or the quarter in C4 is wrong.","")
B49: AR MONTH 2: headers where they should be, report not too long | C49: =IF(AND(AND(TRIM('AR MONTH 2'!$E$1)="Category",TRIM('AR MONTH 2'!$K$1)="Invoice Date",TRIM('AR MONTH 2'!$S$1)="County",TRIM('AR MONTH 2'!$Y$1)="Taxable Sales",TRIM('AR MONTH 2'!$Z$1)="Tax Rate",TRIM('AR MONTH 2'!$AA$1)="Total Sales Tax"),COUNTA('AR MONTH 2'!$A$1501:$A$3500)=0),"OK","LOOK") -> OK | D49: =IF(C49<>"OK","LOOK","") | E49: =IF(D49="LOOK","AR MONTH 2: the paste is the wrong shape. Paste the whole report at A1, headers and all (over 1500 rows: copy the last row of the grey helper columns further down).","")
B50: AR MONTH 2: grey helper columns still there | C50: =IF(AND('AR MONTH 2'!$AE$1="County (helper)",'AR MONTH 2'!$AF$1="Rate (helper)",'AR MONTH 2'!$AG$1="On the county list? (helper)",'AR MONTH 2'!$AH$1="County and rate (helper)"),"OK","LOOK") -> OK | D50: =IF(C50<>"OK","LOOK","") | E50: =IF(D50="LOOK","AR MONTH 2: the grey columns at the right are gone, so a whole sheet was pasted. Copy the grey columns over from the same tab of another month, or start from a fresh blank, then paste only the report's cells.","")
B51: AR MONTH 2: invoice dates outside the month | C51: =IF('READ ME'!$C$4="",0,COUNTIFS('AR MONTH 2'!$K$2:$K$1500,"<"&DATE(YEAR('READ ME'!$C$4),MONTH('READ ME'!$C$4)+1,1))+COUNTIFS('AR MONTH 2'!$K$2:$K$1500,">="&DATE(YEAR('READ ME'!$C$4),MONTH('READ ME'!$C$4)+2,1))+COUNTA('AR MONTH 2'!$K$2:$K$1500)-COUNT('AR MONTH 2'!$K$2:$K$1500)) -> 0 | D51: =IF(C51<>0,"LOOK","") | E51: =IF(D51="LOOK","AR MONTH 2: "&C51&" invoice dates fall outside "&TEXT(DATE(YEAR('READ ME'!$C$4),MONTH('READ ME'!$C$4)+1,1),"mmmm yyyy")&". Wrong month pasted, or the quarter in C4 is wrong.","")
B52: AR MONTH 2: Tax Paid lines not on the county list | C52: =COUNTIF('AR MONTH 2'!$AG$2:$AG$1500,"NOT ON LIST") -> 0 | D52: =IF(C52<>0,"LOOK","") | E52: =IF(D52="LOOK","AR MONTH 2: "&INDEX('AR MONTH 2'!$AH$2:$AH$1500,MATCH("NOT ON LIST",'AR MONTH 2'!$AG$2:$AG$1500,0))&" is not on the county list"&IF(C52>1," ("&C52&" lines in all)","")&". Add the county and rate on LISTS, or fix the county on the report.","")
B53: Month 2: taxable sales on RECAP less the AR Tax Paid lines | C53: =ROUND(RECAP!F58-SUMIFS('AR MONTH 2'!$Y$2:$Y$1500,'AR MONTH 2'!$E$2:$E$1500,"Tax Paid"),2) -> 0 | D53: =IF(AND(ROUND(C53,2)<>0,COUNTIF('AR MONTH 2'!$AG$2:$AG$1500,"NOT ON LIST")=0),"LOOK","") | E53: =IF(D53="LOOK","Month 2: taxable sales on RECAP are "&IF(C53>0,"over","under")&" the AR Tax Paid lines by "&TEXT(ABS(C53),"#,##0.00")&IF(C53>0,". A county and rate is on LISTS twice.",". Some Tax Paid lines are not being counted; check the grey columns on AR MONTH 2."),"")
...

Sheet RECAP
A1: ="Missouri use tax "&IF('READ ME'!$C$4="","",CHOOSE(ROUNDUP(MONTH('READ ME'!$C$4)/3,0),"1st","2nd","3rd","4th")&" QTR "&YEAR('READ ME'!$C$4)) -> Missouri use tax
A2: Nothing here is typed. Paste the reports on their tabs; the county list is on LISTS.
B4: total sales | D4: exempt sales | F4: taxable sales | G4: sales due | H4: County | I4: rate | K4: jurisdiction code
A5: =IF('READ ME'!$C$4="","Month 1",DATE(YEAR('READ ME'!$C$4),MONTH('READ ME'!$C$4)+0,1)) -> Month 1 | B5: =SUMIFS('TERSE MONTH 1'!$AD$2:$AD$3000,'TERSE MONTH 1'!$AU$2:$AU$3000,"COUNTED") -> 0 | D5: =B5-F30 -> 0 | F5: =IF(LISTS!$D$2="","",SUMIFS('AR MONTH 1'!$Y$2:$Y$1500,'AR MONTH 1'!$AE$2:$AE$1500,LISTS!$F$2,'AR MONTH 1'!$AF$2:$AF$1500,LISTS!$G$2)) -> 0 | G5: =IF(F5="","",ROUND(F5*I5,2)) -> 0 | H5: =LISTS!$D$2 -> Cedar (4.225%) | I5: =IF(LISTS!$D$2="","",LISTS!$B$2) -> 0.04225 | K5: =IF(LISTS!$C$2="","",LISTS!$C$2)
F6: =IF(LISTS!$D$3="","",SUMIFS('AR MONTH 1'!$Y$2:$Y$1500,'AR MONTH 1'!$AE$2:$AE$1500,LISTS!$F$3,'AR MONTH 1'!$AF$2:$AF$1500,LISTS!$G$3)) -> 0 | G6: =IF(F6="","",ROUND(F6*I6,2)) -> 0 | H6: =LISTS!$D$3 -> Wright (4.225%) | I6: =IF(LISTS!$D$3="","",LISTS!$B$3) -> 0.04225 | K6: =IF(LISTS!$C$3="","",LISTS!$C$3)
F7: =IF(LISTS!$D$4="","",SUMIFS('AR MONTH 1'!$Y$2:$Y$1500,'AR MONTH 1'!$AE$2:$AE$1500,LISTS!$F$4,'AR MONTH 1'!$AF$2:$AF$1500,LISTS!$G$4)) -> 0 | G7: =IF(F7="","",ROUND(F7*I7,2)) -> 0 | H7: =LISTS!$D$4 -> Hickory (4.225%) | I7: =IF(LISTS!$D$4="","",LISTS!$B$4) -> 0.04225 | K7: =IF(LISTS!$C$4="","",LISTS!$C$4)
F8: =IF(LISTS!$D$5="","",SUMIFS('AR MONTH 1'!$Y$2:$Y$1500,'AR MONTH 1'!$AE$2:$AE$1500,LISTS!$F$5,'AR MONTH 1'!$AF$2:$AF$1500,LISTS!$G$5)) -> 0 | G8: =IF(F8="","",ROUND(F8*I8,2)) -> 0 | H8: =LISTS!$D$5 -> Christian (4.225%) | I8: =IF(LISTS!$D$5="","",LISTS!$B$5) -> 0.04225 | K8: =IF(LISTS!$C$5="","",LISTS!$C$5)
F9: =IF(LISTS!$D$6="","",SUMIFS('AR MONTH 1'!$Y$2:$Y$1500,'AR MONTH 1'!$AE$2:$AE$1500,LISTS!$F$6,'AR MONTH 1'!$AF$2:$AF$1500,LISTS!$G$6)) -> 0 | G9: =IF(F9="","",ROUND(F9*I9,2)) -> 0 | H9: =LISTS!$D$6 -> Nodaway (6.1%) | I9: =IF(LISTS!$D$6="","",LISTS!$B$6) -> 0.061 | K9: =IF(LISTS!$C$6="","",LISTS!$C$6) -> 00000-147-000
F10: =IF(LISTS!$D$7="","",SUMIFS('AR MONTH 1'!$Y$2:$Y$1500,'AR MONTH 1'!$AE$2:$AE$1500,LISTS!$F$7,'AR MONTH 1'!$AF$2:$AF$1500,LISTS!$G$7)) -> 0 | G10: =IF(F10="","",ROUND(F10*I10,2)) -> 0 | H10: =LISTS!$D$7 -> Bates (5.225%) | I10: =IF(LISTS!$D$7="","",LISTS!$B$7) -> 0.05225 | K10: =IF(LISTS!$C$7="","",LISTS!$C$7)
F11: =IF(LISTS!$D$8="","",SUMIFS('AR MONTH 1'!$Y$2:$Y$1500,'AR MONTH 1'!$AE$2:$AE$1500,LISTS!$F$8,'AR MONTH 1'!$AF$2:$AF$1500,LISTS!$G$8)) -> 0 | G11: =IF(F11="","",ROUND(F11*I11,2)) -> 0 | H11: =LISTS!$D$8 -> Jasper (5.6%) | I11: =IF(LISTS!$D$8="","",LISTS!$B$8) -> 0.056 | K11: =IF(LISTS!$C$8="","",LISTS!$C$8)
F12: =IF(LISTS!$D$9="","",SUMIFS('AR MONTH 1'!$Y$2:$Y$1500,'AR MONTH 1'!$AE$2:$AE$1500,LISTS!$F$9,'AR MONTH 1'!$AF$2:$AF$1500,LISTS!$G$9)) -> 0 | G12: =IF(F12="","",ROUND(F12*I12,2)) -> 0 | H12: =LISTS!$D$9 -> Clay (8.725%) | I12: =IF(LISTS!$D$9="","",LISTS!$B$9) -> 0.08725 | K12: =IF(LISTS!$C$9="","",LISTS!$C$9)
F13: =IF(LISTS!$D$10="","",SUMIFS('AR MONTH 1'!$Y$2:$Y$1500,'AR MONTH 1'!$AE$2:$AE$1500,LISTS!$F$10,'AR MONTH 1'!$AF$2:$AF$1500,LISTS!$G$10)) -> 0 | G13: =IF(F13="","",ROUND(F13*I13,2)) -> 0 | H13: =LISTS!$D$10 -> Clay (8.6%) | I13: =IF(LISTS!$D$10="","",LISTS!$B$10) -> 0.086 | K13: =IF(LISTS!$C$10="","",LISTS!$C$10)
F14: =IF(LISTS!$D$11="","",SUMIFS('AR MONTH 1'!$Y$2:$Y$1500,'AR MONTH 1'!$AE$2:$AE$1500,LISTS!$F$11,'AR MONTH 1'!$AF$2:$AF$1500,LISTS!$G$11)) -> 0 | G14: =IF(F14="","",ROUND(F14*I14,2)) -> 0 | H14: =LISTS!$D$11 -> Clay (9.725%) | I14: =IF(LISTS!$D$11="","",LISTS!$B$11) -> 0.09725 | K14: =IF(LISTS!$C$11="","",LISTS!$C$11)
F15: =IF(LISTS!$D$12="","",SUMIFS('AR MONTH 1'!$Y$2:$Y$1500,'AR MONTH 1'!$AE$2:$AE$1500,LISTS!$F$12,'AR MONTH 1'!$AF$2:$AF$1500,LISTS!$G$12)) -> 0 | G15: =IF(F15="","",ROUND(F15*I15,2)) -> 0 | H15: =LISTS!$D$12 -> Stoddard (6.225%) | I15: =IF(LISTS!$D$12="","",LISTS!$B$12) -> 0.06225 | K15: =IF(LISTS!$C$12="","",LISTS!$C$12) -> 00000-207-000
F16: =IF(LISTS!$D$13="","",SUMIFS('AR MONTH 1'!$Y$2:$Y$1500,'AR MONTH 1'!$AE$2:$AE$1500,LISTS!$F$13,'AR MONTH 1'!$AF$2:$AF$1500,LISTS!$G$13)) -> 0 | G16: =IF(F16="","",ROUND(F16*I16,2)) -> 0 | H16: =LISTS!$D$13 -> Warren (6.225%) | I16: =IF(LISTS!$D$13="","",LISTS!$B$13) -> 0.06225 | K16: =IF(LISTS!$C$13="","",LISTS!$C$13)
F17: =IF(LISTS!$D$14="","",SUMIFS('AR MONTH 1'!$Y$2:$Y$1500,'AR MONTH 1'!$AE$2:$AE$1500,LISTS!$F$14,'AR MONTH 1'!$AF$2:$AF$1500,LISTS!$G$14)) -> 0 | G17: =IF(F17="","",ROUND(F17*I17,2)) -> 0 | H17: =LISTS!$D$14 -> Greene (6.35%) | I17: =IF(LISTS!$D$14="","",LISTS!$B$14) -> 0.0635 | K17: =IF(LISTS!$C$14="","",LISTS!$C$14)
F18: =IF(LISTS!$D$15="","",SUMIFS('AR MONTH 1'!$Y$2:$Y$1500,'AR MONTH 1'!$AE$2:$AE$1500,LISTS!$F$15,'AR MONTH 1'!$AF$2:$AF$1500,LISTS!$G$15)) -> 0 | G18: =IF(F18="","",ROUND(F18*I18,2)) -> 0 | H18: =LISTS!$D$15 -> Henry (7.925%) | I18: =IF(LISTS!$D$15="","",LISTS!$B$15) -> 0.07925 | K18: =IF(LISTS!$C$15="","",LISTS!$C$15)
F19: =IF(LISTS!$D$16="","",SUMIFS('AR MONTH 1'!$Y$2:$Y$1500,'AR MONTH 1'!$AE$2:$AE$1500,LISTS!$F$16,'AR MONTH 1'!$AF$2:$AF$1500,LISTS!$G$16)) -> 0 | G19: =IF(F19="","",ROUND(F19*I19,2)) -> 0 | H19: =LISTS!$D$16 -> St. Charles (7.95%) | I19: =IF(LISTS!$D$16="","",LISTS!$B$16) -> 0.0795 | K19: =IF(LISTS!$C$16="","",LISTS!$C$16)
F20: =IF(LISTS!$D$17="","",SUMIFS('AR MONTH 1'!$Y$2:$Y$1500,'AR MONTH 1'!$AE$2:$AE$1500,LISTS!$F$17,'AR MONTH 1'!$AF$2:$AF$1500,LISTS!$G$17)) -> 0 | G20: =IF(F20="","",ROUND(F20*I20,2)) -> 0 | H20: =LISTS!$D$17 -> Boone (7.975%) | I20: =IF(LISTS!$D$17="","",LISTS!$B$17) -> 0.07975 | K20: =IF(LISTS!$C$17="","",LISTS!$C$17)
F21: =IF(LISTS!$D$18="","",SUMIFS('AR MONTH 1'!$Y$2:$Y$1500,'AR MONTH 1'!$AE$2:$AE$1500,LISTS!$F$18,'AR MONTH 1'!$AF$2:$AF$1500,LISTS!$G$18)) -> 0 | G21: =IF(F21="","",ROUND(F21*I21,2)) -> 0 | H21: =LISTS!$D$18 -> Wright (6.1%) | I21: =IF(LISTS!$D$18="","",LISTS!$B$18) -> 0.061 | K21: =IF(LISTS!$C$18="","",LISTS!$C$18)
F22: =IF(LISTS!$D$19="","",SUMIFS('AR MONTH 1'!$Y$2:$Y$1500,'AR MONTH 1'!$AE$2:$AE$1500,LISTS!$F$19,'AR MONTH 1'!$AF$2:$AF$1500,LISTS!$G$19)) -> 0 | G22: =IF(F22="","",ROUND(F22*I22,2)) -> 0 | H22: =LISTS!$D$19 -> Franklin (6.475%) | I22: =IF(LISTS!$D$19="","",LISTS!$B$19) -> 0.06475 | K22: =IF(LISTS!$C$19="","",LISTS!$C$19)
F23: =IF(LISTS!$D$20="","",SUMIFS('AR MONTH 1'!$Y$2:$Y$1500,'AR MONTH 1'!$AE$2:$AE$1500,LISTS!$F$20,'AR MONTH 1'!$AF$2:$AF$1500,LISTS!$G$20)) -> 0 | G23: =IF(F23="","",ROUND(F23*I23,2)) -> 0 | H23: =LISTS!$D$20 -> Cape Girardeau (8.475%) | I23: =IF(LISTS!$D$20="","",LISTS!$B$20) -> 0.08475 | K23: =IF(LISTS!$C$20="","",LISTS!$C$20)
F24: =IF(LISTS!$D$21="","",SUMIFS('AR MONTH 1'!$Y$2:$Y$1500,'AR MONTH 1'!$AE$2:$AE$1500,LISTS!$F$21,'AR MONTH 1'!$AF$2:$AF$1500,LISTS!$G$21)) | G24: =IF(F24="","",ROUND(F24*I24,2)) | H24: =LISTS!$D$21 | I24: =IF(LISTS!$D$21="","",LISTS!$B$21) | K24: =IF(LISTS!$C$21="","",LISTS!$C$21)
F25: =IF(LISTS!$D$22="","",SUMIFS('AR MONTH 1'!$Y$2:$Y$1500,'AR MONTH 1'!$AE$2:$AE$1500,LISTS!$F$22,'AR MONTH 1'!$AF$2:$AF$1500,LISTS!$G$22)) | G25: =IF(F25="","",ROUND(F25*I25,2)) | H25: =LISTS!$D$22 | I25: =IF(LISTS!$D$22="","",LISTS!$B$22) | K25: =IF(LISTS!$C$22="","",LISTS!$C$22)
F26: =IF(LISTS!$D$23="","",SUMIFS('AR MONTH 1'!$Y$2:$Y$1500,'AR MONTH 1'!$AE$2:$AE$1500,LISTS!$F$23,'AR MONTH 1'!$AF$2:$AF$1500,LISTS!$G$23)) | G26: =IF(F26="","",ROUND(F26*I26,2)) | H26: =LISTS!$D$23 | I26: =IF(LISTS!$D$23="","",LISTS!$B$23) | K26: =IF(LISTS!$C$23="","",LISTS!$C$23)
F27: =IF(LISTS!$D$24="","",SUMIFS('AR MONTH 1'!$Y$2:$Y$1500,'AR MONTH 1'!$AE$2:$AE$1500,LISTS!$F$24,'AR MONTH 1'!$AF$2:$AF$1500,LISTS!$G$24)) | G27: =IF(F27="","",ROUND(F27*I27,2)) | H27: =LISTS!$D$24 | I27: =IF(LISTS!$D$24="","",LISTS!$B$24) | K27: =IF(LISTS!$C$24="","",LISTS!$C$24)
F28: =IF(LISTS!$D$25="","",SUMIFS('AR MONTH 1'!$Y$2:$Y$1500,'AR MONTH 1'!$AE$2:$AE$1500,LISTS!$F$25,'AR MONTH 1'!$AF$2:$AF$1500,LISTS!$G$25)) | G28: =IF(F28="","",ROUND(F28*I28,2)) | H28: =LISTS!$D$25 | I28: =IF(LISTS!$D$25="","",LISTS!$B$25) | K28: =IF(LISTS!$C$25="","",LISTS!$C$25)
F29: =IF(LISTS!$D$26="","",SUMIFS('AR MONTH 1'!$Y$2:$Y$1500,'AR MONTH 1'!$AE$2:$AE$1500,LISTS!$F$26,'AR MONTH 1'!$AF$2:$AF$1500,LISTS!$G$26)) | G29: =IF(F29="","",ROUND(F29*I29,2)) | H29: =LISTS!$D$26 | I29: =IF(LISTS!$D$26="","",LISTS!$B$26) | K29: =IF(LISTS!$C$26="","",LISTS!$C$26)
F30: =SUM(F5:F29) -> 0 | G30: =SUM(G5:G29) -> 0
A33: =IF('READ ME'!$C$4="","Month 2",DATE(YEAR('READ ME'!$C$4),MONTH('READ ME'!$C$4)+1,1)) -> Month 2 | B33: =SUMIFS('TERSE MONTH 2'!$AD$2:$AD$3000,'TERSE MONTH 2'!$AU$2:$AU$3000,"COUNTED") -> 0 | D33: =B33-F58 -> 0 | F33: =IF(LISTS!$D$2="","",SUMIFS('AR MONTH 2'!$Y$2:$Y$1500,'AR MONTH 2'!$AE$2:$AE$1500,LISTS!$F$2,'AR MONTH 2'!$AF$2:$AF$1500,LISTS!$G$2)) -> 0 | G33: =IF(F33="","",ROUND(F33*I33,2)) -> 0 | H33: =LISTS!$D$2 -> Cedar (4.225%) | I33: =IF(LISTS!$D$2="","",LISTS!$B$2) -> 0.04225 | K33: =IF(LISTS!$C$2="","",LISTS!$C$2)
F34: =IF(LISTS!$D$3="","",SUMIFS('AR MONTH 2'!$Y$2:$Y$1500,'AR MONTH 2'!$AE$2:$AE$1500,LISTS!$F$3,'AR MONTH 2'!$AF$2:$AF$1500,LISTS!$G$3)) -> 0 | G34: =IF(F34="","",ROUND(F34*I34,2)) -> 0 | H34: =LISTS!$D$3 -> Wright (4.225%) | I34: =IF(LISTS!$D$3="","",LISTS!$B$3) -> 0.04225 | K34: =IF(LISTS!$C$3="","",LISTS!$C$3)
F35: =IF(LISTS!$D$4="","",SUMIFS('AR MONTH 2'!$Y$2:$Y$1500,'AR MONTH 2'!$AE$2:$AE$1500,LISTS!$F$4,'AR MONTH 2'!$AF$2:$AF$1500,LISTS!$G$4)) -> 0 | G35: =IF(F35="","",ROUND(F35*I35,2)) -> 0 | H35: =LISTS!$D$4 -> Hickory (4.225%) | I35: =IF(LISTS!$D$4="","",LISTS!$B$4) -> 0.04225 | K35: =IF(LISTS!$C$4="","",LISTS!$C$4)
F36: =IF(LISTS!$D$5="","",SUMIFS('AR MONTH 2'!$Y$2:$Y$1500,'AR MONTH 2'!$AE$2:$AE$1500,LISTS!$F$5,'AR MONTH 2'!$AF$2:$AF$1500,LISTS!$G$5)) -> 0 | G36: =IF(F36="","",ROUND(F36*I36,2)) -> 0 | H36: =LISTS!$D$5 -> Christian (4.225%) | I36: =IF(LISTS!$D$5="","",LISTS!$B$5) -> 0.04225 | K36: =IF(LISTS!$C$5="","",LISTS!$C$5)
F37: =IF(LISTS!$D$6="","",SUMIFS('AR MONTH 2'!$Y$2:$Y$1500,'AR MONTH 2'!$AE$2:$AE$1500,LISTS!$F$6,'AR MONTH 2'!$AF$2:$AF$1500,LISTS!$G$6)) -> 0 | G37: =IF(F37="","",ROUND(F37*I37,2)) -> 0 | H37: =LISTS!$D$6 -> Nodaway (6.1%) | I37: =IF(LISTS!$D$6="","",LISTS!$B$6) -> 0.061 | K37: =IF(LISTS!$C$6="","",LISTS!$C$6) -> 00000-147-000
F38: =IF(LISTS!$D$7="","",SUMIFS('AR MONTH 2'!$Y$2:$Y$1500,'AR MONTH 2'!$AE$2:$AE$1500,LISTS!$F$7,'AR MONTH 2'!$AF$2:$AF$1500,LISTS!$G$7)) -> 0 | G38: =IF(F38="","",ROUND(F38*I38,2)) -> 0 | H38: =LISTS!$D$7 -> Bates (5.225%) | I38: =IF(LISTS!$D$7="","",LISTS!$B$7) -> 0.05225 | K38: =IF(LISTS!$C$7="","",LISTS!$C$7)
F39: =IF(LISTS!$D$8="","",SUMIFS('AR MONTH 2'!$Y$2:$Y$1500,'AR MONTH 2'!$AE$2:$AE$1500,LISTS!$F$8,'AR MONTH 2'!$AF$2:$AF$1500,LISTS!$G$8)) -> 0 | G39: =IF(F39="","",ROUND(F39*I39,2)) -> 0 | H39: =LISTS!$D$8 -> Jasper (5.6%) | I39: =IF(LISTS!$D$8="","",LISTS!$B$8) -> 0.056 | K39: =IF(LISTS!$C$8="","",LISTS!$C$8)
F40: =IF(LISTS!$D$9="","",SUMIFS('AR MONTH 2'!$Y$2:$Y$1500,'AR MONTH 2'!$AE$2:$AE$1500,LISTS!$F$9,'AR MONTH 2'!$AF$2:$AF$1500,LISTS!$G$9)) -> 0 | G40: =IF(F40="","",ROUND(F40*I40,2)) -> 0 | H40: =LISTS!$D$9 -> Clay (8.725%) | I40: =IF(LISTS!$D$9="","",LISTS!$B$9) -> 0.08725 | K40: =IF(LISTS!$C$9="","",LISTS!$C$9)
F41: =IF(LISTS!$D$10="","",SUMIFS('AR MONTH 2'!$Y$2:$Y$1500,'AR MONTH 2'!$AE$2:$AE$1500,LISTS!$F$10,'AR MONTH 2'!$AF$2:$AF$1500,LISTS!$G$10)) -> 0 | G41: =IF(F41="","",ROUND(F41*I41,2)) -> 0 | H41: =LISTS!$D$10 -> Clay (8.6%) | I41: =IF(LISTS!$D$10="","",LISTS!$B$10) -> 0.086 | K41: =IF(LISTS!$C$10="","",LISTS!$C$10)
F42: =IF(LISTS!$D$11="","",SUMIFS('AR MONTH 2'!$Y$2:$Y$1500,'AR MONTH 2'!$AE$2:$AE$1500,LISTS!$F$11,'AR MONTH 2'!$AF$2:$AF$1500,LISTS!$G$11)) -> 0 | G42: =IF(F42="","",ROUND(F42*I42,2)) -> 0 | H42: =LISTS!$D$11 -> Clay (9.725%) | I42: =IF(LISTS!$D$11="","",LISTS!$B$11) -> 0.09725 | K42: =IF(LISTS!$C$11="","",LISTS!$C$11)
F43: =IF(LISTS!$D$12="","",SUMIFS('AR MONTH 2'!$Y$2:$Y$1500,'AR MONTH 2'!$AE$2:$AE$1500,LISTS!$F$12,'AR MONTH 2'!$AF$2:$AF$1500,LISTS!$G$12)) -> 0 | G43: =IF(F43="","",ROUND(F43*I43,2)) -> 0 | H43: =LISTS!$D$12 -> Stoddard (6.225%) | I43: =IF(LISTS!$D$12="","",LISTS!$B$12) -> 0.06225 | K43: =IF(LISTS!$C$12="","",LISTS!$C$12) -> 00000-207-000
...

Sheet TERSE MONTH 1
A1: Ship To State | B1: Ship To State Name | C1: Ship To City | D1: lng City ID | E1: Ship To County | F1: Product Type | G1: Product Type Name | H1: Customer Name | I1: Account Number | J1: Ship To Number | K1: Account Ship To | L1: Order Number | M1: Carrier | N1: Marketing Consultant | O1: Product | P1: Invoice Date | Q1: Ordered Qty | R1: Sold Qty | S1: Metered Qty | T1: Gross Profit | U1: Sold As | V1: Unit Price | W1: Qty Price | X1: Total Taxes Now | Y1: Total Taxes Deferred | Z1: Total Taxes | AA1: Total Excise Taxes | AB1: Total Sales Taxes | AC1: Line Total | AD1: Total Product | AE1: Total Product Excise | AF1: Ship To Name | AG1: Address 1 | AH1: Destination State | AI1: Bid ID | AJ1: Firm Contract | AK1: Firm Contract Adjustment | AL1: NYMEX Weekly Adjustment | AM1: Sold Qty No Svc | AN1: Gross Profit No Svc | AO1: Total Product No Svc | AP1: Total Product Excise No Svc | AQ1: Line Total No Svc | AR1: cnt Order Item ID | AS1: cnt Order ID | AU1: Counted? (helper)
AU2: =IF(TRIM($G2)="","",IF(COUNTIF(LISTS!$I$2:$I$16,TRIM($G2))>0,"COUNTED",IF(COUNTIF(LISTS!$J$2:$J$16,TRIM($G2))>0,"LEFT OUT","NEW")))
AU3: =IF(TRIM($G3)="","",IF(COUNTIF(LISTS!$I$2:$I$16,TRIM($G3))>0,"COUNTED",IF(COUNTIF(LISTS!$J$2:$J$16,TRIM($G3))>0,"LEFT OUT","NEW")))
AU4: =IF(TRIM($G4)="","",IF(COUNTIF(LISTS!$I$2:$I$16,TRIM($G4))>0,"COUNTED",IF(COUNTIF(LISTS!$J$2:$J$16,TRIM($G4))>0,"LEFT OUT","NEW")))
AU5: =IF(TRIM($G5)="","",IF(COUNTIF(LISTS!$I$2:$I$16,TRIM($G5))>0,"COUNTED",IF(COUNTIF(LISTS!$J$2:$J$16,TRIM($G5))>0,"LEFT OUT","NEW")))
AU6: =IF(TRIM($G6)="","",IF(COUNTIF(LISTS!$I$2:$I$16,TRIM($G6))>0,"COUNTED",IF(COUNTIF(LISTS!$J$2:$J$16,TRIM($G6))>0,"LEFT OUT","NEW")))
AU7: =IF(TRIM($G7)="","",IF(COUNTIF(LISTS!$I$2:$I$16,TRIM($G7))>0,"COUNTED",IF(COUNTIF(LISTS!$J$2:$J$16,TRIM($G7))>0,"LEFT OUT","NEW")))
AU8: =IF(TRIM($G8)="","",IF(COUNTIF(LISTS!$I$2:$I$16,TRIM($G8))>0,"COUNTED",IF(COUNTIF(LISTS!$J$2:$J$16,TRIM($G8))>0,"LEFT OUT","NEW")))
AU9: =IF(TRIM($G9)="","",IF(COUNTIF(LISTS!$I$2:$I$16,TRIM($G9))>0,"COUNTED",IF(COUNTIF(LISTS!$J$2:$J$16,TRIM($G9))>0,"LEFT OUT","NEW")))
AU10: =IF(TRIM($G10)="","",IF(COUNTIF(LISTS!$I$2:$I$16,TRIM($G10))>0,"COUNTED",IF(COUNTIF(LISTS!$J$2:$J$16,TRIM($G10))>0,"LEFT OUT","NEW")))
AU11: =IF(TRIM($G11)="","",IF(COUNTIF(LISTS!$I$2:$I$16,TRIM($G11))>0,"COUNTED",IF(COUNTIF(LISTS!$J$2:$J$16,TRIM($G11))>0,"LEFT OUT","NEW")))
AU12: =IF(TRIM($G12)="","",IF(COUNTIF(LISTS!$I$2:$I$16,TRIM($G12))>0,"COUNTED",IF(COUNTIF(LISTS!$J$2:$J$16,TRIM($G12))>0,"LEFT OUT","NEW")))
AU13: =IF(TRIM($G13)="","",IF(COUNTIF(LISTS!$I$2:$I$16,TRIM($G13))>0,"COUNTED",IF(COUNTIF(LISTS!$J$2:$J$16,TRIM($G13))>0,"LEFT OUT","NEW")))
... AU3000: =IF(TRIM($G3000)="","",IF(COUNTIF(LISTS!$I$2:$I$16,TRIM($G3000))>0,"COUNTED",IF(COUNTIF(LISTS!$J$2:$J$16,TRIM($G3000))>0,"LEFT OUT","NEW")))

Sheet AR MONTH 1
A1: Tax State | B1: Tax State Name | C1: Destination State | D1: Destination State Name | E1: Category | F1: Import Export | G1: Category Import Export | H1: Tax Name | I1: Tax Class | J1: Tax Exemption | K1: Invoice Date | L1: Order Number | M1: Customer Name | N1: Ship To Name | O1: Address 1 | P1: Ship To City | Q1: Ship To State | R1: Ship To City State | S1: County | T1: Account Number | U1: Ship To Number | V1: Account Ship To | W1: Invoice Total | X1: Non Taxable Sales | Y1: Taxable Sales | Z1: Tax Rate | AA1: Total Sales Tax | AB1: lng Tax Class ID | AC1: cnt Tax ID | AE1: County (helper) | AF1: Rate (helper) | AG1: On the county list? (helper) | AH1: County and rate (helper)
AE2: =IF(TRIM($E2)="Tax Paid",TRIM($S2),"") | AF2: =IF(TRIM($E2)="Tax Paid",ROUND($Z2/100,5),"") | AG2: =IF(TRIM($E2)<>"Tax Paid","",IF(COUNTIFS(LISTS!$F$2:$F$26,$AE2,LISTS!$G$2:$G$26,$AF2)=0,"NOT ON LIST","")) | AH2: =IF($AG2="","",IF($AE2="","(no county)",$AE2)&" ("&SUBSTITUTE(TEXT($AF2,"0.###%"),".%","%")&")")
AE3: =IF(TRIM($E3)="Tax Paid",TRIM($S3),"") | AF3: =IF(TRIM($E3)="Tax Paid",ROUND($Z3/100,5),"") | AG3: =IF(TRIM($E3)<>"Tax Paid","",IF(COUNTIFS(LISTS!$F$2:$F$26,$AE3,LISTS!$G$2:$G$26,$AF3)=0,"NOT ON LIST","")) | AH3: =IF($AG3="","",IF($AE3="","(no county)",$AE3)&" ("&SUBSTITUTE(TEXT($AF3,"0.###%"),".%","%")&")")
AE4: =IF(TRIM($E4)="Tax Paid",TRIM($S4),"") | AF4: =IF(TRIM($E4)="Tax Paid",ROUND($Z4/100,5),"") | AG4: =IF(TRIM($E4)<>"Tax Paid","",IF(COUNTIFS(LISTS!$F$2:$F$26,$AE4,LISTS!$G$2:$G$26,$AF4)=0,"NOT ON LIST","")) | AH4: =IF($AG4="","",IF($AE4="","(no county)",$AE4)&" ("&SUBSTITUTE(TEXT($AF4,"0.###%"),".%","%")&")")
AE5: =IF(TRIM($E5)="Tax Paid",TRIM($S5),"") | AF5: =IF(TRIM($E5)="Tax Paid",ROUND($Z5/100,5),"") | AG5: =IF(TRIM($E5)<>"Tax Paid","",IF(COUNTIFS(LISTS!$F$2:$F$26,$AE5,LISTS!$G$2:$G$26,$AF5)=0,"NOT ON LIST","")) | AH5: =IF($AG5="","",IF($AE5="","(no county)",$AE5)&" ("&SUBSTITUTE(TEXT($AF5,"0.###%"),".%","%")&")")
AE6: =IF(TRIM($E6)="Tax Paid",TRIM($S6),"") | AF6: =IF(TRIM($E6)="Tax Paid",ROUND($Z6/100,5),"") | AG6: =IF(TRIM($E6)<>"Tax Paid","",IF(COUNTIFS(LISTS!$F$2:$F$26,$AE6,LISTS!$G$2:$G$26,$AF6)=0,"NOT ON LIST","")) | AH6: =IF($AG6="","",IF($AE6="","(no county)",$AE6)&" ("&SUBSTITUTE(TEXT($AF6,"0.###%"),".%","%")&")")
AE7: =IF(TRIM($E7)="Tax Paid",TRIM($S7),"") | AF7: =IF(TRIM($E7)="Tax Paid",ROUND($Z7/100,5),"") | AG7: =IF(TRIM($E7)<>"Tax Paid","",IF(COUNTIFS(LISTS!$F$2:$F$26,$AE7,LISTS!$G$2:$G$26,$AF7)=0,"NOT ON LIST","")) | AH7: =IF($AG7="","",IF($AE7="","(no county)",$AE7)&" ("&SUBSTITUTE(TEXT($AF7,"0.###%"),".%","%")&")")
AE8: =IF(TRIM($E8)="Tax Paid",TRIM($S8),"") | AF8: =IF(TRIM($E8)="Tax Paid",ROUND($Z8/100,5),"") | AG8: =IF(TRIM($E8)<>"Tax Paid","",IF(COUNTIFS(LISTS!$F$2:$F$26,$AE8,LISTS!$G$2:$G$26,$AF8)=0,"NOT ON LIST","")) | AH8: =IF($AG8="","",IF($AE8="","(no county)",$AE8)&" ("&SUBSTITUTE(TEXT($AF8,"0.###%"),".%","%")&")")
AE9: =IF(TRIM($E9)="Tax Paid",TRIM($S9),"") | AF9: =IF(TRIM($E9)="Tax Paid",ROUND($Z9/100,5),"") | AG9: =IF(TRIM($E9)<>"Tax Paid","",IF(COUNTIFS(LISTS!$F$2:$F$26,$AE9,LISTS!$G$2:$G$26,$AF9)=0,"NOT ON LIST","")) | AH9: =IF($AG9="","",IF($AE9="","(no county)",$AE9)&" ("&SUBSTITUTE(TEXT($AF9,"0.###%"),".%","%")&")")
AE10: =IF(TRIM($E10)="Tax Paid",TRIM($S10),"") | AF10: =IF(TRIM($E10)="Tax Paid",ROUND($Z10/100,5),"") | AG10: =IF(TRIM($E10)<>"Tax Paid","",IF(COUNTIFS(LISTS!$F$2:$F$26,$AE10,LISTS!$G$2:$G$26,$AF10)=0,"NOT ON LIST","")) | AH10: =IF($AG10="","",IF($AE10="","(no county)",$AE10)&" ("&SUBSTITUTE(TEXT($AF10,"0.###%"),".%","%")&")")
AE11: =IF(TRIM($E11)="Tax Paid",TRIM($S11),"") | AF11: =IF(TRIM($E11)="Tax Paid",ROUND($Z11/100,5),"") | AG11: =IF(TRIM($E11)<>"Tax Paid","",IF(COUNTIFS(LISTS!$F$2:$F$26,$AE11,LISTS!$G$2:$G$26,$AF11)=0,"NOT ON LIST","")) | AH11: =IF($AG11="","",IF($AE11="","(no county)",$AE11)&" ("&SUBSTITUTE(TEXT($AF11,"0.###%"),".%","%")&")")
AE12: =IF(TRIM($E12)="Tax Paid",TRIM($S12),"") | AF12: =IF(TRIM($E12)="Tax Paid",ROUND($Z12/100,5),"") | AG12: =IF(TRIM($E12)<>"Tax Paid","",IF(COUNTIFS(LISTS!$F$2:$F$26,$AE12,LISTS!$G$2:$G$26,$AF12)=0,"NOT ON LIST","")) | AH12: =IF($AG12="","",IF($AE12="","(no county)",$AE12)&" ("&SUBSTITUTE(TEXT($AF12,"0.###%"),".%","%")&")")
AE13: =IF(TRIM($E13)="Tax Paid",TRIM($S13),"") | AF13: =IF(TRIM($E13)="Tax Paid",ROUND($Z13/100,5),"") | AG13: =IF(TRIM($E13)<>"Tax Paid","",IF(COUNTIFS(LISTS!$F$2:$F$26,$AE13,LISTS!$G$2:$G$26,$AF13)=0,"NOT ON LIST","")) | AH13: =IF($AG13="","",IF($AE13="","(no county)",$AE13)&" ("&SUBSTITUTE(TEXT($AF13,"0.###%"),".%","%")&")")
... AE1500: =IF(TRIM($E1500)="Tax Paid",TRIM($S1500),"") | AF1500: =IF(TRIM($E1500)="Tax Paid",ROUND($Z1500/100,5),"") | AG1500: =IF(TRIM($E1500)<>"Tax Paid","",IF(COUNTIFS(LISTS!$F$2:$F$26,$AE1500,LISTS!$G$2:$G$26,$AF1500)=0,"NOT ON LIST","")) | AH1500: =IF($AG1500="","",IF($AE1500="","(no county)",$AE1500)&" ("&SUBSTITUTE(TEXT($AF1500,"0.###%"),".%","%")&")")

Sheet TERSE MONTH 2
A1: Ship To State | B1: Ship To State Name | C1: Ship To City | D1: lng City ID | E1: Ship To County | F1: Product Type | G1: Product Type Name | H1: Customer Name | I1: Account Number | J1: Ship To Number | K1: Account Ship To | L1: Order Number | M1: Carrier | N1: Marketing Consultant | O1: Product | P1: Invoice Date | Q1: Ordered Qty | R1: Sold Qty | S1: Metered Qty | T1: Gross Profit | U1: Sold As | V1: Unit Price | W1: Qty Price | X1: Total Taxes Now | Y1: Total Taxes Deferred | Z1: Total Taxes | AA1: Total Excise Taxes | AB1: Total Sales Taxes | AC1: Line Total | AD1: Total Product | AE1: Total Product Excise | AF1: Ship To Name | AG1: Address 1 | AH1: Destination State | AI1: Bid ID | AJ1: Firm Contract | AK1: Firm Contract Adjustment | AL1: NYMEX Weekly Adjustment | AM1: Sold Qty No Svc | AN1: Gross Profit No Svc | AO1: Total Product No Svc | AP1: Total Product Excise No Svc | AQ1: Line Total No Svc | AR1: cnt Order Item ID | AS1: cnt Order ID | AU1: Counted? (helper)
AU2: =IF(TRIM($G2)="","",IF(COUNTIF(LISTS!$I$2:$I$16,TRIM($G2))>0,"COUNTED",IF(COUNTIF(LISTS!$J$2:$J$16,TRIM($G2))>0,"LEFT OUT","NEW")))
AU3: =IF(TRIM($G3)="","",IF(COUNTIF(LISTS!$I$2:$I$16,TRIM($G3))>0,"COUNTED",IF(COUNTIF(LISTS!$J$2:$J$16,TRIM($G3))>0,"LEFT OUT","NEW")))
AU4: =IF(TRIM($G4)="","",IF(COUNTIF(LISTS!$I$2:$I$16,TRIM($G4))>0,"COUNTED",IF(COUNTIF(LISTS!$J$2:$J$16,TRIM($G4))>0,"LEFT OUT","NEW")))
AU5: =IF(TRIM($G5)="","",IF(COUNTIF(LISTS!$I$2:$I$16,TRIM($G5))>0,"COUNTED",IF(COUNTIF(LISTS!$J$2:$J$16,TRIM($G5))>0,"LEFT OUT","NEW")))
AU6: =IF(TRIM($G6)="","",IF(COUNTIF(LISTS!$I$2:$I$16,TRIM($G6))>0,"COUNTED",IF(COUNTIF(LISTS!$J$2:$J$16,TRIM($G6))>0,"LEFT OUT","NEW")))
AU7: =IF(TRIM($G7)="","",IF(COUNTIF(LISTS!$I$2:$I$16,TRIM($G7))>0,"COUNTED",IF(COUNTIF(LISTS!$J$2:$J$16,TRIM($G7))>0,"LEFT OUT","NEW")))
AU8: =IF(TRIM($G8)="","",IF(COUNTIF(LISTS!$I$2:$I$16,TRIM($G8))>0,"COUNTED",IF(COUNTIF(LISTS!$J$2:$J$16,TRIM($G8))>0,"LEFT OUT","NEW")))
AU9: =IF(TRIM($G9)="","",IF(COUNTIF(LISTS!$I$2:$I$16,TRIM($G9))>0,"COUNTED",IF(COUNTIF(LISTS!$J$2:$J$16,TRIM($G9))>0,"LEFT OUT","NEW")))
AU10: =IF(TRIM($G10)="","",IF(COUNTIF(LISTS!$I$2:$I$16,TRIM($G10))>0,"COUNTED",IF(COUNTIF(LISTS!$J$2:$J$16,TRIM($G10))>0,"LEFT OUT","NEW")))
AU11: =IF(TRIM($G11)="","",IF(COUNTIF(LISTS!$I$2:$I$16,TRIM($G11))>0,"COUNTED",IF(COUNTIF(LISTS!$J$2:$J$16,TRIM($G11))>0,"LEFT OUT","NEW")))
AU12: =IF(TRIM($G12)="","",IF(COUNTIF(LISTS!$I$2:$I$16,TRIM($G12))>0,"COUNTED",IF(COUNTIF(LISTS!$J$2:$J$16,TRIM($G12))>0,"LEFT OUT","NEW")))
AU13: =IF(TRIM($G13)="","",IF(COUNTIF(LISTS!$I$2:$I$16,TRIM($G13))>0,"COUNTED",IF(COUNTIF(LISTS!$J$2:$J$16,TRIM($G13))>0,"LEFT OUT","NEW")))
... AU3000: =IF(TRIM($G3000)="","",IF(COUNTIF(LISTS!$I$2:$I$16,TRIM($G3000))>0,"COUNTED",IF(COUNTIF(LISTS!$J$2:$J$16,TRIM($G3000))>0,"LEFT OUT","NEW")))

Sheet AR MONTH 2
A1: Tax State | B1: Tax State Name | C1: Destination State | D1: Destination State Name | E1: Category | F1: Import Export | G1: Category Import Export | H1: Tax Name | I1: Tax Class | J1: Tax Exemption | K1: Invoice Date | L1: Order Number | M1: Customer Name | N1: Ship To Name | O1: Address 1 | P1: Ship To City | Q1: Ship To State | R1: Ship To City State | S1: County | T1: Account Number | U1: Ship To Number | V1: Account Ship To | W1: Invoice Total | X1: Non Taxable Sales | Y1: Taxable Sales | Z1: Tax Rate | AA1: Total Sales Tax | AB1: lng Tax Class ID | AC1: cnt Tax ID | AE1: County (helper) | AF1: Rate (helper) | AG1: On the county list? (helper) | AH1: County and rate (helper)
AE2: =IF(TRIM($E2)="Tax Paid",TRIM($S2),"") | AF2: =IF(TRIM($E2)="Tax Paid",ROUND($Z2/100,5),"") | AG2: =IF(TRIM($E2)<>"Tax Paid","",IF(COUNTIFS(LISTS!$F$2:$F$26,$AE2,LISTS!$G$2:$G$26,$AF2)=0,"NOT ON LIST","")) | AH2: =IF($AG2="","",IF($AE2="","(no county)",$AE2)&" ("&SUBSTITUTE(TEXT($AF2,"0.###%"),".%","%")&")")
AE3: =IF(TRIM($E3)="Tax Paid",TRIM($S3),"") | AF3: =IF(TRIM($E3)="Tax Paid",ROUND($Z3/100,5),"") | AG3: =IF(TRIM($E3)<>"Tax Paid","",IF(COUNTIFS(LISTS!$F$2:$F$26,$AE3,LISTS!$G$2:$G$26,$AF3)=0,"NOT ON LIST","")) | AH3: =IF($AG3="","",IF($AE3="","(no county)",$AE3)&" ("&SUBSTITUTE(TEXT($AF3,"0.###%"),".%","%")&")")
AE4: =IF(TRIM($E4)="Tax Paid",TRIM($S4),"") | AF4: =IF(TRIM($E4)="Tax Paid",ROUND($Z4/100,5),"") | AG4: =IF(TRIM($E4)<>"Tax Paid","",IF(COUNTIFS(LISTS!$F$2:$F$26,$AE4,LISTS!$G$2:$G$26,$AF4)=0,"NOT ON LIST","")) | AH4: =IF($AG4="","",IF($AE4="","(no county)",$AE4)&" ("&SUBSTITUTE(TEXT($AF4,"0.###%"),".%","%")&")")
AE5: =IF(TRIM($E5)="Tax Paid",TRIM($S5),"") | AF5: =IF(TRIM($E5)="Tax Paid",ROUND($Z5/100,5),"") | AG5: =IF(TRIM($E5)<>"Tax Paid","",IF(COUNTIFS(LISTS!$F$2:$F$26,$AE5,LISTS!$G$2:$G$26,$AF5)=0,"NOT ON LIST","")) | AH5: =IF($AG5="","",IF($AE5="","(no county)",$AE5)&" ("&SUBSTITUTE(TEXT($AF5,"0.###%"),".%","%")&")")
AE6: =IF(TRIM($E6)="Tax Paid",TRIM($S6),"") | AF6: =IF(TRIM($E6)="Tax Paid",ROUND($Z6/100,5),"") | AG6: =IF(TRIM($E6)<>"Tax Paid","",IF(COUNTIFS(LISTS!$F$2:$F$26,$AE6,LISTS!$G$2:$G$26,$AF6)=0,"NOT ON LIST","")) | AH6: =IF($AG6="","",IF($AE6="","(no county)",$AE6)&" ("&SUBSTITUTE(TEXT($AF6,"0.###%"),".%","%")&")")
AE7: =IF(TRIM($E7)="Tax Paid",TRIM($S7),"") | AF7: =IF(TRIM($E7)="Tax Paid",ROUND($Z7/100,5),"") | AG7: =IF(TRIM($E7)<>"Tax Paid","",IF(COUNTIFS(LISTS!$F$2:$F$26,$AE7,LISTS!$G$2:$G$26,$AF7)=0,"NOT ON LIST","")) | AH7: =IF($AG7="","",IF($AE7="","(no county)",$AE7)&" ("&SUBSTITUTE(TEXT($AF7,"0.###%"),".%","%")&")")
AE8: =IF(TRIM($E8)="Tax Paid",TRIM($S8),"") | AF8: =IF(TRIM($E8)="Tax Paid",ROUND($Z8/100,5),"") | AG8: =IF(TRIM($E8)<>"Tax Paid","",IF(COUNTIFS(LISTS!$F$2:$F$26,$AE8,LISTS!$G$2:$G$26,$AF8)=0,"NOT ON LIST","")) | AH8: =IF($AG8="","",IF($AE8="","(no county)",$AE8)&" ("&SUBSTITUTE(TEXT($AF8,"0.###%"),".%","%")&")")
AE9: =IF(TRIM($E9)="Tax Paid",TRIM($S9),"") | AF9: =IF(TRIM($E9)="Tax Paid",ROUND($Z9/100,5),"") | AG9: =IF(TRIM($E9)<>"Tax Paid","",IF(COUNTIFS(LISTS!$F$2:$F$26,$AE9,LISTS!$G$2:$G$26,$AF9)=0,"NOT ON LIST","")) | AH9: =IF($AG9="","",IF($AE9="","(no county)",$AE9)&" ("&SUBSTITUTE(TEXT($AF9,"0.###%"),".%","%")&")")
AE10: =IF(TRIM($E10)="Tax Paid",TRIM($S10),"") | AF10: =IF(TRIM($E10)="Tax Paid",ROUND($Z10/100,5),"") | AG10: =IF(TRIM($E10)<>"Tax Paid","",IF(COUNTIFS(LISTS!$F$2:$F$26,$AE10,LISTS!$G$2:$G$26,$AF10)=0,"NOT ON LIST","")) | AH10: =IF($AG10="","",IF($AE10="","(no county)",$AE10)&" ("&SUBSTITUTE(TEXT($AF10,"0.###%"),".%","%")&")")
AE11: =IF(TRIM($E11)="Tax Paid",TRIM($S11),"") | AF11: =IF(TRIM($E11)="Tax Paid",ROUND($Z11/100,5),"") | AG11: =IF(TRIM($E11)<>"Tax Paid","",IF(COUNTIFS(LISTS!$F$2:$F$26,$AE11,LISTS!$G$2:$G$26,$AF11)=0,"NOT ON LIST","")) | AH11: =IF($AG11="","",IF($AE11="","(no county)",$AE11)&" ("&SUBSTITUTE(TEXT($AF11,"0.###%"),".%","%")&")")
AE12: =IF(TRIM($E12)="Tax Paid",TRIM($S12),"") | AF12: =IF(TRIM($E12)="Tax Paid",ROUND($Z12/100,5),"") | AG12: =IF(TRIM($E12)<>"Tax Paid","",IF(COUNTIFS(LISTS!$F$2:$F$26,$AE12,LISTS!$G$2:$G$26,$AF12)=0,"NOT ON LIST","")) | AH12: =IF($AG12="","",IF($AE12="","(no county)",$AE12)&" ("&SUBSTITUTE(TEXT($AF12,"0.###%"),".%","%")&")")
AE13: =IF(TRIM($E13)="Tax Paid",TRIM($S13),"") | AF13: =IF(TRIM($E13)="Tax Paid",ROUND($Z13/100,5),"") | AG13: =IF(TRIM($E13)<>"Tax Paid","",IF(COUNTIFS(LISTS!$F$2:$F$26,$AE13,LISTS!$G$2:$G$26,$AF13)=0,"NOT ON LIST","")) | AH13: =IF($AG13="","",IF($AE13="","(no county)",$AE13)&" ("&SUBSTITUTE(TEXT($AF13,"0.###%"),".%","%")&")")
... AE1500: =IF(TRIM($E1500)="Tax Paid",TRIM($S1500),"") | AF1500: =IF(TRIM($E1500)="Tax Paid",ROUND($Z1500/100,5),"") | AG1500: =IF(TRIM($E1500)<>"Tax Paid","",IF(COUNTIFS(LISTS!$F$2:$F$26,$AE1500,LISTS!$G$2:$G$26,$AF1500)=0,"NOT ON LIST","")) | AH1500: =IF($AG1500="","",IF($AE1500="","(no county)",$AE1500)&" ("&SUBSTITUTE(TEXT($AF1500,"0.###%"),".%","%")&")")

Sheet TERSE MONTH 3
A1: Ship To State | B1: Ship To State Name | C1: Ship To City | D1: lng City ID | E1: Ship To County | F1: Product Type | G1: Product Type Name | H1: Customer Name | I1: Account Number | J1: Ship To Number | K1: Account Ship To | L1: Order Number | M1: Carrier | N1: Marketing Consultant | O1: Product | P1: Invoice Date | Q1: Ordered Qty | R1: Sold Qty | S1: Metered Qty | T1: Gross Profit | U1: Sold As | V1: Unit Price | W1: Qty Price | X1: Total Taxes Now | Y1: Total Taxes Deferred | Z1: Total Taxes | AA1: Total Excise Taxes | AB1: Total Sales Taxes | AC1: Line Total | AD1: Total Product | AE1: Total Product Excise | AF1: Ship To Name | AG1: Address 1 | AH1: Destination State | AI1: Bid ID | AJ1: Firm Contract | AK1: Firm Contract Adjustment | AL1: NYMEX Weekly Adjustment | AM1: Sold Qty No Svc | AN1: Gross Profit No Svc | AO1: Total Product No Svc | AP1: Total Product Excise No Svc | AQ1: Line Total No Svc | AR1: cnt Order Item ID | AS1: cnt Order ID | AU1: Counted? (helper)
AU2: =IF(TRIM($G2)="","",IF(COUNTIF(LISTS!$I$2:$I$16,TRIM($G2))>0,"COUNTED",IF(COUNTIF(LISTS!$J$2:$J$16,TRIM($G2))>0,"LEFT OUT","NEW")))
AU3: =IF(TRIM($G3)="","",IF(COUNTIF(LISTS!$I$2:$I$16,TRIM($G3))>0,"COUNTED",IF(COUNTIF(LISTS!$J$2:$J$16,TRIM($G3))>0,"LEFT OUT","NEW")))
AU4: =IF(TRIM($G4)="","",IF(COUNTIF(LISTS!$I$2:$I$16,TRIM($G4))>0,"COUNTED",IF(COUNTIF(LISTS!$J$2:$J$16,TRIM($G4))>0,"LEFT OUT","NEW")))
AU5: =IF(TRIM($G5)="","",IF(COUNTIF(LISTS!$I$2:$I$16,TRIM($G5))>0,"COUNTED",IF(COUNTIF(LISTS!$J$2:$J$16,TRIM($G5))>0,"LEFT OUT","NEW")))
AU6: =IF(TRIM($G6)="","",IF(COUNTIF(LISTS!$I$2:$I$16,TRIM($G6))>0,"COUNTED",IF(COUNTIF(LISTS!$J$2:$J$16,TRIM($G6))>0,"LEFT OUT","NEW")))
AU7: =IF(TRIM($G7)="","",IF(COUNTIF(LISTS!$I$2:$I$16,TRIM($G7))>0,"COUNTED",IF(COUNTIF(LISTS!$J$2:$J$16,TRIM($G7))>0,"LEFT OUT","NEW")))
AU8: =IF(TRIM($G8)="","",IF(COUNTIF(LISTS!$I$2:$I$16,TRIM($G8))>0,"COUNTED",IF(COUNTIF(LISTS!$J$2:$J$16,TRIM($G8))>0,"LEFT OUT","NEW")))
AU9: =IF(TRIM($G9)="","",IF(COUNTIF(LISTS!$I$2:$I$16,TRIM($G9))>0,"COUNTED",IF(COUNTIF(LISTS!$J$2:$J$16,TRIM($G9))>0,"LEFT OUT","NEW")))
AU10: =IF(TRIM($G10)="","",IF(COUNTIF(LISTS!$I$2:$I$16,TRIM($G10))>0,"COUNTED",IF(COUNTIF(LISTS!$J$2:$J$16,TRIM($G10))>0,"LEFT OUT","NEW")))
AU11: =IF(TRIM($G11)="","",IF(COUNTIF(LISTS!$I$2:$I$16,TRIM($G11))>0,"COUNTED",IF(COUNTIF(LISTS!$J$2:$J$16,TRIM($G11))>0,"LEFT OUT","NEW")))
AU12: =IF(TRIM($G12)="","",IF(COUNTIF(LISTS!$I$2:$I$16,TRIM($G12))>0,"COUNTED",IF(COUNTIF(LISTS!$J$2:$J$16,TRIM($G12))>0,"LEFT OUT","NEW")))
AU13: =IF(TRIM($G13)="","",IF(COUNTIF(LISTS!$I$2:$I$16,TRIM($G13))>0,"COUNTED",IF(COUNTIF(LISTS!$J$2:$J$16,TRIM($G13))>0,"LEFT OUT","NEW")))
... AU3000: =IF(TRIM($G3000)="","",IF(COUNTIF(LISTS!$I$2:$I$16,TRIM($G3000))>0,"COUNTED",IF(COUNTIF(LISTS!$J$2:$J$16,TRIM($G3000))>0,"LEFT OUT","NEW")))

Sheet AR MONTH 3
A1: Tax State | B1: Tax State Name | C1: Destination State | D1: Destination State Name | E1: Category | F1: Import Export | G1: Category Import Export | H1: Tax Name | I1: Tax Class | J1: Tax Exemption | K1: Invoice Date | L1: Order Number | M1: Customer Name | N1: Ship To Name | O1: Address 1 | P1: Ship To City | Q1: Ship To State | R1: Ship To City State | S1: County | T1: Account Number | U1: Ship To Number | V1: Account Ship To | W1: Invoice Total | X1: Non Taxable Sales | Y1: Taxable Sales | Z1: Tax Rate | AA1: Total Sales Tax | AB1: lng Tax Class ID | AC1: cnt Tax ID | AE1: County (helper) | AF1: Rate (helper) | AG1: On the county list? (helper) | AH1: County and rate (helper)
AE2: =IF(TRIM($E2)="Tax Paid",TRIM($S2),"") | AF2: =IF(TRIM($E2)="Tax Paid",ROUND($Z2/100,5),"") | AG2: =IF(TRIM($E2)<>"Tax Paid","",IF(COUNTIFS(LISTS!$F$2:$F$26,$AE2,LISTS!$G$2:$G$26,$AF2)=0,"NOT ON LIST","")) | AH2: =IF($AG2="","",IF($AE2="","(no county)",$AE2)&" ("&SUBSTITUTE(TEXT($AF2,"0.###%"),".%","%")&")")
AE3: =IF(TRIM($E3)="Tax Paid",TRIM($S3),"") | AF3: =IF(TRIM($E3)="Tax Paid",ROUND($Z3/100,5),"") | AG3: =IF(TRIM($E3)<>"Tax Paid","",IF(COUNTIFS(LISTS!$F$2:$F$26,$AE3,LISTS!$G$2:$G$26,$AF3)=0,"NOT ON LIST","")) | AH3: =IF($AG3="","",IF($AE3="","(no county)",$AE3)&" ("&SUBSTITUTE(TEXT($AF3,"0.###%"),".%","%")&")")
AE4: =IF(TRIM($E4)="Tax Paid",TRIM($S4),"") | AF4: =IF(TRIM($E4)="Tax Paid",ROUND($Z4/100,5),"") | AG4: =IF(TRIM($E4)<>"Tax Paid","",IF(COUNTIFS(LISTS!$F$2:$F$26,$AE4,LISTS!$G$2:$G$26,$AF4)=0,"NOT ON LIST","")) | AH4: =IF($AG4="","",IF($AE4="","(no county)",$AE4)&" ("&SUBSTITUTE(TEXT($AF4,"0.###%"),".%","%")&")")
AE5: =IF(TRIM($E5)="Tax Paid",TRIM($S5),"") | AF5: =IF(TRIM($E5)="Tax Paid",ROUND($Z5/100,5),"") | AG5: =IF(TRIM($E5)<>"Tax Paid","",IF(COUNTIFS(LISTS!$F$2:$F$26,$AE5,LISTS!$G$2:$G$26,$AF5)=0,"NOT ON LIST","")) | AH5: =IF($AG5="","",IF($AE5="","(no county)",$AE5)&" ("&SUBSTITUTE(TEXT($AF5,"0.###%"),".%","%")&")")
AE6: =IF(TRIM($E6)="Tax Paid",TRIM($S6),"") | AF6: =IF(TRIM($E6)="Tax Paid",ROUND($Z6/100,5),"") | AG6: =IF(TRIM($E6)<>"Tax Paid","",IF(COUNTIFS(LISTS!$F$2:$F$26,$AE6,LISTS!$G$2:$G$26,$AF6)=0,"NOT ON LIST","")) | AH6: =IF($AG6="","",IF($AE6="","(no county)",$AE6)&" ("&SUBSTITUTE(TEXT($AF6,"0.###%"),".%","%")&")")
AE7: =IF(TRIM($E7)="Tax Paid",TRIM($S7),"") | AF7: =IF(TRIM($E7)="Tax Paid",ROUND($Z7/100,5),"") | AG7: =IF(TRIM($E7)<>"Tax Paid","",IF(COUNTIFS(LISTS!$F$2:$F$26,$AE7,LISTS!$G$2:$G$26,$AF7)=0,"NOT ON LIST","")) | AH7: =IF($AG7="","",IF($AE7="","(no county)",$AE7)&" ("&SUBSTITUTE(TEXT($AF7,"0.###%"),".%","%")&")")
AE8: =IF(TRIM($E8)="Tax Paid",TRIM($S8),"") | AF8: =IF(TRIM($E8)="Tax Paid",ROUND($Z8/100,5),"") | AG8: =IF(TRIM($E8)<>"Tax Paid","",IF(COUNTIFS(LISTS!$F$2:$F$26,$AE8,LISTS!$G$2:$G$26,$AF8)=0,"NOT ON LIST","")) | AH8: =IF($AG8="","",IF($AE8="","(no county)",$AE8)&" ("&SUBSTITUTE(TEXT($AF8,"0.###%"),".%","%")&")")
AE9: =IF(TRIM($E9)="Tax Paid",TRIM($S9),"") | AF9: =IF(TRIM($E9)="Tax Paid",ROUND($Z9/100,5),"") | AG9: =IF(TRIM($E9)<>"Tax Paid","",IF(COUNTIFS(LISTS!$F$2:$F$26,$AE9,LISTS!$G$2:$G$26,$AF9)=0,"NOT ON LIST","")) | AH9: =IF($AG9="","",IF($AE9="","(no county)",$AE9)&" ("&SUBSTITUTE(TEXT($AF9,"0.###%"),".%","%")&")")
AE10: =IF(TRIM($E10)="Tax Paid",TRIM($S10),"") | AF10: =IF(TRIM($E10)="Tax Paid",ROUND($Z10/100,5),"") | AG10: =IF(TRIM($E10)<>"Tax Paid","",IF(COUNTIFS(LISTS!$F$2:$F$26,$AE10,LISTS!$G$2:$G$26,$AF10)=0,"NOT ON LIST","")) | AH10: =IF($AG10="","",IF($AE10="","(no county)",$AE10)&" ("&SUBSTITUTE(TEXT($AF10,"0.###%"),".%","%")&")")
AE11: =IF(TRIM($E11)="Tax Paid",TRIM($S11),"") | AF11: =IF(TRIM($E11)="Tax Paid",ROUND($Z11/100,5),"") | AG11: =IF(TRIM($E11)<>"Tax Paid","",IF(COUNTIFS(LISTS!$F$2:$F$26,$AE11,LISTS!$G$2:$G$26,$AF11)=0,"NOT ON LIST","")) | AH11: =IF($AG11="","",IF($AE11="","(no county)",$AE11)&" ("&SUBSTITUTE(TEXT($AF11,"0.###%"),".%","%")&")")
AE12: =IF(TRIM($E12)="Tax Paid",TRIM($S12),"") | AF12: =IF(TRIM($E12)="Tax Paid",ROUND($Z12/100,5),"") | AG12: =IF(TRIM($E12)<>"Tax Paid","",IF(COUNTIFS(LISTS!$F$2:$F$26,$AE12,LISTS!$G$2:$G$26,$AF12)=0,"NOT ON LIST","")) | AH12: =IF($AG12="","",IF($AE12="","(no county)",$AE12)&" ("&SUBSTITUTE(TEXT($AF12,"0.###%"),".%","%")&")")
AE13: =IF(TRIM($E13)="Tax Paid",TRIM($S13),"") | AF13: =IF(TRIM($E13)="Tax Paid",ROUND($Z13/100,5),"") | AG13: =IF(TRIM($E13)<>"Tax Paid","",IF(COUNTIFS(LISTS!$F$2:$F$26,$AE13,LISTS!$G$2:$G$26,$AF13)=0,"NOT ON LIST","")) | AH13: =IF($AG13="","",IF($AE13="","(no county)",$AE13)&" ("&SUBSTITUTE(TEXT($AF13,"0.###%"),".%","%")&")")
... AE1500: =IF(TRIM($E1500)="Tax Paid",TRIM($S1500),"") | AF1500: =IF(TRIM($E1500)="Tax Paid",ROUND($Z1500/100,5),"") | AG1500: =IF(TRIM($E1500)<>"Tax Paid","",IF(COUNTIFS(LISTS!$F$2:$F$26,$AE1500,LISTS!$G$2:$G$26,$AF1500)=0,"NOT ON LIST","")) | AH1500: =IF($AG1500="","",IF($AE1500="","(no county)",$AE1500)&" ("&SUBSTITUTE(TEXT($AF1500,"0.###%"),".%","%")&")")

Sheet LISTS
A1: County | B1: Rate | C1: Jurisdiction code | D1: Name on the sheet | F1: County (helper) | G1: Rate (helper) | I1: Product types counted in total sales | J1: Product types left out | L1: Rate with no local tax
A2: Cedar | B2: 0.04225 | D2: =IF(OR(TRIM(A2)="",B2=""),"",TRIM(A2)&" ("&SUBSTITUTE(TEXT(B2,"0.###%"),".%","%")&")") -> Cedar (4.225%) | F2: =IF(D2="","",TRIM(A2)) -> Cedar | G2: =IF(D2="","",ROUND(B2,5)) -> 0.04225 | I2: 2 - #2 Ultra Low Sulfur (clear) | J2: S - Services | L2: 0.04225
A3: Wright | B3: 0.04225 | D3: =IF(OR(TRIM(A3)="",B3=""),"",TRIM(A3)&" ("&SUBSTITUTE(TEXT(B3,"0.###%"),".%","%")&")") -> Wright (4.225%) | F3: =IF(D3="","",TRIM(A3)) -> Wright | G3: =IF(D3="","",ROUND(B3,5)) -> 0.04225 | I3: 4 - #2 Dyed Ultra Low Sulfur | J3: F - Non-Taxable Product
A4: Hickory | B4: 0.04225 | D4: =IF(OR(TRIM(A4)="",B4=""),"",TRIM(A4)&" ("&SUBSTITUTE(TEXT(B4,"0.###%"),".%","%")&")") -> Hickory (4.225%) | F4: =IF(D4="","",TRIM(A4)) -> Hickory | G4: =IF(D4="","",ROUND(B4,5)) -> 0.04225 | I4: H - 10% Gasohol | J4: 8 - Differential - Gas & Clear
A5: Christian | B5: 0.04225 | D5: =IF(OR(TRIM(A5)="",B5=""),"",TRIM(A5)&" ("&SUBSTITUTE(TEXT(B5,"0.###%"),".%","%")&")") -> Christian (4.225%) | F5: =IF(D5="","",TRIM(A5)) -> Christian | G5: =IF(D5="","",ROUND(B5,5)) -> 0.04225 | I5: B - Bio Diesel Clear | J5: Z - Charges not payable through Accounts Payable
A6: Nodaway | B6: 0.061 | C6: 00000-147-000 | D6: =IF(OR(TRIM(A6)="",B6=""),"",TRIM(A6)&" ("&SUBSTITUTE(TEXT(B6,"0.###%"),".%","%")&")") -> Nodaway (6.1%) | F6: =IF(D6="","",TRIM(A6)) -> Nodaway | G6: =IF(D6="","",ROUND(B6,5)) -> 0.061 | I6: D - Bio Diesel Dyed
A7: Bates | B7: 0.05225 | D7: =IF(OR(TRIM(A7)="",B7=""),"",TRIM(A7)&" ("&SUBSTITUTE(TEXT(B7,"0.###%"),".%","%")&")") -> Bates (5.225%) | F7: =IF(D7="","",TRIM(A7)) -> Bates | G7: =IF(D7="","",ROUND(B7,5)) -> 0.05225
A8: Jasper | B8: 0.056 | D8: =IF(OR(TRIM(A8)="",B8=""),"",TRIM(A8)&" ("&SUBSTITUTE(TEXT(B8,"0.###%"),".%","%")&")") -> Jasper (5.6%) | F8: =IF(D8="","",TRIM(A8)) -> Jasper | G8: =IF(D8="","",ROUND(B8,5)) -> 0.056
A9: Clay | B9: 0.08725 | D9: =IF(OR(TRIM(A9)="",B9=""),"",TRIM(A9)&" ("&SUBSTITUTE(TEXT(B9,"0.###%"),".%","%")&")") -> Clay (8.725%) | F9: =IF(D9="","",TRIM(A9)) -> Clay | G9: =IF(D9="","",ROUND(B9,5)) -> 0.08725
A10: Clay | B10: 0.086 | D10: =IF(OR(TRIM(A10)="",B10=""),"",TRIM(A10)&" ("&SUBSTITUTE(TEXT(B10,"0.###%"),".%","%")&")") -> Clay (8.6%) | F10: =IF(D10="","",TRIM(A10)) -> Clay | G10: =IF(D10="","",ROUND(B10,5)) -> 0.086
A11: Clay | B11: 0.09725 | D11: =IF(OR(TRIM(A11)="",B11=""),"",TRIM(A11)&" ("&SUBSTITUTE(TEXT(B11,"0.###%"),".%","%")&")") -> Clay (9.725%) | F11: =IF(D11="","",TRIM(A11)) -> Clay | G11: =IF(D11="","",ROUND(B11,5)) -> 0.09725
A12: Stoddard | B12: 0.06225 | C12: 00000-207-000 | D12: =IF(OR(TRIM(A12)="",B12=""),"",TRIM(A12)&" ("&SUBSTITUTE(TEXT(B12,"0.###%"),".%","%")&")") -> Stoddard (6.225%) | F12: =IF(D12="","",TRIM(A12)) -> Stoddard | G12: =IF(D12="","",ROUND(B12,5)) -> 0.06225
A13: Warren | B13: 0.06225 | D13: =IF(OR(TRIM(A13)="",B13=""),"",TRIM(A13)&" ("&SUBSTITUTE(TEXT(B13,"0.###%"),".%","%")&")") -> Warren (6.225%) | F13: =IF(D13="","",TRIM(A13)) -> Warren | G13: =IF(D13="","",ROUND(B13,5)) -> 0.06225
A14: Greene | B14: 0.0635 | D14: =IF(OR(TRIM(A14)="",B14=""),"",TRIM(A14)&" ("&SUBSTITUTE(TEXT(B14,"0.###%"),".%","%")&")") -> Greene (6.35%) | F14: =IF(D14="","",TRIM(A14)) -> Greene | G14: =IF(D14="","",ROUND(B14,5)) -> 0.0635
A15: Henry | B15: 0.07925 | D15: =IF(OR(TRIM(A15)="",B15=""),"",TRIM(A15)&" ("&SUBSTITUTE(TEXT(B15,"0.###%"),".%","%")&")") -> Henry (7.925%) | F15: =IF(D15="","",TRIM(A15)) -> Henry | G15: =IF(D15="","",ROUND(B15,5)) -> 0.07925
A16: St. Charles | B16: 0.0795 | D16: =IF(OR(TRIM(A16)="",B16=""),"",TRIM(A16)&" ("&SUBSTITUTE(TEXT(B16,"0.###%"),".%","%")&")") -> St. Charles (7.95%) | F16: =IF(D16="","",TRIM(A16)) -> St. Charles | G16: =IF(D16="","",ROUND(B16,5)) -> 0.0795
A17: Boone | B17: 0.07975 | D17: =IF(OR(TRIM(A17)="",B17=""),"",TRIM(A17)&" ("&SUBSTITUTE(TEXT(B17,"0.###%"),".%","%")&")") -> Boone (7.975%) | F17: =IF(D17="","",TRIM(A17)) -> Boone | G17: =IF(D17="","",ROUND(B17,5)) -> 0.07975
A18: Wright | B18: 0.061 | D18: =IF(OR(TRIM(A18)="",B18=""),"",TRIM(A18)&" ("&SUBSTITUTE(TEXT(B18,"0.###%"),".%","%")&")") -> Wright (6.1%) | F18: =IF(D18="","",TRIM(A18)) -> Wright | G18: =IF(D18="","",ROUND(B18,5)) -> 0.061
A19: Franklin | B19: 0.06475 | D19: =IF(OR(TRIM(A19)="",B19=""),"",TRIM(A19)&" ("&SUBSTITUTE(TEXT(B19,"0.###%"),".%","%")&")") -> Franklin (6.475%) | F19: =IF(D19="","",TRIM(A19)) -> Franklin | G19: =IF(D19="","",ROUND(B19,5)) -> 0.06475
A20: Cape Girardeau | B20: 0.08475 | D20: =IF(OR(TRIM(A20)="",B20=""),"",TRIM(A20)&" ("&SUBSTITUTE(TEXT(B20,"0.###%"),".%","%")&")") -> Cape Girardeau (8.475%) | F20: =IF(D20="","",TRIM(A20)) -> Cape Girardeau | G20: =IF(D20="","",ROUND(B20,5)) -> 0.08475
D21: =IF(OR(TRIM(A21)="",B21=""),"",TRIM(A21)&" ("&SUBSTITUTE(TEXT(B21,"0.###%"),".%","%")&")") | F21: =IF(D21="","",TRIM(A21)) | G21: =IF(D21="","",ROUND(B21,5))
D22: =IF(OR(TRIM(A22)="",B22=""),"",TRIM(A22)&" ("&SUBSTITUTE(TEXT(B22,"0.###%"),".%","%")&")") | F22: =IF(D22="","",TRIM(A22)) | G22: =IF(D22="","",ROUND(B22,5))
D23: =IF(OR(TRIM(A23)="",B23=""),"",TRIM(A23)&" ("&SUBSTITUTE(TEXT(B23,"0.###%"),".%","%")&")") | F23: =IF(D23="","",TRIM(A23)) | G23: =IF(D23="","",ROUND(B23,5))
D24: =IF(OR(TRIM(A24)="",B24=""),"",TRIM(A24)&" ("&SUBSTITUTE(TEXT(B24,"0.###%"),".%","%")&")") | F24: =IF(D24="","",TRIM(A24)) | G24: =IF(D24="","",ROUND(B24,5))
D25: =IF(OR(TRIM(A25)="",B25=""),"",TRIM(A25)&" ("&SUBSTITUTE(TEXT(B25,"0.###%"),".%","%")&")") | F25: =IF(D25="","",TRIM(A25)) | G25: =IF(D25="","",ROUND(B25,5))
D26: =IF(OR(TRIM(A26)="",B26=""),"",TRIM(A26)&" ("&SUBSTITUTE(TEXT(B26,"0.###%"),".%","%")&")") | F26: =IF(D26="","",TRIM(A26)) | G26: =IF(D26="","",ROUND(B26,5))
A28: The list holds 25 county and rate pairs. Type a new pair in the first empty yellow row; the RECAP picks it up by itself.
A29: Product types: copy the name exactly as the TERSE report's Product Type Name column has it.
